{
 "cells": [
  {
   "cell_type": "code",
   "execution_count": 2,
   "metadata": {},
   "outputs": [
    {
     "ename": "HTTPError",
     "evalue": "HTTP Error 503: Service Unavailable",
     "output_type": "error",
     "traceback": [
      "\u001b[1;31m---------------------------------------------------------------------------\u001b[0m",
      "\u001b[1;31mHTTPError\u001b[0m                                 Traceback (most recent call last)",
      "Cell \u001b[1;32mIn[2], line 6\u001b[0m\n\u001b[0;32m      4\u001b[0m \u001b[39mimport\u001b[39;00m \u001b[39murllib\u001b[39;00m\u001b[39m.\u001b[39;00m\u001b[39merror\u001b[39;00m\n\u001b[0;32m      5\u001b[0m url \u001b[39m=\u001b[39m \u001b[39m'\u001b[39m\u001b[39mhttps://v5.bvg.transport.rest/locations?query=alexandr&results=3&fuzzy=true\u001b[39m\u001b[39m'\u001b[39m\n\u001b[1;32m----> 6\u001b[0m html \u001b[39m=\u001b[39m urllib\u001b[39m.\u001b[39;49mrequest\u001b[39m.\u001b[39;49murlopen(url)\u001b[39m.\u001b[39mread()\n\u001b[0;32m      7\u001b[0m \u001b[39mprint\u001b[39m(html\u001b[39m.\u001b[39mdecode())\n",
      "File \u001b[1;32mC:\\Program Files\\WindowsApps\\PythonSoftwareFoundation.Python.3.8_3.8.2800.0_x64__qbz5n2kfra8p0\\lib\\urllib\\request.py:222\u001b[0m, in \u001b[0;36murlopen\u001b[1;34m(url, data, timeout, cafile, capath, cadefault, context)\u001b[0m\n\u001b[0;32m    220\u001b[0m \u001b[39melse\u001b[39;00m:\n\u001b[0;32m    221\u001b[0m     opener \u001b[39m=\u001b[39m _opener\n\u001b[1;32m--> 222\u001b[0m \u001b[39mreturn\u001b[39;00m opener\u001b[39m.\u001b[39;49mopen(url, data, timeout)\n",
      "File \u001b[1;32mC:\\Program Files\\WindowsApps\\PythonSoftwareFoundation.Python.3.8_3.8.2800.0_x64__qbz5n2kfra8p0\\lib\\urllib\\request.py:531\u001b[0m, in \u001b[0;36mOpenerDirector.open\u001b[1;34m(self, fullurl, data, timeout)\u001b[0m\n\u001b[0;32m    529\u001b[0m \u001b[39mfor\u001b[39;00m processor \u001b[39min\u001b[39;00m \u001b[39mself\u001b[39m\u001b[39m.\u001b[39mprocess_response\u001b[39m.\u001b[39mget(protocol, []):\n\u001b[0;32m    530\u001b[0m     meth \u001b[39m=\u001b[39m \u001b[39mgetattr\u001b[39m(processor, meth_name)\n\u001b[1;32m--> 531\u001b[0m     response \u001b[39m=\u001b[39m meth(req, response)\n\u001b[0;32m    533\u001b[0m \u001b[39mreturn\u001b[39;00m response\n",
      "File \u001b[1;32mC:\\Program Files\\WindowsApps\\PythonSoftwareFoundation.Python.3.8_3.8.2800.0_x64__qbz5n2kfra8p0\\lib\\urllib\\request.py:640\u001b[0m, in \u001b[0;36mHTTPErrorProcessor.http_response\u001b[1;34m(self, request, response)\u001b[0m\n\u001b[0;32m    637\u001b[0m \u001b[39m# According to RFC 2616, \"2xx\" code indicates that the client's\u001b[39;00m\n\u001b[0;32m    638\u001b[0m \u001b[39m# request was successfully received, understood, and accepted.\u001b[39;00m\n\u001b[0;32m    639\u001b[0m \u001b[39mif\u001b[39;00m \u001b[39mnot\u001b[39;00m (\u001b[39m200\u001b[39m \u001b[39m<\u001b[39m\u001b[39m=\u001b[39m code \u001b[39m<\u001b[39m \u001b[39m300\u001b[39m):\n\u001b[1;32m--> 640\u001b[0m     response \u001b[39m=\u001b[39m \u001b[39mself\u001b[39;49m\u001b[39m.\u001b[39;49mparent\u001b[39m.\u001b[39;49merror(\n\u001b[0;32m    641\u001b[0m         \u001b[39m'\u001b[39;49m\u001b[39mhttp\u001b[39;49m\u001b[39m'\u001b[39;49m, request, response, code, msg, hdrs)\n\u001b[0;32m    643\u001b[0m \u001b[39mreturn\u001b[39;00m response\n",
      "File \u001b[1;32mC:\\Program Files\\WindowsApps\\PythonSoftwareFoundation.Python.3.8_3.8.2800.0_x64__qbz5n2kfra8p0\\lib\\urllib\\request.py:569\u001b[0m, in \u001b[0;36mOpenerDirector.error\u001b[1;34m(self, proto, *args)\u001b[0m\n\u001b[0;32m    567\u001b[0m \u001b[39mif\u001b[39;00m http_err:\n\u001b[0;32m    568\u001b[0m     args \u001b[39m=\u001b[39m (\u001b[39mdict\u001b[39m, \u001b[39m'\u001b[39m\u001b[39mdefault\u001b[39m\u001b[39m'\u001b[39m, \u001b[39m'\u001b[39m\u001b[39mhttp_error_default\u001b[39m\u001b[39m'\u001b[39m) \u001b[39m+\u001b[39m orig_args\n\u001b[1;32m--> 569\u001b[0m     \u001b[39mreturn\u001b[39;00m \u001b[39mself\u001b[39;49m\u001b[39m.\u001b[39;49m_call_chain(\u001b[39m*\u001b[39;49margs)\n",
      "File \u001b[1;32mC:\\Program Files\\WindowsApps\\PythonSoftwareFoundation.Python.3.8_3.8.2800.0_x64__qbz5n2kfra8p0\\lib\\urllib\\request.py:502\u001b[0m, in \u001b[0;36mOpenerDirector._call_chain\u001b[1;34m(self, chain, kind, meth_name, *args)\u001b[0m\n\u001b[0;32m    500\u001b[0m \u001b[39mfor\u001b[39;00m handler \u001b[39min\u001b[39;00m handlers:\n\u001b[0;32m    501\u001b[0m     func \u001b[39m=\u001b[39m \u001b[39mgetattr\u001b[39m(handler, meth_name)\n\u001b[1;32m--> 502\u001b[0m     result \u001b[39m=\u001b[39m func(\u001b[39m*\u001b[39;49margs)\n\u001b[0;32m    503\u001b[0m     \u001b[39mif\u001b[39;00m result \u001b[39mis\u001b[39;00m \u001b[39mnot\u001b[39;00m \u001b[39mNone\u001b[39;00m:\n\u001b[0;32m    504\u001b[0m         \u001b[39mreturn\u001b[39;00m result\n",
      "File \u001b[1;32mC:\\Program Files\\WindowsApps\\PythonSoftwareFoundation.Python.3.8_3.8.2800.0_x64__qbz5n2kfra8p0\\lib\\urllib\\request.py:649\u001b[0m, in \u001b[0;36mHTTPDefaultErrorHandler.http_error_default\u001b[1;34m(self, req, fp, code, msg, hdrs)\u001b[0m\n\u001b[0;32m    648\u001b[0m \u001b[39mdef\u001b[39;00m \u001b[39mhttp_error_default\u001b[39m(\u001b[39mself\u001b[39m, req, fp, code, msg, hdrs):\n\u001b[1;32m--> 649\u001b[0m     \u001b[39mraise\u001b[39;00m HTTPError(req\u001b[39m.\u001b[39mfull_url, code, msg, hdrs, fp)\n",
      "\u001b[1;31mHTTPError\u001b[0m: HTTP Error 503: Service Unavailable"
     ]
    }
   ],
   "source": [
    "#basic html reguest to get the html code of a website and print it out \n",
    "import urllib.request\n",
    "import urllib.parse\n",
    "import urllib.error\n",
    "url = 'https://v5.bvg.transport.rest/locations?query=alexandr&results=3&fuzzy=true'\n",
    "html = urllib.request.urlopen(url).read()\n",
    "print(html.decode())\n"
   ]
  },
  {
   "cell_type": "code",
   "execution_count": 3,
   "metadata": {},
   "outputs": [
    {
     "ename": "HTTPError",
     "evalue": "HTTP Error 503: Service Unavailable",
     "output_type": "error",
     "traceback": [
      "\u001b[1;31m---------------------------------------------------------------------------\u001b[0m",
      "\u001b[1;31mHTTPError\u001b[0m                                 Traceback (most recent call last)",
      "Cell \u001b[1;32mIn[3], line 3\u001b[0m\n\u001b[0;32m      1\u001b[0m \u001b[39mimport\u001b[39;00m \u001b[39mjson\u001b[39;00m\n\u001b[0;32m      2\u001b[0m url \u001b[39m=\u001b[39m \u001b[39m'\u001b[39m\u001b[39mhttps://v5.bvg.transport.rest/stops/nearby?latitude=52.520658&longitude=13.411875&results=5\u001b[39m\u001b[39m'\u001b[39m\n\u001b[1;32m----> 3\u001b[0m html \u001b[39m=\u001b[39m urllib\u001b[39m.\u001b[39;49mrequest\u001b[39m.\u001b[39;49murlopen(url)\u001b[39m.\u001b[39mread()\n\u001b[0;32m      4\u001b[0m x\u001b[39m=\u001b[39m json\u001b[39m.\u001b[39mloads(html) \u001b[39m#make json from html\u001b[39;00m\n\u001b[0;32m      5\u001b[0m \u001b[39mprint\u001b[39m(\u001b[39mlen\u001b[39m(x))\n",
      "File \u001b[1;32mC:\\Program Files\\WindowsApps\\PythonSoftwareFoundation.Python.3.8_3.8.2800.0_x64__qbz5n2kfra8p0\\lib\\urllib\\request.py:222\u001b[0m, in \u001b[0;36murlopen\u001b[1;34m(url, data, timeout, cafile, capath, cadefault, context)\u001b[0m\n\u001b[0;32m    220\u001b[0m \u001b[39melse\u001b[39;00m:\n\u001b[0;32m    221\u001b[0m     opener \u001b[39m=\u001b[39m _opener\n\u001b[1;32m--> 222\u001b[0m \u001b[39mreturn\u001b[39;00m opener\u001b[39m.\u001b[39;49mopen(url, data, timeout)\n",
      "File \u001b[1;32mC:\\Program Files\\WindowsApps\\PythonSoftwareFoundation.Python.3.8_3.8.2800.0_x64__qbz5n2kfra8p0\\lib\\urllib\\request.py:531\u001b[0m, in \u001b[0;36mOpenerDirector.open\u001b[1;34m(self, fullurl, data, timeout)\u001b[0m\n\u001b[0;32m    529\u001b[0m \u001b[39mfor\u001b[39;00m processor \u001b[39min\u001b[39;00m \u001b[39mself\u001b[39m\u001b[39m.\u001b[39mprocess_response\u001b[39m.\u001b[39mget(protocol, []):\n\u001b[0;32m    530\u001b[0m     meth \u001b[39m=\u001b[39m \u001b[39mgetattr\u001b[39m(processor, meth_name)\n\u001b[1;32m--> 531\u001b[0m     response \u001b[39m=\u001b[39m meth(req, response)\n\u001b[0;32m    533\u001b[0m \u001b[39mreturn\u001b[39;00m response\n",
      "File \u001b[1;32mC:\\Program Files\\WindowsApps\\PythonSoftwareFoundation.Python.3.8_3.8.2800.0_x64__qbz5n2kfra8p0\\lib\\urllib\\request.py:640\u001b[0m, in \u001b[0;36mHTTPErrorProcessor.http_response\u001b[1;34m(self, request, response)\u001b[0m\n\u001b[0;32m    637\u001b[0m \u001b[39m# According to RFC 2616, \"2xx\" code indicates that the client's\u001b[39;00m\n\u001b[0;32m    638\u001b[0m \u001b[39m# request was successfully received, understood, and accepted.\u001b[39;00m\n\u001b[0;32m    639\u001b[0m \u001b[39mif\u001b[39;00m \u001b[39mnot\u001b[39;00m (\u001b[39m200\u001b[39m \u001b[39m<\u001b[39m\u001b[39m=\u001b[39m code \u001b[39m<\u001b[39m \u001b[39m300\u001b[39m):\n\u001b[1;32m--> 640\u001b[0m     response \u001b[39m=\u001b[39m \u001b[39mself\u001b[39;49m\u001b[39m.\u001b[39;49mparent\u001b[39m.\u001b[39;49merror(\n\u001b[0;32m    641\u001b[0m         \u001b[39m'\u001b[39;49m\u001b[39mhttp\u001b[39;49m\u001b[39m'\u001b[39;49m, request, response, code, msg, hdrs)\n\u001b[0;32m    643\u001b[0m \u001b[39mreturn\u001b[39;00m response\n",
      "File \u001b[1;32mC:\\Program Files\\WindowsApps\\PythonSoftwareFoundation.Python.3.8_3.8.2800.0_x64__qbz5n2kfra8p0\\lib\\urllib\\request.py:569\u001b[0m, in \u001b[0;36mOpenerDirector.error\u001b[1;34m(self, proto, *args)\u001b[0m\n\u001b[0;32m    567\u001b[0m \u001b[39mif\u001b[39;00m http_err:\n\u001b[0;32m    568\u001b[0m     args \u001b[39m=\u001b[39m (\u001b[39mdict\u001b[39m, \u001b[39m'\u001b[39m\u001b[39mdefault\u001b[39m\u001b[39m'\u001b[39m, \u001b[39m'\u001b[39m\u001b[39mhttp_error_default\u001b[39m\u001b[39m'\u001b[39m) \u001b[39m+\u001b[39m orig_args\n\u001b[1;32m--> 569\u001b[0m     \u001b[39mreturn\u001b[39;00m \u001b[39mself\u001b[39;49m\u001b[39m.\u001b[39;49m_call_chain(\u001b[39m*\u001b[39;49margs)\n",
      "File \u001b[1;32mC:\\Program Files\\WindowsApps\\PythonSoftwareFoundation.Python.3.8_3.8.2800.0_x64__qbz5n2kfra8p0\\lib\\urllib\\request.py:502\u001b[0m, in \u001b[0;36mOpenerDirector._call_chain\u001b[1;34m(self, chain, kind, meth_name, *args)\u001b[0m\n\u001b[0;32m    500\u001b[0m \u001b[39mfor\u001b[39;00m handler \u001b[39min\u001b[39;00m handlers:\n\u001b[0;32m    501\u001b[0m     func \u001b[39m=\u001b[39m \u001b[39mgetattr\u001b[39m(handler, meth_name)\n\u001b[1;32m--> 502\u001b[0m     result \u001b[39m=\u001b[39m func(\u001b[39m*\u001b[39;49margs)\n\u001b[0;32m    503\u001b[0m     \u001b[39mif\u001b[39;00m result \u001b[39mis\u001b[39;00m \u001b[39mnot\u001b[39;00m \u001b[39mNone\u001b[39;00m:\n\u001b[0;32m    504\u001b[0m         \u001b[39mreturn\u001b[39;00m result\n",
      "File \u001b[1;32mC:\\Program Files\\WindowsApps\\PythonSoftwareFoundation.Python.3.8_3.8.2800.0_x64__qbz5n2kfra8p0\\lib\\urllib\\request.py:649\u001b[0m, in \u001b[0;36mHTTPDefaultErrorHandler.http_error_default\u001b[1;34m(self, req, fp, code, msg, hdrs)\u001b[0m\n\u001b[0;32m    648\u001b[0m \u001b[39mdef\u001b[39;00m \u001b[39mhttp_error_default\u001b[39m(\u001b[39mself\u001b[39m, req, fp, code, msg, hdrs):\n\u001b[1;32m--> 649\u001b[0m     \u001b[39mraise\u001b[39;00m HTTPError(req\u001b[39m.\u001b[39mfull_url, code, msg, hdrs, fp)\n",
      "\u001b[1;31mHTTPError\u001b[0m: HTTP Error 503: Service Unavailable"
     ]
    }
   ],
   "source": [
    "import json\n",
    "url = 'https://v5.bvg.transport.rest/stops/nearby?latitude=52.520658&longitude=13.411875&results=5'\n",
    "html = urllib.request.urlopen(url).read()\n",
    "x= json.loads(html) #make json from html\n",
    "print(len(x))\n",
    "print(html.decode())\n"
   ]
  },
  {
   "cell_type": "code",
   "execution_count": null,
   "metadata": {},
   "outputs": [
    {
     "name": "stderr",
     "output_type": "stream",
     "text": [
      "Error while getting Updates: Conflict: terminated by other getUpdates request; make sure that only one bot instance is running\n",
      "No error handlers are registered, logging exception.\n",
      "Traceback (most recent call last):\n",
      "  File \"C:\\Users\\alexb\\AppData\\Local\\Packages\\PythonSoftwareFoundation.Python.3.8_qbz5n2kfra8p0\\LocalCache\\local-packages\\Python38\\site-packages\\telegram\\ext\\updater.py\", line 646, in _network_loop_retry\n",
      "    if not action_cb():\n",
      "  File \"C:\\Users\\alexb\\AppData\\Local\\Packages\\PythonSoftwareFoundation.Python.3.8_qbz5n2kfra8p0\\LocalCache\\local-packages\\Python38\\site-packages\\telegram\\ext\\updater.py\", line 597, in polling_action_cb\n",
      "    updates = self.bot.get_updates(\n",
      "  File \"C:\\Users\\alexb\\AppData\\Local\\Packages\\PythonSoftwareFoundation.Python.3.8_qbz5n2kfra8p0\\LocalCache\\local-packages\\Python38\\site-packages\\telegram\\ext\\extbot.py\", line 222, in get_updates\n",
      "    updates = super().get_updates(\n",
      "  File \"C:\\Users\\alexb\\AppData\\Local\\Packages\\PythonSoftwareFoundation.Python.3.8_qbz5n2kfra8p0\\LocalCache\\local-packages\\Python38\\site-packages\\telegram\\bot.py\", line 130, in decorator\n",
      "    result = func(*args, **kwargs)\n",
      "  File \"C:\\Users\\alexb\\AppData\\Local\\Packages\\PythonSoftwareFoundation.Python.3.8_qbz5n2kfra8p0\\LocalCache\\local-packages\\Python38\\site-packages\\telegram\\bot.py\", line 2861, in get_updates\n",
      "    self._post(\n",
      "  File \"C:\\Users\\alexb\\AppData\\Local\\Packages\\PythonSoftwareFoundation.Python.3.8_qbz5n2kfra8p0\\LocalCache\\local-packages\\Python38\\site-packages\\telegram\\bot.py\", line 295, in _post\n",
      "    return self.request.post(\n",
      "  File \"C:\\Users\\alexb\\AppData\\Local\\Packages\\PythonSoftwareFoundation.Python.3.8_qbz5n2kfra8p0\\LocalCache\\local-packages\\Python38\\site-packages\\telegram\\utils\\request.py\", line 356, in post\n",
      "    result = self._request_wrapper(\n",
      "  File \"C:\\Users\\alexb\\AppData\\Local\\Packages\\PythonSoftwareFoundation.Python.3.8_qbz5n2kfra8p0\\LocalCache\\local-packages\\Python38\\site-packages\\telegram\\utils\\request.py\", line 283, in _request_wrapper\n",
      "    raise Conflict(message)\n",
      "telegram.error.Conflict: Conflict: terminated by other getUpdates request; make sure that only one bot instance is running\n",
      "Error while getting Updates: Conflict: terminated by other getUpdates request; make sure that only one bot instance is running\n",
      "No error handlers are registered, logging exception.\n",
      "Traceback (most recent call last):\n",
      "  File \"C:\\Users\\alexb\\AppData\\Local\\Packages\\PythonSoftwareFoundation.Python.3.8_qbz5n2kfra8p0\\LocalCache\\local-packages\\Python38\\site-packages\\telegram\\ext\\updater.py\", line 646, in _network_loop_retry\n",
      "    if not action_cb():\n",
      "  File \"C:\\Users\\alexb\\AppData\\Local\\Packages\\PythonSoftwareFoundation.Python.3.8_qbz5n2kfra8p0\\LocalCache\\local-packages\\Python38\\site-packages\\telegram\\ext\\updater.py\", line 597, in polling_action_cb\n",
      "    updates = self.bot.get_updates(\n",
      "  File \"C:\\Users\\alexb\\AppData\\Local\\Packages\\PythonSoftwareFoundation.Python.3.8_qbz5n2kfra8p0\\LocalCache\\local-packages\\Python38\\site-packages\\telegram\\ext\\extbot.py\", line 222, in get_updates\n",
      "    updates = super().get_updates(\n",
      "  File \"C:\\Users\\alexb\\AppData\\Local\\Packages\\PythonSoftwareFoundation.Python.3.8_qbz5n2kfra8p0\\LocalCache\\local-packages\\Python38\\site-packages\\telegram\\bot.py\", line 130, in decorator\n",
      "    result = func(*args, **kwargs)\n",
      "  File \"C:\\Users\\alexb\\AppData\\Local\\Packages\\PythonSoftwareFoundation.Python.3.8_qbz5n2kfra8p0\\LocalCache\\local-packages\\Python38\\site-packages\\telegram\\bot.py\", line 2861, in get_updates\n",
      "    self._post(\n",
      "  File \"C:\\Users\\alexb\\AppData\\Local\\Packages\\PythonSoftwareFoundation.Python.3.8_qbz5n2kfra8p0\\LocalCache\\local-packages\\Python38\\site-packages\\telegram\\bot.py\", line 295, in _post\n",
      "    return self.request.post(\n",
      "  File \"C:\\Users\\alexb\\AppData\\Local\\Packages\\PythonSoftwareFoundation.Python.3.8_qbz5n2kfra8p0\\LocalCache\\local-packages\\Python38\\site-packages\\telegram\\utils\\request.py\", line 356, in post\n",
      "    result = self._request_wrapper(\n",
      "  File \"C:\\Users\\alexb\\AppData\\Local\\Packages\\PythonSoftwareFoundation.Python.3.8_qbz5n2kfra8p0\\LocalCache\\local-packages\\Python38\\site-packages\\telegram\\utils\\request.py\", line 283, in _request_wrapper\n",
      "    raise Conflict(message)\n",
      "telegram.error.Conflict: Conflict: terminated by other getUpdates request; make sure that only one bot instance is running\n",
      "Error while getting Updates: Conflict: terminated by other getUpdates request; make sure that only one bot instance is running\n",
      "No error handlers are registered, logging exception.\n",
      "Traceback (most recent call last):\n",
      "  File \"C:\\Users\\alexb\\AppData\\Local\\Packages\\PythonSoftwareFoundation.Python.3.8_qbz5n2kfra8p0\\LocalCache\\local-packages\\Python38\\site-packages\\telegram\\ext\\updater.py\", line 646, in _network_loop_retry\n",
      "    if not action_cb():\n",
      "  File \"C:\\Users\\alexb\\AppData\\Local\\Packages\\PythonSoftwareFoundation.Python.3.8_qbz5n2kfra8p0\\LocalCache\\local-packages\\Python38\\site-packages\\telegram\\ext\\updater.py\", line 597, in polling_action_cb\n",
      "    updates = self.bot.get_updates(\n",
      "  File \"C:\\Users\\alexb\\AppData\\Local\\Packages\\PythonSoftwareFoundation.Python.3.8_qbz5n2kfra8p0\\LocalCache\\local-packages\\Python38\\site-packages\\telegram\\ext\\extbot.py\", line 222, in get_updates\n",
      "    updates = super().get_updates(\n",
      "  File \"C:\\Users\\alexb\\AppData\\Local\\Packages\\PythonSoftwareFoundation.Python.3.8_qbz5n2kfra8p0\\LocalCache\\local-packages\\Python38\\site-packages\\telegram\\bot.py\", line 130, in decorator\n",
      "    result = func(*args, **kwargs)\n",
      "  File \"C:\\Users\\alexb\\AppData\\Local\\Packages\\PythonSoftwareFoundation.Python.3.8_qbz5n2kfra8p0\\LocalCache\\local-packages\\Python38\\site-packages\\telegram\\bot.py\", line 2861, in get_updates\n",
      "    self._post(\n",
      "  File \"C:\\Users\\alexb\\AppData\\Local\\Packages\\PythonSoftwareFoundation.Python.3.8_qbz5n2kfra8p0\\LocalCache\\local-packages\\Python38\\site-packages\\telegram\\bot.py\", line 295, in _post\n",
      "    return self.request.post(\n",
      "  File \"C:\\Users\\alexb\\AppData\\Local\\Packages\\PythonSoftwareFoundation.Python.3.8_qbz5n2kfra8p0\\LocalCache\\local-packages\\Python38\\site-packages\\telegram\\utils\\request.py\", line 356, in post\n",
      "    result = self._request_wrapper(\n",
      "  File \"C:\\Users\\alexb\\AppData\\Local\\Packages\\PythonSoftwareFoundation.Python.3.8_qbz5n2kfra8p0\\LocalCache\\local-packages\\Python38\\site-packages\\telegram\\utils\\request.py\", line 283, in _request_wrapper\n",
      "    raise Conflict(message)\n",
      "telegram.error.Conflict: Conflict: terminated by other getUpdates request; make sure that only one bot instance is running\n",
      "Error while getting Updates: Conflict: terminated by other getUpdates request; make sure that only one bot instance is running\n",
      "No error handlers are registered, logging exception.\n",
      "Traceback (most recent call last):\n",
      "  File \"C:\\Users\\alexb\\AppData\\Local\\Packages\\PythonSoftwareFoundation.Python.3.8_qbz5n2kfra8p0\\LocalCache\\local-packages\\Python38\\site-packages\\telegram\\ext\\updater.py\", line 646, in _network_loop_retry\n",
      "    if not action_cb():\n",
      "  File \"C:\\Users\\alexb\\AppData\\Local\\Packages\\PythonSoftwareFoundation.Python.3.8_qbz5n2kfra8p0\\LocalCache\\local-packages\\Python38\\site-packages\\telegram\\ext\\updater.py\", line 597, in polling_action_cb\n",
      "    updates = self.bot.get_updates(\n",
      "  File \"C:\\Users\\alexb\\AppData\\Local\\Packages\\PythonSoftwareFoundation.Python.3.8_qbz5n2kfra8p0\\LocalCache\\local-packages\\Python38\\site-packages\\telegram\\ext\\extbot.py\", line 222, in get_updates\n",
      "    updates = super().get_updates(\n",
      "  File \"C:\\Users\\alexb\\AppData\\Local\\Packages\\PythonSoftwareFoundation.Python.3.8_qbz5n2kfra8p0\\LocalCache\\local-packages\\Python38\\site-packages\\telegram\\bot.py\", line 130, in decorator\n",
      "    result = func(*args, **kwargs)\n",
      "  File \"C:\\Users\\alexb\\AppData\\Local\\Packages\\PythonSoftwareFoundation.Python.3.8_qbz5n2kfra8p0\\LocalCache\\local-packages\\Python38\\site-packages\\telegram\\bot.py\", line 2861, in get_updates\n",
      "    self._post(\n",
      "  File \"C:\\Users\\alexb\\AppData\\Local\\Packages\\PythonSoftwareFoundation.Python.3.8_qbz5n2kfra8p0\\LocalCache\\local-packages\\Python38\\site-packages\\telegram\\bot.py\", line 295, in _post\n",
      "    return self.request.post(\n",
      "  File \"C:\\Users\\alexb\\AppData\\Local\\Packages\\PythonSoftwareFoundation.Python.3.8_qbz5n2kfra8p0\\LocalCache\\local-packages\\Python38\\site-packages\\telegram\\utils\\request.py\", line 356, in post\n",
      "    result = self._request_wrapper(\n",
      "  File \"C:\\Users\\alexb\\AppData\\Local\\Packages\\PythonSoftwareFoundation.Python.3.8_qbz5n2kfra8p0\\LocalCache\\local-packages\\Python38\\site-packages\\telegram\\utils\\request.py\", line 283, in _request_wrapper\n",
      "    raise Conflict(message)\n",
      "telegram.error.Conflict: Conflict: terminated by other getUpdates request; make sure that only one bot instance is running\n",
      "Error while getting Updates: Conflict: terminated by other getUpdates request; make sure that only one bot instance is running\n",
      "No error handlers are registered, logging exception.\n",
      "Traceback (most recent call last):\n",
      "  File \"C:\\Users\\alexb\\AppData\\Local\\Packages\\PythonSoftwareFoundation.Python.3.8_qbz5n2kfra8p0\\LocalCache\\local-packages\\Python38\\site-packages\\telegram\\ext\\updater.py\", line 646, in _network_loop_retry\n",
      "    if not action_cb():\n",
      "  File \"C:\\Users\\alexb\\AppData\\Local\\Packages\\PythonSoftwareFoundation.Python.3.8_qbz5n2kfra8p0\\LocalCache\\local-packages\\Python38\\site-packages\\telegram\\ext\\updater.py\", line 597, in polling_action_cb\n",
      "    updates = self.bot.get_updates(\n",
      "  File \"C:\\Users\\alexb\\AppData\\Local\\Packages\\PythonSoftwareFoundation.Python.3.8_qbz5n2kfra8p0\\LocalCache\\local-packages\\Python38\\site-packages\\telegram\\ext\\extbot.py\", line 222, in get_updates\n",
      "    updates = super().get_updates(\n",
      "  File \"C:\\Users\\alexb\\AppData\\Local\\Packages\\PythonSoftwareFoundation.Python.3.8_qbz5n2kfra8p0\\LocalCache\\local-packages\\Python38\\site-packages\\telegram\\bot.py\", line 130, in decorator\n",
      "    result = func(*args, **kwargs)\n",
      "  File \"C:\\Users\\alexb\\AppData\\Local\\Packages\\PythonSoftwareFoundation.Python.3.8_qbz5n2kfra8p0\\LocalCache\\local-packages\\Python38\\site-packages\\telegram\\bot.py\", line 2861, in get_updates\n",
      "    self._post(\n",
      "  File \"C:\\Users\\alexb\\AppData\\Local\\Packages\\PythonSoftwareFoundation.Python.3.8_qbz5n2kfra8p0\\LocalCache\\local-packages\\Python38\\site-packages\\telegram\\bot.py\", line 295, in _post\n",
      "    return self.request.post(\n",
      "  File \"C:\\Users\\alexb\\AppData\\Local\\Packages\\PythonSoftwareFoundation.Python.3.8_qbz5n2kfra8p0\\LocalCache\\local-packages\\Python38\\site-packages\\telegram\\utils\\request.py\", line 356, in post\n",
      "    result = self._request_wrapper(\n",
      "  File \"C:\\Users\\alexb\\AppData\\Local\\Packages\\PythonSoftwareFoundation.Python.3.8_qbz5n2kfra8p0\\LocalCache\\local-packages\\Python38\\site-packages\\telegram\\utils\\request.py\", line 283, in _request_wrapper\n",
      "    raise Conflict(message)\n",
      "telegram.error.Conflict: Conflict: terminated by other getUpdates request; make sure that only one bot instance is running\n",
      "Error while getting Updates: Conflict: terminated by other getUpdates request; make sure that only one bot instance is running\n",
      "No error handlers are registered, logging exception.\n",
      "Traceback (most recent call last):\n",
      "  File \"C:\\Users\\alexb\\AppData\\Local\\Packages\\PythonSoftwareFoundation.Python.3.8_qbz5n2kfra8p0\\LocalCache\\local-packages\\Python38\\site-packages\\telegram\\ext\\updater.py\", line 646, in _network_loop_retry\n",
      "    if not action_cb():\n",
      "  File \"C:\\Users\\alexb\\AppData\\Local\\Packages\\PythonSoftwareFoundation.Python.3.8_qbz5n2kfra8p0\\LocalCache\\local-packages\\Python38\\site-packages\\telegram\\ext\\updater.py\", line 597, in polling_action_cb\n",
      "    updates = self.bot.get_updates(\n",
      "  File \"C:\\Users\\alexb\\AppData\\Local\\Packages\\PythonSoftwareFoundation.Python.3.8_qbz5n2kfra8p0\\LocalCache\\local-packages\\Python38\\site-packages\\telegram\\ext\\extbot.py\", line 222, in get_updates\n",
      "    updates = super().get_updates(\n",
      "  File \"C:\\Users\\alexb\\AppData\\Local\\Packages\\PythonSoftwareFoundation.Python.3.8_qbz5n2kfra8p0\\LocalCache\\local-packages\\Python38\\site-packages\\telegram\\bot.py\", line 130, in decorator\n",
      "    result = func(*args, **kwargs)\n",
      "  File \"C:\\Users\\alexb\\AppData\\Local\\Packages\\PythonSoftwareFoundation.Python.3.8_qbz5n2kfra8p0\\LocalCache\\local-packages\\Python38\\site-packages\\telegram\\bot.py\", line 2861, in get_updates\n",
      "    self._post(\n",
      "  File \"C:\\Users\\alexb\\AppData\\Local\\Packages\\PythonSoftwareFoundation.Python.3.8_qbz5n2kfra8p0\\LocalCache\\local-packages\\Python38\\site-packages\\telegram\\bot.py\", line 295, in _post\n",
      "    return self.request.post(\n",
      "  File \"C:\\Users\\alexb\\AppData\\Local\\Packages\\PythonSoftwareFoundation.Python.3.8_qbz5n2kfra8p0\\LocalCache\\local-packages\\Python38\\site-packages\\telegram\\utils\\request.py\", line 356, in post\n",
      "    result = self._request_wrapper(\n",
      "  File \"C:\\Users\\alexb\\AppData\\Local\\Packages\\PythonSoftwareFoundation.Python.3.8_qbz5n2kfra8p0\\LocalCache\\local-packages\\Python38\\site-packages\\telegram\\utils\\request.py\", line 283, in _request_wrapper\n",
      "    raise Conflict(message)\n",
      "telegram.error.Conflict: Conflict: terminated by other getUpdates request; make sure that only one bot instance is running\n",
      "Error while getting Updates: Conflict: terminated by other getUpdates request; make sure that only one bot instance is running\n",
      "No error handlers are registered, logging exception.\n",
      "Traceback (most recent call last):\n",
      "  File \"C:\\Users\\alexb\\AppData\\Local\\Packages\\PythonSoftwareFoundation.Python.3.8_qbz5n2kfra8p0\\LocalCache\\local-packages\\Python38\\site-packages\\telegram\\ext\\updater.py\", line 646, in _network_loop_retry\n",
      "    if not action_cb():\n",
      "  File \"C:\\Users\\alexb\\AppData\\Local\\Packages\\PythonSoftwareFoundation.Python.3.8_qbz5n2kfra8p0\\LocalCache\\local-packages\\Python38\\site-packages\\telegram\\ext\\updater.py\", line 597, in polling_action_cb\n",
      "    updates = self.bot.get_updates(\n",
      "  File \"C:\\Users\\alexb\\AppData\\Local\\Packages\\PythonSoftwareFoundation.Python.3.8_qbz5n2kfra8p0\\LocalCache\\local-packages\\Python38\\site-packages\\telegram\\ext\\extbot.py\", line 222, in get_updates\n",
      "    updates = super().get_updates(\n",
      "  File \"C:\\Users\\alexb\\AppData\\Local\\Packages\\PythonSoftwareFoundation.Python.3.8_qbz5n2kfra8p0\\LocalCache\\local-packages\\Python38\\site-packages\\telegram\\bot.py\", line 130, in decorator\n",
      "    result = func(*args, **kwargs)\n",
      "  File \"C:\\Users\\alexb\\AppData\\Local\\Packages\\PythonSoftwareFoundation.Python.3.8_qbz5n2kfra8p0\\LocalCache\\local-packages\\Python38\\site-packages\\telegram\\bot.py\", line 2861, in get_updates\n",
      "    self._post(\n",
      "  File \"C:\\Users\\alexb\\AppData\\Local\\Packages\\PythonSoftwareFoundation.Python.3.8_qbz5n2kfra8p0\\LocalCache\\local-packages\\Python38\\site-packages\\telegram\\bot.py\", line 295, in _post\n",
      "    return self.request.post(\n",
      "  File \"C:\\Users\\alexb\\AppData\\Local\\Packages\\PythonSoftwareFoundation.Python.3.8_qbz5n2kfra8p0\\LocalCache\\local-packages\\Python38\\site-packages\\telegram\\utils\\request.py\", line 356, in post\n",
      "    result = self._request_wrapper(\n",
      "  File \"C:\\Users\\alexb\\AppData\\Local\\Packages\\PythonSoftwareFoundation.Python.3.8_qbz5n2kfra8p0\\LocalCache\\local-packages\\Python38\\site-packages\\telegram\\utils\\request.py\", line 283, in _request_wrapper\n",
      "    raise Conflict(message)\n",
      "telegram.error.Conflict: Conflict: terminated by other getUpdates request; make sure that only one bot instance is running\n",
      "Error while getting Updates: Conflict: terminated by other getUpdates request; make sure that only one bot instance is running\n",
      "No error handlers are registered, logging exception.\n",
      "Traceback (most recent call last):\n",
      "  File \"C:\\Users\\alexb\\AppData\\Local\\Packages\\PythonSoftwareFoundation.Python.3.8_qbz5n2kfra8p0\\LocalCache\\local-packages\\Python38\\site-packages\\telegram\\ext\\updater.py\", line 646, in _network_loop_retry\n",
      "    if not action_cb():\n",
      "  File \"C:\\Users\\alexb\\AppData\\Local\\Packages\\PythonSoftwareFoundation.Python.3.8_qbz5n2kfra8p0\\LocalCache\\local-packages\\Python38\\site-packages\\telegram\\ext\\updater.py\", line 597, in polling_action_cb\n",
      "    updates = self.bot.get_updates(\n",
      "  File \"C:\\Users\\alexb\\AppData\\Local\\Packages\\PythonSoftwareFoundation.Python.3.8_qbz5n2kfra8p0\\LocalCache\\local-packages\\Python38\\site-packages\\telegram\\ext\\extbot.py\", line 222, in get_updates\n",
      "    updates = super().get_updates(\n",
      "  File \"C:\\Users\\alexb\\AppData\\Local\\Packages\\PythonSoftwareFoundation.Python.3.8_qbz5n2kfra8p0\\LocalCache\\local-packages\\Python38\\site-packages\\telegram\\bot.py\", line 130, in decorator\n",
      "    result = func(*args, **kwargs)\n",
      "  File \"C:\\Users\\alexb\\AppData\\Local\\Packages\\PythonSoftwareFoundation.Python.3.8_qbz5n2kfra8p0\\LocalCache\\local-packages\\Python38\\site-packages\\telegram\\bot.py\", line 2861, in get_updates\n",
      "    self._post(\n",
      "  File \"C:\\Users\\alexb\\AppData\\Local\\Packages\\PythonSoftwareFoundation.Python.3.8_qbz5n2kfra8p0\\LocalCache\\local-packages\\Python38\\site-packages\\telegram\\bot.py\", line 295, in _post\n",
      "    return self.request.post(\n",
      "  File \"C:\\Users\\alexb\\AppData\\Local\\Packages\\PythonSoftwareFoundation.Python.3.8_qbz5n2kfra8p0\\LocalCache\\local-packages\\Python38\\site-packages\\telegram\\utils\\request.py\", line 356, in post\n",
      "    result = self._request_wrapper(\n",
      "  File \"C:\\Users\\alexb\\AppData\\Local\\Packages\\PythonSoftwareFoundation.Python.3.8_qbz5n2kfra8p0\\LocalCache\\local-packages\\Python38\\site-packages\\telegram\\utils\\request.py\", line 283, in _request_wrapper\n",
      "    raise Conflict(message)\n",
      "telegram.error.Conflict: Conflict: terminated by other getUpdates request; make sure that only one bot instance is running\n",
      "Error while getting Updates: Conflict: terminated by other getUpdates request; make sure that only one bot instance is running\n",
      "No error handlers are registered, logging exception.\n",
      "Traceback (most recent call last):\n",
      "  File \"C:\\Users\\alexb\\AppData\\Local\\Packages\\PythonSoftwareFoundation.Python.3.8_qbz5n2kfra8p0\\LocalCache\\local-packages\\Python38\\site-packages\\telegram\\ext\\updater.py\", line 646, in _network_loop_retry\n",
      "    if not action_cb():\n",
      "  File \"C:\\Users\\alexb\\AppData\\Local\\Packages\\PythonSoftwareFoundation.Python.3.8_qbz5n2kfra8p0\\LocalCache\\local-packages\\Python38\\site-packages\\telegram\\ext\\updater.py\", line 597, in polling_action_cb\n",
      "    updates = self.bot.get_updates(\n",
      "  File \"C:\\Users\\alexb\\AppData\\Local\\Packages\\PythonSoftwareFoundation.Python.3.8_qbz5n2kfra8p0\\LocalCache\\local-packages\\Python38\\site-packages\\telegram\\ext\\extbot.py\", line 222, in get_updates\n",
      "    updates = super().get_updates(\n",
      "  File \"C:\\Users\\alexb\\AppData\\Local\\Packages\\PythonSoftwareFoundation.Python.3.8_qbz5n2kfra8p0\\LocalCache\\local-packages\\Python38\\site-packages\\telegram\\bot.py\", line 130, in decorator\n",
      "    result = func(*args, **kwargs)\n",
      "  File \"C:\\Users\\alexb\\AppData\\Local\\Packages\\PythonSoftwareFoundation.Python.3.8_qbz5n2kfra8p0\\LocalCache\\local-packages\\Python38\\site-packages\\telegram\\bot.py\", line 2861, in get_updates\n",
      "    self._post(\n",
      "  File \"C:\\Users\\alexb\\AppData\\Local\\Packages\\PythonSoftwareFoundation.Python.3.8_qbz5n2kfra8p0\\LocalCache\\local-packages\\Python38\\site-packages\\telegram\\bot.py\", line 295, in _post\n",
      "    return self.request.post(\n",
      "  File \"C:\\Users\\alexb\\AppData\\Local\\Packages\\PythonSoftwareFoundation.Python.3.8_qbz5n2kfra8p0\\LocalCache\\local-packages\\Python38\\site-packages\\telegram\\utils\\request.py\", line 356, in post\n",
      "    result = self._request_wrapper(\n",
      "  File \"C:\\Users\\alexb\\AppData\\Local\\Packages\\PythonSoftwareFoundation.Python.3.8_qbz5n2kfra8p0\\LocalCache\\local-packages\\Python38\\site-packages\\telegram\\utils\\request.py\", line 283, in _request_wrapper\n",
      "    raise Conflict(message)\n",
      "telegram.error.Conflict: Conflict: terminated by other getUpdates request; make sure that only one bot instance is running\n",
      "Error while getting Updates: Conflict: terminated by other getUpdates request; make sure that only one bot instance is running\n",
      "No error handlers are registered, logging exception.\n",
      "Traceback (most recent call last):\n",
      "  File \"C:\\Users\\alexb\\AppData\\Local\\Packages\\PythonSoftwareFoundation.Python.3.8_qbz5n2kfra8p0\\LocalCache\\local-packages\\Python38\\site-packages\\telegram\\ext\\updater.py\", line 646, in _network_loop_retry\n",
      "    if not action_cb():\n",
      "  File \"C:\\Users\\alexb\\AppData\\Local\\Packages\\PythonSoftwareFoundation.Python.3.8_qbz5n2kfra8p0\\LocalCache\\local-packages\\Python38\\site-packages\\telegram\\ext\\updater.py\", line 597, in polling_action_cb\n",
      "    updates = self.bot.get_updates(\n",
      "  File \"C:\\Users\\alexb\\AppData\\Local\\Packages\\PythonSoftwareFoundation.Python.3.8_qbz5n2kfra8p0\\LocalCache\\local-packages\\Python38\\site-packages\\telegram\\ext\\extbot.py\", line 222, in get_updates\n",
      "    updates = super().get_updates(\n",
      "  File \"C:\\Users\\alexb\\AppData\\Local\\Packages\\PythonSoftwareFoundation.Python.3.8_qbz5n2kfra8p0\\LocalCache\\local-packages\\Python38\\site-packages\\telegram\\bot.py\", line 130, in decorator\n",
      "    result = func(*args, **kwargs)\n",
      "  File \"C:\\Users\\alexb\\AppData\\Local\\Packages\\PythonSoftwareFoundation.Python.3.8_qbz5n2kfra8p0\\LocalCache\\local-packages\\Python38\\site-packages\\telegram\\bot.py\", line 2861, in get_updates\n",
      "    self._post(\n",
      "  File \"C:\\Users\\alexb\\AppData\\Local\\Packages\\PythonSoftwareFoundation.Python.3.8_qbz5n2kfra8p0\\LocalCache\\local-packages\\Python38\\site-packages\\telegram\\bot.py\", line 295, in _post\n",
      "    return self.request.post(\n",
      "  File \"C:\\Users\\alexb\\AppData\\Local\\Packages\\PythonSoftwareFoundation.Python.3.8_qbz5n2kfra8p0\\LocalCache\\local-packages\\Python38\\site-packages\\telegram\\utils\\request.py\", line 356, in post\n",
      "    result = self._request_wrapper(\n",
      "  File \"C:\\Users\\alexb\\AppData\\Local\\Packages\\PythonSoftwareFoundation.Python.3.8_qbz5n2kfra8p0\\LocalCache\\local-packages\\Python38\\site-packages\\telegram\\utils\\request.py\", line 283, in _request_wrapper\n",
      "    raise Conflict(message)\n",
      "telegram.error.Conflict: Conflict: terminated by other getUpdates request; make sure that only one bot instance is running\n",
      "Error while getting Updates: Conflict: terminated by other getUpdates request; make sure that only one bot instance is running\n",
      "No error handlers are registered, logging exception.\n",
      "Traceback (most recent call last):\n",
      "  File \"C:\\Users\\alexb\\AppData\\Local\\Packages\\PythonSoftwareFoundation.Python.3.8_qbz5n2kfra8p0\\LocalCache\\local-packages\\Python38\\site-packages\\telegram\\ext\\updater.py\", line 646, in _network_loop_retry\n",
      "    if not action_cb():\n",
      "  File \"C:\\Users\\alexb\\AppData\\Local\\Packages\\PythonSoftwareFoundation.Python.3.8_qbz5n2kfra8p0\\LocalCache\\local-packages\\Python38\\site-packages\\telegram\\ext\\updater.py\", line 597, in polling_action_cb\n",
      "    updates = self.bot.get_updates(\n",
      "  File \"C:\\Users\\alexb\\AppData\\Local\\Packages\\PythonSoftwareFoundation.Python.3.8_qbz5n2kfra8p0\\LocalCache\\local-packages\\Python38\\site-packages\\telegram\\ext\\extbot.py\", line 222, in get_updates\n",
      "    updates = super().get_updates(\n",
      "  File \"C:\\Users\\alexb\\AppData\\Local\\Packages\\PythonSoftwareFoundation.Python.3.8_qbz5n2kfra8p0\\LocalCache\\local-packages\\Python38\\site-packages\\telegram\\bot.py\", line 130, in decorator\n",
      "    result = func(*args, **kwargs)\n",
      "  File \"C:\\Users\\alexb\\AppData\\Local\\Packages\\PythonSoftwareFoundation.Python.3.8_qbz5n2kfra8p0\\LocalCache\\local-packages\\Python38\\site-packages\\telegram\\bot.py\", line 2861, in get_updates\n",
      "    self._post(\n",
      "  File \"C:\\Users\\alexb\\AppData\\Local\\Packages\\PythonSoftwareFoundation.Python.3.8_qbz5n2kfra8p0\\LocalCache\\local-packages\\Python38\\site-packages\\telegram\\bot.py\", line 295, in _post\n",
      "    return self.request.post(\n",
      "  File \"C:\\Users\\alexb\\AppData\\Local\\Packages\\PythonSoftwareFoundation.Python.3.8_qbz5n2kfra8p0\\LocalCache\\local-packages\\Python38\\site-packages\\telegram\\utils\\request.py\", line 356, in post\n",
      "    result = self._request_wrapper(\n",
      "  File \"C:\\Users\\alexb\\AppData\\Local\\Packages\\PythonSoftwareFoundation.Python.3.8_qbz5n2kfra8p0\\LocalCache\\local-packages\\Python38\\site-packages\\telegram\\utils\\request.py\", line 283, in _request_wrapper\n",
      "    raise Conflict(message)\n",
      "telegram.error.Conflict: Conflict: terminated by other getUpdates request; make sure that only one bot instance is running\n",
      "Error while getting Updates: Conflict: terminated by other getUpdates request; make sure that only one bot instance is running\n",
      "No error handlers are registered, logging exception.\n",
      "Traceback (most recent call last):\n",
      "  File \"C:\\Users\\alexb\\AppData\\Local\\Packages\\PythonSoftwareFoundation.Python.3.8_qbz5n2kfra8p0\\LocalCache\\local-packages\\Python38\\site-packages\\telegram\\ext\\updater.py\", line 646, in _network_loop_retry\n",
      "    if not action_cb():\n",
      "  File \"C:\\Users\\alexb\\AppData\\Local\\Packages\\PythonSoftwareFoundation.Python.3.8_qbz5n2kfra8p0\\LocalCache\\local-packages\\Python38\\site-packages\\telegram\\ext\\updater.py\", line 597, in polling_action_cb\n",
      "    updates = self.bot.get_updates(\n",
      "  File \"C:\\Users\\alexb\\AppData\\Local\\Packages\\PythonSoftwareFoundation.Python.3.8_qbz5n2kfra8p0\\LocalCache\\local-packages\\Python38\\site-packages\\telegram\\ext\\extbot.py\", line 222, in get_updates\n",
      "    updates = super().get_updates(\n",
      "  File \"C:\\Users\\alexb\\AppData\\Local\\Packages\\PythonSoftwareFoundation.Python.3.8_qbz5n2kfra8p0\\LocalCache\\local-packages\\Python38\\site-packages\\telegram\\bot.py\", line 130, in decorator\n",
      "    result = func(*args, **kwargs)\n",
      "  File \"C:\\Users\\alexb\\AppData\\Local\\Packages\\PythonSoftwareFoundation.Python.3.8_qbz5n2kfra8p0\\LocalCache\\local-packages\\Python38\\site-packages\\telegram\\bot.py\", line 2861, in get_updates\n",
      "    self._post(\n",
      "  File \"C:\\Users\\alexb\\AppData\\Local\\Packages\\PythonSoftwareFoundation.Python.3.8_qbz5n2kfra8p0\\LocalCache\\local-packages\\Python38\\site-packages\\telegram\\bot.py\", line 295, in _post\n",
      "    return self.request.post(\n",
      "  File \"C:\\Users\\alexb\\AppData\\Local\\Packages\\PythonSoftwareFoundation.Python.3.8_qbz5n2kfra8p0\\LocalCache\\local-packages\\Python38\\site-packages\\telegram\\utils\\request.py\", line 356, in post\n",
      "    result = self._request_wrapper(\n",
      "  File \"C:\\Users\\alexb\\AppData\\Local\\Packages\\PythonSoftwareFoundation.Python.3.8_qbz5n2kfra8p0\\LocalCache\\local-packages\\Python38\\site-packages\\telegram\\utils\\request.py\", line 283, in _request_wrapper\n",
      "    raise Conflict(message)\n",
      "telegram.error.Conflict: Conflict: terminated by other getUpdates request; make sure that only one bot instance is running\n",
      "Error while getting Updates: Conflict: terminated by other getUpdates request; make sure that only one bot instance is running\n",
      "No error handlers are registered, logging exception.\n",
      "Traceback (most recent call last):\n",
      "  File \"C:\\Users\\alexb\\AppData\\Local\\Packages\\PythonSoftwareFoundation.Python.3.8_qbz5n2kfra8p0\\LocalCache\\local-packages\\Python38\\site-packages\\telegram\\ext\\updater.py\", line 646, in _network_loop_retry\n",
      "    if not action_cb():\n",
      "  File \"C:\\Users\\alexb\\AppData\\Local\\Packages\\PythonSoftwareFoundation.Python.3.8_qbz5n2kfra8p0\\LocalCache\\local-packages\\Python38\\site-packages\\telegram\\ext\\updater.py\", line 597, in polling_action_cb\n",
      "    updates = self.bot.get_updates(\n",
      "  File \"C:\\Users\\alexb\\AppData\\Local\\Packages\\PythonSoftwareFoundation.Python.3.8_qbz5n2kfra8p0\\LocalCache\\local-packages\\Python38\\site-packages\\telegram\\ext\\extbot.py\", line 222, in get_updates\n",
      "    updates = super().get_updates(\n",
      "  File \"C:\\Users\\alexb\\AppData\\Local\\Packages\\PythonSoftwareFoundation.Python.3.8_qbz5n2kfra8p0\\LocalCache\\local-packages\\Python38\\site-packages\\telegram\\bot.py\", line 130, in decorator\n",
      "    result = func(*args, **kwargs)\n",
      "  File \"C:\\Users\\alexb\\AppData\\Local\\Packages\\PythonSoftwareFoundation.Python.3.8_qbz5n2kfra8p0\\LocalCache\\local-packages\\Python38\\site-packages\\telegram\\bot.py\", line 2861, in get_updates\n",
      "    self._post(\n",
      "  File \"C:\\Users\\alexb\\AppData\\Local\\Packages\\PythonSoftwareFoundation.Python.3.8_qbz5n2kfra8p0\\LocalCache\\local-packages\\Python38\\site-packages\\telegram\\bot.py\", line 295, in _post\n",
      "    return self.request.post(\n",
      "  File \"C:\\Users\\alexb\\AppData\\Local\\Packages\\PythonSoftwareFoundation.Python.3.8_qbz5n2kfra8p0\\LocalCache\\local-packages\\Python38\\site-packages\\telegram\\utils\\request.py\", line 356, in post\n",
      "    result = self._request_wrapper(\n",
      "  File \"C:\\Users\\alexb\\AppData\\Local\\Packages\\PythonSoftwareFoundation.Python.3.8_qbz5n2kfra8p0\\LocalCache\\local-packages\\Python38\\site-packages\\telegram\\utils\\request.py\", line 283, in _request_wrapper\n",
      "    raise Conflict(message)\n",
      "telegram.error.Conflict: Conflict: terminated by other getUpdates request; make sure that only one bot instance is running\n",
      "Error while getting Updates: Conflict: terminated by other getUpdates request; make sure that only one bot instance is running\n",
      "No error handlers are registered, logging exception.\n",
      "Traceback (most recent call last):\n",
      "  File \"C:\\Users\\alexb\\AppData\\Local\\Packages\\PythonSoftwareFoundation.Python.3.8_qbz5n2kfra8p0\\LocalCache\\local-packages\\Python38\\site-packages\\telegram\\ext\\updater.py\", line 646, in _network_loop_retry\n",
      "    if not action_cb():\n",
      "  File \"C:\\Users\\alexb\\AppData\\Local\\Packages\\PythonSoftwareFoundation.Python.3.8_qbz5n2kfra8p0\\LocalCache\\local-packages\\Python38\\site-packages\\telegram\\ext\\updater.py\", line 597, in polling_action_cb\n",
      "    updates = self.bot.get_updates(\n",
      "  File \"C:\\Users\\alexb\\AppData\\Local\\Packages\\PythonSoftwareFoundation.Python.3.8_qbz5n2kfra8p0\\LocalCache\\local-packages\\Python38\\site-packages\\telegram\\ext\\extbot.py\", line 222, in get_updates\n",
      "    updates = super().get_updates(\n",
      "  File \"C:\\Users\\alexb\\AppData\\Local\\Packages\\PythonSoftwareFoundation.Python.3.8_qbz5n2kfra8p0\\LocalCache\\local-packages\\Python38\\site-packages\\telegram\\bot.py\", line 130, in decorator\n",
      "    result = func(*args, **kwargs)\n",
      "  File \"C:\\Users\\alexb\\AppData\\Local\\Packages\\PythonSoftwareFoundation.Python.3.8_qbz5n2kfra8p0\\LocalCache\\local-packages\\Python38\\site-packages\\telegram\\bot.py\", line 2861, in get_updates\n",
      "    self._post(\n",
      "  File \"C:\\Users\\alexb\\AppData\\Local\\Packages\\PythonSoftwareFoundation.Python.3.8_qbz5n2kfra8p0\\LocalCache\\local-packages\\Python38\\site-packages\\telegram\\bot.py\", line 295, in _post\n",
      "    return self.request.post(\n",
      "  File \"C:\\Users\\alexb\\AppData\\Local\\Packages\\PythonSoftwareFoundation.Python.3.8_qbz5n2kfra8p0\\LocalCache\\local-packages\\Python38\\site-packages\\telegram\\utils\\request.py\", line 356, in post\n",
      "    result = self._request_wrapper(\n",
      "  File \"C:\\Users\\alexb\\AppData\\Local\\Packages\\PythonSoftwareFoundation.Python.3.8_qbz5n2kfra8p0\\LocalCache\\local-packages\\Python38\\site-packages\\telegram\\utils\\request.py\", line 283, in _request_wrapper\n",
      "    raise Conflict(message)\n",
      "telegram.error.Conflict: Conflict: terminated by other getUpdates request; make sure that only one bot instance is running\n",
      "Error while getting Updates: Conflict: terminated by other getUpdates request; make sure that only one bot instance is running\n",
      "No error handlers are registered, logging exception.\n",
      "Traceback (most recent call last):\n",
      "  File \"C:\\Users\\alexb\\AppData\\Local\\Packages\\PythonSoftwareFoundation.Python.3.8_qbz5n2kfra8p0\\LocalCache\\local-packages\\Python38\\site-packages\\telegram\\ext\\updater.py\", line 646, in _network_loop_retry\n",
      "    if not action_cb():\n",
      "  File \"C:\\Users\\alexb\\AppData\\Local\\Packages\\PythonSoftwareFoundation.Python.3.8_qbz5n2kfra8p0\\LocalCache\\local-packages\\Python38\\site-packages\\telegram\\ext\\updater.py\", line 597, in polling_action_cb\n",
      "    updates = self.bot.get_updates(\n",
      "  File \"C:\\Users\\alexb\\AppData\\Local\\Packages\\PythonSoftwareFoundation.Python.3.8_qbz5n2kfra8p0\\LocalCache\\local-packages\\Python38\\site-packages\\telegram\\ext\\extbot.py\", line 222, in get_updates\n",
      "    updates = super().get_updates(\n",
      "  File \"C:\\Users\\alexb\\AppData\\Local\\Packages\\PythonSoftwareFoundation.Python.3.8_qbz5n2kfra8p0\\LocalCache\\local-packages\\Python38\\site-packages\\telegram\\bot.py\", line 130, in decorator\n",
      "    result = func(*args, **kwargs)\n",
      "  File \"C:\\Users\\alexb\\AppData\\Local\\Packages\\PythonSoftwareFoundation.Python.3.8_qbz5n2kfra8p0\\LocalCache\\local-packages\\Python38\\site-packages\\telegram\\bot.py\", line 2861, in get_updates\n",
      "    self._post(\n",
      "  File \"C:\\Users\\alexb\\AppData\\Local\\Packages\\PythonSoftwareFoundation.Python.3.8_qbz5n2kfra8p0\\LocalCache\\local-packages\\Python38\\site-packages\\telegram\\bot.py\", line 295, in _post\n",
      "    return self.request.post(\n",
      "  File \"C:\\Users\\alexb\\AppData\\Local\\Packages\\PythonSoftwareFoundation.Python.3.8_qbz5n2kfra8p0\\LocalCache\\local-packages\\Python38\\site-packages\\telegram\\utils\\request.py\", line 356, in post\n",
      "    result = self._request_wrapper(\n",
      "  File \"C:\\Users\\alexb\\AppData\\Local\\Packages\\PythonSoftwareFoundation.Python.3.8_qbz5n2kfra8p0\\LocalCache\\local-packages\\Python38\\site-packages\\telegram\\utils\\request.py\", line 283, in _request_wrapper\n",
      "    raise Conflict(message)\n",
      "telegram.error.Conflict: Conflict: terminated by other getUpdates request; make sure that only one bot instance is running\n",
      "Error while getting Updates: Conflict: terminated by other getUpdates request; make sure that only one bot instance is running\n",
      "No error handlers are registered, logging exception.\n",
      "Traceback (most recent call last):\n",
      "  File \"C:\\Users\\alexb\\AppData\\Local\\Packages\\PythonSoftwareFoundation.Python.3.8_qbz5n2kfra8p0\\LocalCache\\local-packages\\Python38\\site-packages\\telegram\\ext\\updater.py\", line 646, in _network_loop_retry\n",
      "    if not action_cb():\n",
      "  File \"C:\\Users\\alexb\\AppData\\Local\\Packages\\PythonSoftwareFoundation.Python.3.8_qbz5n2kfra8p0\\LocalCache\\local-packages\\Python38\\site-packages\\telegram\\ext\\updater.py\", line 597, in polling_action_cb\n",
      "    updates = self.bot.get_updates(\n",
      "  File \"C:\\Users\\alexb\\AppData\\Local\\Packages\\PythonSoftwareFoundation.Python.3.8_qbz5n2kfra8p0\\LocalCache\\local-packages\\Python38\\site-packages\\telegram\\ext\\extbot.py\", line 222, in get_updates\n",
      "    updates = super().get_updates(\n",
      "  File \"C:\\Users\\alexb\\AppData\\Local\\Packages\\PythonSoftwareFoundation.Python.3.8_qbz5n2kfra8p0\\LocalCache\\local-packages\\Python38\\site-packages\\telegram\\bot.py\", line 130, in decorator\n",
      "    result = func(*args, **kwargs)\n",
      "  File \"C:\\Users\\alexb\\AppData\\Local\\Packages\\PythonSoftwareFoundation.Python.3.8_qbz5n2kfra8p0\\LocalCache\\local-packages\\Python38\\site-packages\\telegram\\bot.py\", line 2861, in get_updates\n",
      "    self._post(\n",
      "  File \"C:\\Users\\alexb\\AppData\\Local\\Packages\\PythonSoftwareFoundation.Python.3.8_qbz5n2kfra8p0\\LocalCache\\local-packages\\Python38\\site-packages\\telegram\\bot.py\", line 295, in _post\n",
      "    return self.request.post(\n",
      "  File \"C:\\Users\\alexb\\AppData\\Local\\Packages\\PythonSoftwareFoundation.Python.3.8_qbz5n2kfra8p0\\LocalCache\\local-packages\\Python38\\site-packages\\telegram\\utils\\request.py\", line 356, in post\n",
      "    result = self._request_wrapper(\n",
      "  File \"C:\\Users\\alexb\\AppData\\Local\\Packages\\PythonSoftwareFoundation.Python.3.8_qbz5n2kfra8p0\\LocalCache\\local-packages\\Python38\\site-packages\\telegram\\utils\\request.py\", line 283, in _request_wrapper\n",
      "    raise Conflict(message)\n",
      "telegram.error.Conflict: Conflict: terminated by other getUpdates request; make sure that only one bot instance is running\n",
      "Error while getting Updates: Conflict: terminated by other getUpdates request; make sure that only one bot instance is running\n",
      "No error handlers are registered, logging exception.\n",
      "Traceback (most recent call last):\n",
      "  File \"C:\\Users\\alexb\\AppData\\Local\\Packages\\PythonSoftwareFoundation.Python.3.8_qbz5n2kfra8p0\\LocalCache\\local-packages\\Python38\\site-packages\\telegram\\ext\\updater.py\", line 646, in _network_loop_retry\n",
      "    if not action_cb():\n",
      "  File \"C:\\Users\\alexb\\AppData\\Local\\Packages\\PythonSoftwareFoundation.Python.3.8_qbz5n2kfra8p0\\LocalCache\\local-packages\\Python38\\site-packages\\telegram\\ext\\updater.py\", line 597, in polling_action_cb\n",
      "    updates = self.bot.get_updates(\n",
      "  File \"C:\\Users\\alexb\\AppData\\Local\\Packages\\PythonSoftwareFoundation.Python.3.8_qbz5n2kfra8p0\\LocalCache\\local-packages\\Python38\\site-packages\\telegram\\ext\\extbot.py\", line 222, in get_updates\n",
      "    updates = super().get_updates(\n",
      "  File \"C:\\Users\\alexb\\AppData\\Local\\Packages\\PythonSoftwareFoundation.Python.3.8_qbz5n2kfra8p0\\LocalCache\\local-packages\\Python38\\site-packages\\telegram\\bot.py\", line 130, in decorator\n",
      "    result = func(*args, **kwargs)\n",
      "  File \"C:\\Users\\alexb\\AppData\\Local\\Packages\\PythonSoftwareFoundation.Python.3.8_qbz5n2kfra8p0\\LocalCache\\local-packages\\Python38\\site-packages\\telegram\\bot.py\", line 2861, in get_updates\n",
      "    self._post(\n",
      "  File \"C:\\Users\\alexb\\AppData\\Local\\Packages\\PythonSoftwareFoundation.Python.3.8_qbz5n2kfra8p0\\LocalCache\\local-packages\\Python38\\site-packages\\telegram\\bot.py\", line 295, in _post\n",
      "    return self.request.post(\n",
      "  File \"C:\\Users\\alexb\\AppData\\Local\\Packages\\PythonSoftwareFoundation.Python.3.8_qbz5n2kfra8p0\\LocalCache\\local-packages\\Python38\\site-packages\\telegram\\utils\\request.py\", line 356, in post\n",
      "    result = self._request_wrapper(\n",
      "  File \"C:\\Users\\alexb\\AppData\\Local\\Packages\\PythonSoftwareFoundation.Python.3.8_qbz5n2kfra8p0\\LocalCache\\local-packages\\Python38\\site-packages\\telegram\\utils\\request.py\", line 283, in _request_wrapper\n",
      "    raise Conflict(message)\n",
      "telegram.error.Conflict: Conflict: terminated by other getUpdates request; make sure that only one bot instance is running\n",
      "Error while getting Updates: Conflict: terminated by other getUpdates request; make sure that only one bot instance is running\n",
      "No error handlers are registered, logging exception.\n",
      "Traceback (most recent call last):\n",
      "  File \"C:\\Users\\alexb\\AppData\\Local\\Packages\\PythonSoftwareFoundation.Python.3.8_qbz5n2kfra8p0\\LocalCache\\local-packages\\Python38\\site-packages\\telegram\\ext\\updater.py\", line 646, in _network_loop_retry\n",
      "    if not action_cb():\n",
      "  File \"C:\\Users\\alexb\\AppData\\Local\\Packages\\PythonSoftwareFoundation.Python.3.8_qbz5n2kfra8p0\\LocalCache\\local-packages\\Python38\\site-packages\\telegram\\ext\\updater.py\", line 597, in polling_action_cb\n",
      "    updates = self.bot.get_updates(\n",
      "  File \"C:\\Users\\alexb\\AppData\\Local\\Packages\\PythonSoftwareFoundation.Python.3.8_qbz5n2kfra8p0\\LocalCache\\local-packages\\Python38\\site-packages\\telegram\\ext\\extbot.py\", line 222, in get_updates\n",
      "    updates = super().get_updates(\n",
      "  File \"C:\\Users\\alexb\\AppData\\Local\\Packages\\PythonSoftwareFoundation.Python.3.8_qbz5n2kfra8p0\\LocalCache\\local-packages\\Python38\\site-packages\\telegram\\bot.py\", line 130, in decorator\n",
      "    result = func(*args, **kwargs)\n",
      "  File \"C:\\Users\\alexb\\AppData\\Local\\Packages\\PythonSoftwareFoundation.Python.3.8_qbz5n2kfra8p0\\LocalCache\\local-packages\\Python38\\site-packages\\telegram\\bot.py\", line 2861, in get_updates\n",
      "    self._post(\n",
      "  File \"C:\\Users\\alexb\\AppData\\Local\\Packages\\PythonSoftwareFoundation.Python.3.8_qbz5n2kfra8p0\\LocalCache\\local-packages\\Python38\\site-packages\\telegram\\bot.py\", line 295, in _post\n",
      "    return self.request.post(\n",
      "  File \"C:\\Users\\alexb\\AppData\\Local\\Packages\\PythonSoftwareFoundation.Python.3.8_qbz5n2kfra8p0\\LocalCache\\local-packages\\Python38\\site-packages\\telegram\\utils\\request.py\", line 356, in post\n",
      "    result = self._request_wrapper(\n",
      "  File \"C:\\Users\\alexb\\AppData\\Local\\Packages\\PythonSoftwareFoundation.Python.3.8_qbz5n2kfra8p0\\LocalCache\\local-packages\\Python38\\site-packages\\telegram\\utils\\request.py\", line 283, in _request_wrapper\n",
      "    raise Conflict(message)\n",
      "telegram.error.Conflict: Conflict: terminated by other getUpdates request; make sure that only one bot instance is running\n",
      "Error while getting Updates: Conflict: terminated by other getUpdates request; make sure that only one bot instance is running\n",
      "No error handlers are registered, logging exception.\n",
      "Traceback (most recent call last):\n",
      "  File \"C:\\Users\\alexb\\AppData\\Local\\Packages\\PythonSoftwareFoundation.Python.3.8_qbz5n2kfra8p0\\LocalCache\\local-packages\\Python38\\site-packages\\telegram\\ext\\updater.py\", line 646, in _network_loop_retry\n",
      "    if not action_cb():\n",
      "  File \"C:\\Users\\alexb\\AppData\\Local\\Packages\\PythonSoftwareFoundation.Python.3.8_qbz5n2kfra8p0\\LocalCache\\local-packages\\Python38\\site-packages\\telegram\\ext\\updater.py\", line 597, in polling_action_cb\n",
      "    updates = self.bot.get_updates(\n",
      "  File \"C:\\Users\\alexb\\AppData\\Local\\Packages\\PythonSoftwareFoundation.Python.3.8_qbz5n2kfra8p0\\LocalCache\\local-packages\\Python38\\site-packages\\telegram\\ext\\extbot.py\", line 222, in get_updates\n",
      "    updates = super().get_updates(\n",
      "  File \"C:\\Users\\alexb\\AppData\\Local\\Packages\\PythonSoftwareFoundation.Python.3.8_qbz5n2kfra8p0\\LocalCache\\local-packages\\Python38\\site-packages\\telegram\\bot.py\", line 130, in decorator\n",
      "    result = func(*args, **kwargs)\n",
      "  File \"C:\\Users\\alexb\\AppData\\Local\\Packages\\PythonSoftwareFoundation.Python.3.8_qbz5n2kfra8p0\\LocalCache\\local-packages\\Python38\\site-packages\\telegram\\bot.py\", line 2861, in get_updates\n",
      "    self._post(\n",
      "  File \"C:\\Users\\alexb\\AppData\\Local\\Packages\\PythonSoftwareFoundation.Python.3.8_qbz5n2kfra8p0\\LocalCache\\local-packages\\Python38\\site-packages\\telegram\\bot.py\", line 295, in _post\n",
      "    return self.request.post(\n",
      "  File \"C:\\Users\\alexb\\AppData\\Local\\Packages\\PythonSoftwareFoundation.Python.3.8_qbz5n2kfra8p0\\LocalCache\\local-packages\\Python38\\site-packages\\telegram\\utils\\request.py\", line 356, in post\n",
      "    result = self._request_wrapper(\n",
      "  File \"C:\\Users\\alexb\\AppData\\Local\\Packages\\PythonSoftwareFoundation.Python.3.8_qbz5n2kfra8p0\\LocalCache\\local-packages\\Python38\\site-packages\\telegram\\utils\\request.py\", line 283, in _request_wrapper\n",
      "    raise Conflict(message)\n",
      "telegram.error.Conflict: Conflict: terminated by other getUpdates request; make sure that only one bot instance is running\n",
      "Error while getting Updates: Conflict: terminated by other getUpdates request; make sure that only one bot instance is running\n",
      "No error handlers are registered, logging exception.\n",
      "Traceback (most recent call last):\n",
      "  File \"C:\\Users\\alexb\\AppData\\Local\\Packages\\PythonSoftwareFoundation.Python.3.8_qbz5n2kfra8p0\\LocalCache\\local-packages\\Python38\\site-packages\\telegram\\ext\\updater.py\", line 646, in _network_loop_retry\n",
      "    if not action_cb():\n",
      "  File \"C:\\Users\\alexb\\AppData\\Local\\Packages\\PythonSoftwareFoundation.Python.3.8_qbz5n2kfra8p0\\LocalCache\\local-packages\\Python38\\site-packages\\telegram\\ext\\updater.py\", line 597, in polling_action_cb\n",
      "    updates = self.bot.get_updates(\n",
      "  File \"C:\\Users\\alexb\\AppData\\Local\\Packages\\PythonSoftwareFoundation.Python.3.8_qbz5n2kfra8p0\\LocalCache\\local-packages\\Python38\\site-packages\\telegram\\ext\\extbot.py\", line 222, in get_updates\n",
      "    updates = super().get_updates(\n",
      "  File \"C:\\Users\\alexb\\AppData\\Local\\Packages\\PythonSoftwareFoundation.Python.3.8_qbz5n2kfra8p0\\LocalCache\\local-packages\\Python38\\site-packages\\telegram\\bot.py\", line 130, in decorator\n",
      "    result = func(*args, **kwargs)\n",
      "  File \"C:\\Users\\alexb\\AppData\\Local\\Packages\\PythonSoftwareFoundation.Python.3.8_qbz5n2kfra8p0\\LocalCache\\local-packages\\Python38\\site-packages\\telegram\\bot.py\", line 2861, in get_updates\n",
      "    self._post(\n",
      "  File \"C:\\Users\\alexb\\AppData\\Local\\Packages\\PythonSoftwareFoundation.Python.3.8_qbz5n2kfra8p0\\LocalCache\\local-packages\\Python38\\site-packages\\telegram\\bot.py\", line 295, in _post\n",
      "    return self.request.post(\n",
      "  File \"C:\\Users\\alexb\\AppData\\Local\\Packages\\PythonSoftwareFoundation.Python.3.8_qbz5n2kfra8p0\\LocalCache\\local-packages\\Python38\\site-packages\\telegram\\utils\\request.py\", line 356, in post\n",
      "    result = self._request_wrapper(\n",
      "  File \"C:\\Users\\alexb\\AppData\\Local\\Packages\\PythonSoftwareFoundation.Python.3.8_qbz5n2kfra8p0\\LocalCache\\local-packages\\Python38\\site-packages\\telegram\\utils\\request.py\", line 283, in _request_wrapper\n",
      "    raise Conflict(message)\n",
      "telegram.error.Conflict: Conflict: terminated by other getUpdates request; make sure that only one bot instance is running\n",
      "Error while getting Updates: Conflict: terminated by other getUpdates request; make sure that only one bot instance is running\n",
      "No error handlers are registered, logging exception.\n",
      "Traceback (most recent call last):\n",
      "  File \"C:\\Users\\alexb\\AppData\\Local\\Packages\\PythonSoftwareFoundation.Python.3.8_qbz5n2kfra8p0\\LocalCache\\local-packages\\Python38\\site-packages\\telegram\\ext\\updater.py\", line 646, in _network_loop_retry\n",
      "    if not action_cb():\n",
      "  File \"C:\\Users\\alexb\\AppData\\Local\\Packages\\PythonSoftwareFoundation.Python.3.8_qbz5n2kfra8p0\\LocalCache\\local-packages\\Python38\\site-packages\\telegram\\ext\\updater.py\", line 597, in polling_action_cb\n",
      "    updates = self.bot.get_updates(\n",
      "  File \"C:\\Users\\alexb\\AppData\\Local\\Packages\\PythonSoftwareFoundation.Python.3.8_qbz5n2kfra8p0\\LocalCache\\local-packages\\Python38\\site-packages\\telegram\\ext\\extbot.py\", line 222, in get_updates\n",
      "    updates = super().get_updates(\n",
      "  File \"C:\\Users\\alexb\\AppData\\Local\\Packages\\PythonSoftwareFoundation.Python.3.8_qbz5n2kfra8p0\\LocalCache\\local-packages\\Python38\\site-packages\\telegram\\bot.py\", line 130, in decorator\n",
      "    result = func(*args, **kwargs)\n",
      "  File \"C:\\Users\\alexb\\AppData\\Local\\Packages\\PythonSoftwareFoundation.Python.3.8_qbz5n2kfra8p0\\LocalCache\\local-packages\\Python38\\site-packages\\telegram\\bot.py\", line 2861, in get_updates\n",
      "    self._post(\n",
      "  File \"C:\\Users\\alexb\\AppData\\Local\\Packages\\PythonSoftwareFoundation.Python.3.8_qbz5n2kfra8p0\\LocalCache\\local-packages\\Python38\\site-packages\\telegram\\bot.py\", line 295, in _post\n",
      "    return self.request.post(\n",
      "  File \"C:\\Users\\alexb\\AppData\\Local\\Packages\\PythonSoftwareFoundation.Python.3.8_qbz5n2kfra8p0\\LocalCache\\local-packages\\Python38\\site-packages\\telegram\\utils\\request.py\", line 356, in post\n",
      "    result = self._request_wrapper(\n",
      "  File \"C:\\Users\\alexb\\AppData\\Local\\Packages\\PythonSoftwareFoundation.Python.3.8_qbz5n2kfra8p0\\LocalCache\\local-packages\\Python38\\site-packages\\telegram\\utils\\request.py\", line 283, in _request_wrapper\n",
      "    raise Conflict(message)\n",
      "telegram.error.Conflict: Conflict: terminated by other getUpdates request; make sure that only one bot instance is running\n",
      "Error while getting Updates: Conflict: terminated by other getUpdates request; make sure that only one bot instance is running\n",
      "No error handlers are registered, logging exception.\n",
      "Traceback (most recent call last):\n",
      "  File \"C:\\Users\\alexb\\AppData\\Local\\Packages\\PythonSoftwareFoundation.Python.3.8_qbz5n2kfra8p0\\LocalCache\\local-packages\\Python38\\site-packages\\telegram\\ext\\updater.py\", line 646, in _network_loop_retry\n",
      "    if not action_cb():\n",
      "  File \"C:\\Users\\alexb\\AppData\\Local\\Packages\\PythonSoftwareFoundation.Python.3.8_qbz5n2kfra8p0\\LocalCache\\local-packages\\Python38\\site-packages\\telegram\\ext\\updater.py\", line 597, in polling_action_cb\n",
      "    updates = self.bot.get_updates(\n",
      "  File \"C:\\Users\\alexb\\AppData\\Local\\Packages\\PythonSoftwareFoundation.Python.3.8_qbz5n2kfra8p0\\LocalCache\\local-packages\\Python38\\site-packages\\telegram\\ext\\extbot.py\", line 222, in get_updates\n",
      "    updates = super().get_updates(\n",
      "  File \"C:\\Users\\alexb\\AppData\\Local\\Packages\\PythonSoftwareFoundation.Python.3.8_qbz5n2kfra8p0\\LocalCache\\local-packages\\Python38\\site-packages\\telegram\\bot.py\", line 130, in decorator\n",
      "    result = func(*args, **kwargs)\n",
      "  File \"C:\\Users\\alexb\\AppData\\Local\\Packages\\PythonSoftwareFoundation.Python.3.8_qbz5n2kfra8p0\\LocalCache\\local-packages\\Python38\\site-packages\\telegram\\bot.py\", line 2861, in get_updates\n",
      "    self._post(\n",
      "  File \"C:\\Users\\alexb\\AppData\\Local\\Packages\\PythonSoftwareFoundation.Python.3.8_qbz5n2kfra8p0\\LocalCache\\local-packages\\Python38\\site-packages\\telegram\\bot.py\", line 295, in _post\n",
      "    return self.request.post(\n",
      "  File \"C:\\Users\\alexb\\AppData\\Local\\Packages\\PythonSoftwareFoundation.Python.3.8_qbz5n2kfra8p0\\LocalCache\\local-packages\\Python38\\site-packages\\telegram\\utils\\request.py\", line 356, in post\n",
      "    result = self._request_wrapper(\n",
      "  File \"C:\\Users\\alexb\\AppData\\Local\\Packages\\PythonSoftwareFoundation.Python.3.8_qbz5n2kfra8p0\\LocalCache\\local-packages\\Python38\\site-packages\\telegram\\utils\\request.py\", line 283, in _request_wrapper\n",
      "    raise Conflict(message)\n",
      "telegram.error.Conflict: Conflict: terminated by other getUpdates request; make sure that only one bot instance is running\n",
      "Error while getting Updates: Conflict: terminated by other getUpdates request; make sure that only one bot instance is running\n",
      "No error handlers are registered, logging exception.\n",
      "Traceback (most recent call last):\n",
      "  File \"C:\\Users\\alexb\\AppData\\Local\\Packages\\PythonSoftwareFoundation.Python.3.8_qbz5n2kfra8p0\\LocalCache\\local-packages\\Python38\\site-packages\\telegram\\ext\\updater.py\", line 646, in _network_loop_retry\n",
      "    if not action_cb():\n",
      "  File \"C:\\Users\\alexb\\AppData\\Local\\Packages\\PythonSoftwareFoundation.Python.3.8_qbz5n2kfra8p0\\LocalCache\\local-packages\\Python38\\site-packages\\telegram\\ext\\updater.py\", line 597, in polling_action_cb\n",
      "    updates = self.bot.get_updates(\n",
      "  File \"C:\\Users\\alexb\\AppData\\Local\\Packages\\PythonSoftwareFoundation.Python.3.8_qbz5n2kfra8p0\\LocalCache\\local-packages\\Python38\\site-packages\\telegram\\ext\\extbot.py\", line 222, in get_updates\n",
      "    updates = super().get_updates(\n",
      "  File \"C:\\Users\\alexb\\AppData\\Local\\Packages\\PythonSoftwareFoundation.Python.3.8_qbz5n2kfra8p0\\LocalCache\\local-packages\\Python38\\site-packages\\telegram\\bot.py\", line 130, in decorator\n",
      "    result = func(*args, **kwargs)\n",
      "  File \"C:\\Users\\alexb\\AppData\\Local\\Packages\\PythonSoftwareFoundation.Python.3.8_qbz5n2kfra8p0\\LocalCache\\local-packages\\Python38\\site-packages\\telegram\\bot.py\", line 2861, in get_updates\n",
      "    self._post(\n",
      "  File \"C:\\Users\\alexb\\AppData\\Local\\Packages\\PythonSoftwareFoundation.Python.3.8_qbz5n2kfra8p0\\LocalCache\\local-packages\\Python38\\site-packages\\telegram\\bot.py\", line 295, in _post\n",
      "    return self.request.post(\n",
      "  File \"C:\\Users\\alexb\\AppData\\Local\\Packages\\PythonSoftwareFoundation.Python.3.8_qbz5n2kfra8p0\\LocalCache\\local-packages\\Python38\\site-packages\\telegram\\utils\\request.py\", line 356, in post\n",
      "    result = self._request_wrapper(\n",
      "  File \"C:\\Users\\alexb\\AppData\\Local\\Packages\\PythonSoftwareFoundation.Python.3.8_qbz5n2kfra8p0\\LocalCache\\local-packages\\Python38\\site-packages\\telegram\\utils\\request.py\", line 283, in _request_wrapper\n",
      "    raise Conflict(message)\n",
      "telegram.error.Conflict: Conflict: terminated by other getUpdates request; make sure that only one bot instance is running\n",
      "Error while getting Updates: Conflict: terminated by other getUpdates request; make sure that only one bot instance is running\n",
      "No error handlers are registered, logging exception.\n",
      "Traceback (most recent call last):\n",
      "  File \"C:\\Users\\alexb\\AppData\\Local\\Packages\\PythonSoftwareFoundation.Python.3.8_qbz5n2kfra8p0\\LocalCache\\local-packages\\Python38\\site-packages\\telegram\\ext\\updater.py\", line 646, in _network_loop_retry\n",
      "    if not action_cb():\n",
      "  File \"C:\\Users\\alexb\\AppData\\Local\\Packages\\PythonSoftwareFoundation.Python.3.8_qbz5n2kfra8p0\\LocalCache\\local-packages\\Python38\\site-packages\\telegram\\ext\\updater.py\", line 597, in polling_action_cb\n",
      "    updates = self.bot.get_updates(\n",
      "  File \"C:\\Users\\alexb\\AppData\\Local\\Packages\\PythonSoftwareFoundation.Python.3.8_qbz5n2kfra8p0\\LocalCache\\local-packages\\Python38\\site-packages\\telegram\\ext\\extbot.py\", line 222, in get_updates\n",
      "    updates = super().get_updates(\n",
      "  File \"C:\\Users\\alexb\\AppData\\Local\\Packages\\PythonSoftwareFoundation.Python.3.8_qbz5n2kfra8p0\\LocalCache\\local-packages\\Python38\\site-packages\\telegram\\bot.py\", line 130, in decorator\n",
      "    result = func(*args, **kwargs)\n",
      "  File \"C:\\Users\\alexb\\AppData\\Local\\Packages\\PythonSoftwareFoundation.Python.3.8_qbz5n2kfra8p0\\LocalCache\\local-packages\\Python38\\site-packages\\telegram\\bot.py\", line 2861, in get_updates\n",
      "    self._post(\n",
      "  File \"C:\\Users\\alexb\\AppData\\Local\\Packages\\PythonSoftwareFoundation.Python.3.8_qbz5n2kfra8p0\\LocalCache\\local-packages\\Python38\\site-packages\\telegram\\bot.py\", line 295, in _post\n",
      "    return self.request.post(\n",
      "  File \"C:\\Users\\alexb\\AppData\\Local\\Packages\\PythonSoftwareFoundation.Python.3.8_qbz5n2kfra8p0\\LocalCache\\local-packages\\Python38\\site-packages\\telegram\\utils\\request.py\", line 356, in post\n",
      "    result = self._request_wrapper(\n",
      "  File \"C:\\Users\\alexb\\AppData\\Local\\Packages\\PythonSoftwareFoundation.Python.3.8_qbz5n2kfra8p0\\LocalCache\\local-packages\\Python38\\site-packages\\telegram\\utils\\request.py\", line 283, in _request_wrapper\n",
      "    raise Conflict(message)\n",
      "telegram.error.Conflict: Conflict: terminated by other getUpdates request; make sure that only one bot instance is running\n",
      "Error while getting Updates: Conflict: terminated by other getUpdates request; make sure that only one bot instance is running\n",
      "No error handlers are registered, logging exception.\n",
      "Traceback (most recent call last):\n",
      "  File \"C:\\Users\\alexb\\AppData\\Local\\Packages\\PythonSoftwareFoundation.Python.3.8_qbz5n2kfra8p0\\LocalCache\\local-packages\\Python38\\site-packages\\telegram\\ext\\updater.py\", line 646, in _network_loop_retry\n",
      "    if not action_cb():\n",
      "  File \"C:\\Users\\alexb\\AppData\\Local\\Packages\\PythonSoftwareFoundation.Python.3.8_qbz5n2kfra8p0\\LocalCache\\local-packages\\Python38\\site-packages\\telegram\\ext\\updater.py\", line 597, in polling_action_cb\n",
      "    updates = self.bot.get_updates(\n",
      "  File \"C:\\Users\\alexb\\AppData\\Local\\Packages\\PythonSoftwareFoundation.Python.3.8_qbz5n2kfra8p0\\LocalCache\\local-packages\\Python38\\site-packages\\telegram\\ext\\extbot.py\", line 222, in get_updates\n",
      "    updates = super().get_updates(\n",
      "  File \"C:\\Users\\alexb\\AppData\\Local\\Packages\\PythonSoftwareFoundation.Python.3.8_qbz5n2kfra8p0\\LocalCache\\local-packages\\Python38\\site-packages\\telegram\\bot.py\", line 130, in decorator\n",
      "    result = func(*args, **kwargs)\n",
      "  File \"C:\\Users\\alexb\\AppData\\Local\\Packages\\PythonSoftwareFoundation.Python.3.8_qbz5n2kfra8p0\\LocalCache\\local-packages\\Python38\\site-packages\\telegram\\bot.py\", line 2861, in get_updates\n",
      "    self._post(\n",
      "  File \"C:\\Users\\alexb\\AppData\\Local\\Packages\\PythonSoftwareFoundation.Python.3.8_qbz5n2kfra8p0\\LocalCache\\local-packages\\Python38\\site-packages\\telegram\\bot.py\", line 295, in _post\n",
      "    return self.request.post(\n",
      "  File \"C:\\Users\\alexb\\AppData\\Local\\Packages\\PythonSoftwareFoundation.Python.3.8_qbz5n2kfra8p0\\LocalCache\\local-packages\\Python38\\site-packages\\telegram\\utils\\request.py\", line 356, in post\n",
      "    result = self._request_wrapper(\n",
      "  File \"C:\\Users\\alexb\\AppData\\Local\\Packages\\PythonSoftwareFoundation.Python.3.8_qbz5n2kfra8p0\\LocalCache\\local-packages\\Python38\\site-packages\\telegram\\utils\\request.py\", line 283, in _request_wrapper\n",
      "    raise Conflict(message)\n",
      "telegram.error.Conflict: Conflict: terminated by other getUpdates request; make sure that only one bot instance is running\n",
      "Error while getting Updates: Conflict: terminated by other getUpdates request; make sure that only one bot instance is running\n",
      "No error handlers are registered, logging exception.\n",
      "Traceback (most recent call last):\n",
      "  File \"C:\\Users\\alexb\\AppData\\Local\\Packages\\PythonSoftwareFoundation.Python.3.8_qbz5n2kfra8p0\\LocalCache\\local-packages\\Python38\\site-packages\\telegram\\ext\\updater.py\", line 646, in _network_loop_retry\n",
      "    if not action_cb():\n",
      "  File \"C:\\Users\\alexb\\AppData\\Local\\Packages\\PythonSoftwareFoundation.Python.3.8_qbz5n2kfra8p0\\LocalCache\\local-packages\\Python38\\site-packages\\telegram\\ext\\updater.py\", line 597, in polling_action_cb\n",
      "    updates = self.bot.get_updates(\n",
      "  File \"C:\\Users\\alexb\\AppData\\Local\\Packages\\PythonSoftwareFoundation.Python.3.8_qbz5n2kfra8p0\\LocalCache\\local-packages\\Python38\\site-packages\\telegram\\ext\\extbot.py\", line 222, in get_updates\n",
      "    updates = super().get_updates(\n",
      "  File \"C:\\Users\\alexb\\AppData\\Local\\Packages\\PythonSoftwareFoundation.Python.3.8_qbz5n2kfra8p0\\LocalCache\\local-packages\\Python38\\site-packages\\telegram\\bot.py\", line 130, in decorator\n",
      "    result = func(*args, **kwargs)\n",
      "  File \"C:\\Users\\alexb\\AppData\\Local\\Packages\\PythonSoftwareFoundation.Python.3.8_qbz5n2kfra8p0\\LocalCache\\local-packages\\Python38\\site-packages\\telegram\\bot.py\", line 2861, in get_updates\n",
      "    self._post(\n",
      "  File \"C:\\Users\\alexb\\AppData\\Local\\Packages\\PythonSoftwareFoundation.Python.3.8_qbz5n2kfra8p0\\LocalCache\\local-packages\\Python38\\site-packages\\telegram\\bot.py\", line 295, in _post\n",
      "    return self.request.post(\n",
      "  File \"C:\\Users\\alexb\\AppData\\Local\\Packages\\PythonSoftwareFoundation.Python.3.8_qbz5n2kfra8p0\\LocalCache\\local-packages\\Python38\\site-packages\\telegram\\utils\\request.py\", line 356, in post\n",
      "    result = self._request_wrapper(\n",
      "  File \"C:\\Users\\alexb\\AppData\\Local\\Packages\\PythonSoftwareFoundation.Python.3.8_qbz5n2kfra8p0\\LocalCache\\local-packages\\Python38\\site-packages\\telegram\\utils\\request.py\", line 283, in _request_wrapper\n",
      "    raise Conflict(message)\n",
      "telegram.error.Conflict: Conflict: terminated by other getUpdates request; make sure that only one bot instance is running\n",
      "Error while getting Updates: Conflict: terminated by other getUpdates request; make sure that only one bot instance is running\n",
      "No error handlers are registered, logging exception.\n",
      "Traceback (most recent call last):\n",
      "  File \"C:\\Users\\alexb\\AppData\\Local\\Packages\\PythonSoftwareFoundation.Python.3.8_qbz5n2kfra8p0\\LocalCache\\local-packages\\Python38\\site-packages\\telegram\\ext\\updater.py\", line 646, in _network_loop_retry\n",
      "    if not action_cb():\n",
      "  File \"C:\\Users\\alexb\\AppData\\Local\\Packages\\PythonSoftwareFoundation.Python.3.8_qbz5n2kfra8p0\\LocalCache\\local-packages\\Python38\\site-packages\\telegram\\ext\\updater.py\", line 597, in polling_action_cb\n",
      "    updates = self.bot.get_updates(\n",
      "  File \"C:\\Users\\alexb\\AppData\\Local\\Packages\\PythonSoftwareFoundation.Python.3.8_qbz5n2kfra8p0\\LocalCache\\local-packages\\Python38\\site-packages\\telegram\\ext\\extbot.py\", line 222, in get_updates\n",
      "    updates = super().get_updates(\n",
      "  File \"C:\\Users\\alexb\\AppData\\Local\\Packages\\PythonSoftwareFoundation.Python.3.8_qbz5n2kfra8p0\\LocalCache\\local-packages\\Python38\\site-packages\\telegram\\bot.py\", line 130, in decorator\n",
      "    result = func(*args, **kwargs)\n",
      "  File \"C:\\Users\\alexb\\AppData\\Local\\Packages\\PythonSoftwareFoundation.Python.3.8_qbz5n2kfra8p0\\LocalCache\\local-packages\\Python38\\site-packages\\telegram\\bot.py\", line 2861, in get_updates\n",
      "    self._post(\n",
      "  File \"C:\\Users\\alexb\\AppData\\Local\\Packages\\PythonSoftwareFoundation.Python.3.8_qbz5n2kfra8p0\\LocalCache\\local-packages\\Python38\\site-packages\\telegram\\bot.py\", line 295, in _post\n",
      "    return self.request.post(\n",
      "  File \"C:\\Users\\alexb\\AppData\\Local\\Packages\\PythonSoftwareFoundation.Python.3.8_qbz5n2kfra8p0\\LocalCache\\local-packages\\Python38\\site-packages\\telegram\\utils\\request.py\", line 356, in post\n",
      "    result = self._request_wrapper(\n",
      "  File \"C:\\Users\\alexb\\AppData\\Local\\Packages\\PythonSoftwareFoundation.Python.3.8_qbz5n2kfra8p0\\LocalCache\\local-packages\\Python38\\site-packages\\telegram\\utils\\request.py\", line 283, in _request_wrapper\n",
      "    raise Conflict(message)\n",
      "telegram.error.Conflict: Conflict: terminated by other getUpdates request; make sure that only one bot instance is running\n",
      "Error while getting Updates: Conflict: terminated by other getUpdates request; make sure that only one bot instance is running\n",
      "No error handlers are registered, logging exception.\n",
      "Traceback (most recent call last):\n",
      "  File \"C:\\Users\\alexb\\AppData\\Local\\Packages\\PythonSoftwareFoundation.Python.3.8_qbz5n2kfra8p0\\LocalCache\\local-packages\\Python38\\site-packages\\telegram\\ext\\updater.py\", line 646, in _network_loop_retry\n",
      "    if not action_cb():\n",
      "  File \"C:\\Users\\alexb\\AppData\\Local\\Packages\\PythonSoftwareFoundation.Python.3.8_qbz5n2kfra8p0\\LocalCache\\local-packages\\Python38\\site-packages\\telegram\\ext\\updater.py\", line 597, in polling_action_cb\n",
      "    updates = self.bot.get_updates(\n",
      "  File \"C:\\Users\\alexb\\AppData\\Local\\Packages\\PythonSoftwareFoundation.Python.3.8_qbz5n2kfra8p0\\LocalCache\\local-packages\\Python38\\site-packages\\telegram\\ext\\extbot.py\", line 222, in get_updates\n",
      "    updates = super().get_updates(\n",
      "  File \"C:\\Users\\alexb\\AppData\\Local\\Packages\\PythonSoftwareFoundation.Python.3.8_qbz5n2kfra8p0\\LocalCache\\local-packages\\Python38\\site-packages\\telegram\\bot.py\", line 130, in decorator\n",
      "    result = func(*args, **kwargs)\n",
      "  File \"C:\\Users\\alexb\\AppData\\Local\\Packages\\PythonSoftwareFoundation.Python.3.8_qbz5n2kfra8p0\\LocalCache\\local-packages\\Python38\\site-packages\\telegram\\bot.py\", line 2861, in get_updates\n",
      "    self._post(\n",
      "  File \"C:\\Users\\alexb\\AppData\\Local\\Packages\\PythonSoftwareFoundation.Python.3.8_qbz5n2kfra8p0\\LocalCache\\local-packages\\Python38\\site-packages\\telegram\\bot.py\", line 295, in _post\n",
      "    return self.request.post(\n",
      "  File \"C:\\Users\\alexb\\AppData\\Local\\Packages\\PythonSoftwareFoundation.Python.3.8_qbz5n2kfra8p0\\LocalCache\\local-packages\\Python38\\site-packages\\telegram\\utils\\request.py\", line 356, in post\n",
      "    result = self._request_wrapper(\n",
      "  File \"C:\\Users\\alexb\\AppData\\Local\\Packages\\PythonSoftwareFoundation.Python.3.8_qbz5n2kfra8p0\\LocalCache\\local-packages\\Python38\\site-packages\\telegram\\utils\\request.py\", line 283, in _request_wrapper\n",
      "    raise Conflict(message)\n",
      "telegram.error.Conflict: Conflict: terminated by other getUpdates request; make sure that only one bot instance is running\n",
      "Error while getting Updates: Conflict: terminated by other getUpdates request; make sure that only one bot instance is running\n",
      "No error handlers are registered, logging exception.\n",
      "Traceback (most recent call last):\n",
      "  File \"C:\\Users\\alexb\\AppData\\Local\\Packages\\PythonSoftwareFoundation.Python.3.8_qbz5n2kfra8p0\\LocalCache\\local-packages\\Python38\\site-packages\\telegram\\ext\\updater.py\", line 646, in _network_loop_retry\n",
      "    if not action_cb():\n",
      "  File \"C:\\Users\\alexb\\AppData\\Local\\Packages\\PythonSoftwareFoundation.Python.3.8_qbz5n2kfra8p0\\LocalCache\\local-packages\\Python38\\site-packages\\telegram\\ext\\updater.py\", line 597, in polling_action_cb\n",
      "    updates = self.bot.get_updates(\n",
      "  File \"C:\\Users\\alexb\\AppData\\Local\\Packages\\PythonSoftwareFoundation.Python.3.8_qbz5n2kfra8p0\\LocalCache\\local-packages\\Python38\\site-packages\\telegram\\ext\\extbot.py\", line 222, in get_updates\n",
      "    updates = super().get_updates(\n",
      "  File \"C:\\Users\\alexb\\AppData\\Local\\Packages\\PythonSoftwareFoundation.Python.3.8_qbz5n2kfra8p0\\LocalCache\\local-packages\\Python38\\site-packages\\telegram\\bot.py\", line 130, in decorator\n",
      "    result = func(*args, **kwargs)\n",
      "  File \"C:\\Users\\alexb\\AppData\\Local\\Packages\\PythonSoftwareFoundation.Python.3.8_qbz5n2kfra8p0\\LocalCache\\local-packages\\Python38\\site-packages\\telegram\\bot.py\", line 2861, in get_updates\n",
      "    self._post(\n",
      "  File \"C:\\Users\\alexb\\AppData\\Local\\Packages\\PythonSoftwareFoundation.Python.3.8_qbz5n2kfra8p0\\LocalCache\\local-packages\\Python38\\site-packages\\telegram\\bot.py\", line 295, in _post\n",
      "    return self.request.post(\n",
      "  File \"C:\\Users\\alexb\\AppData\\Local\\Packages\\PythonSoftwareFoundation.Python.3.8_qbz5n2kfra8p0\\LocalCache\\local-packages\\Python38\\site-packages\\telegram\\utils\\request.py\", line 356, in post\n",
      "    result = self._request_wrapper(\n",
      "  File \"C:\\Users\\alexb\\AppData\\Local\\Packages\\PythonSoftwareFoundation.Python.3.8_qbz5n2kfra8p0\\LocalCache\\local-packages\\Python38\\site-packages\\telegram\\utils\\request.py\", line 283, in _request_wrapper\n",
      "    raise Conflict(message)\n",
      "telegram.error.Conflict: Conflict: terminated by other getUpdates request; make sure that only one bot instance is running\n",
      "Error while getting Updates: Conflict: terminated by other getUpdates request; make sure that only one bot instance is running\n",
      "No error handlers are registered, logging exception.\n",
      "Traceback (most recent call last):\n",
      "  File \"C:\\Users\\alexb\\AppData\\Local\\Packages\\PythonSoftwareFoundation.Python.3.8_qbz5n2kfra8p0\\LocalCache\\local-packages\\Python38\\site-packages\\telegram\\ext\\updater.py\", line 646, in _network_loop_retry\n",
      "    if not action_cb():\n",
      "  File \"C:\\Users\\alexb\\AppData\\Local\\Packages\\PythonSoftwareFoundation.Python.3.8_qbz5n2kfra8p0\\LocalCache\\local-packages\\Python38\\site-packages\\telegram\\ext\\updater.py\", line 597, in polling_action_cb\n",
      "    updates = self.bot.get_updates(\n",
      "  File \"C:\\Users\\alexb\\AppData\\Local\\Packages\\PythonSoftwareFoundation.Python.3.8_qbz5n2kfra8p0\\LocalCache\\local-packages\\Python38\\site-packages\\telegram\\ext\\extbot.py\", line 222, in get_updates\n",
      "    updates = super().get_updates(\n",
      "  File \"C:\\Users\\alexb\\AppData\\Local\\Packages\\PythonSoftwareFoundation.Python.3.8_qbz5n2kfra8p0\\LocalCache\\local-packages\\Python38\\site-packages\\telegram\\bot.py\", line 130, in decorator\n",
      "    result = func(*args, **kwargs)\n",
      "  File \"C:\\Users\\alexb\\AppData\\Local\\Packages\\PythonSoftwareFoundation.Python.3.8_qbz5n2kfra8p0\\LocalCache\\local-packages\\Python38\\site-packages\\telegram\\bot.py\", line 2861, in get_updates\n",
      "    self._post(\n",
      "  File \"C:\\Users\\alexb\\AppData\\Local\\Packages\\PythonSoftwareFoundation.Python.3.8_qbz5n2kfra8p0\\LocalCache\\local-packages\\Python38\\site-packages\\telegram\\bot.py\", line 295, in _post\n",
      "    return self.request.post(\n",
      "  File \"C:\\Users\\alexb\\AppData\\Local\\Packages\\PythonSoftwareFoundation.Python.3.8_qbz5n2kfra8p0\\LocalCache\\local-packages\\Python38\\site-packages\\telegram\\utils\\request.py\", line 356, in post\n",
      "    result = self._request_wrapper(\n",
      "  File \"C:\\Users\\alexb\\AppData\\Local\\Packages\\PythonSoftwareFoundation.Python.3.8_qbz5n2kfra8p0\\LocalCache\\local-packages\\Python38\\site-packages\\telegram\\utils\\request.py\", line 283, in _request_wrapper\n",
      "    raise Conflict(message)\n",
      "telegram.error.Conflict: Conflict: terminated by other getUpdates request; make sure that only one bot instance is running\n",
      "Error while getting Updates: Conflict: terminated by other getUpdates request; make sure that only one bot instance is running\n",
      "No error handlers are registered, logging exception.\n",
      "Traceback (most recent call last):\n",
      "  File \"C:\\Users\\alexb\\AppData\\Local\\Packages\\PythonSoftwareFoundation.Python.3.8_qbz5n2kfra8p0\\LocalCache\\local-packages\\Python38\\site-packages\\telegram\\ext\\updater.py\", line 646, in _network_loop_retry\n",
      "    if not action_cb():\n",
      "  File \"C:\\Users\\alexb\\AppData\\Local\\Packages\\PythonSoftwareFoundation.Python.3.8_qbz5n2kfra8p0\\LocalCache\\local-packages\\Python38\\site-packages\\telegram\\ext\\updater.py\", line 597, in polling_action_cb\n",
      "    updates = self.bot.get_updates(\n",
      "  File \"C:\\Users\\alexb\\AppData\\Local\\Packages\\PythonSoftwareFoundation.Python.3.8_qbz5n2kfra8p0\\LocalCache\\local-packages\\Python38\\site-packages\\telegram\\ext\\extbot.py\", line 222, in get_updates\n",
      "    updates = super().get_updates(\n",
      "  File \"C:\\Users\\alexb\\AppData\\Local\\Packages\\PythonSoftwareFoundation.Python.3.8_qbz5n2kfra8p0\\LocalCache\\local-packages\\Python38\\site-packages\\telegram\\bot.py\", line 130, in decorator\n",
      "    result = func(*args, **kwargs)\n",
      "  File \"C:\\Users\\alexb\\AppData\\Local\\Packages\\PythonSoftwareFoundation.Python.3.8_qbz5n2kfra8p0\\LocalCache\\local-packages\\Python38\\site-packages\\telegram\\bot.py\", line 2861, in get_updates\n",
      "    self._post(\n",
      "  File \"C:\\Users\\alexb\\AppData\\Local\\Packages\\PythonSoftwareFoundation.Python.3.8_qbz5n2kfra8p0\\LocalCache\\local-packages\\Python38\\site-packages\\telegram\\bot.py\", line 295, in _post\n",
      "    return self.request.post(\n",
      "  File \"C:\\Users\\alexb\\AppData\\Local\\Packages\\PythonSoftwareFoundation.Python.3.8_qbz5n2kfra8p0\\LocalCache\\local-packages\\Python38\\site-packages\\telegram\\utils\\request.py\", line 356, in post\n",
      "    result = self._request_wrapper(\n",
      "  File \"C:\\Users\\alexb\\AppData\\Local\\Packages\\PythonSoftwareFoundation.Python.3.8_qbz5n2kfra8p0\\LocalCache\\local-packages\\Python38\\site-packages\\telegram\\utils\\request.py\", line 283, in _request_wrapper\n",
      "    raise Conflict(message)\n",
      "telegram.error.Conflict: Conflict: terminated by other getUpdates request; make sure that only one bot instance is running\n",
      "Error while getting Updates: Conflict: terminated by other getUpdates request; make sure that only one bot instance is running\n",
      "No error handlers are registered, logging exception.\n",
      "Traceback (most recent call last):\n",
      "  File \"C:\\Users\\alexb\\AppData\\Local\\Packages\\PythonSoftwareFoundation.Python.3.8_qbz5n2kfra8p0\\LocalCache\\local-packages\\Python38\\site-packages\\telegram\\ext\\updater.py\", line 646, in _network_loop_retry\n",
      "    if not action_cb():\n",
      "  File \"C:\\Users\\alexb\\AppData\\Local\\Packages\\PythonSoftwareFoundation.Python.3.8_qbz5n2kfra8p0\\LocalCache\\local-packages\\Python38\\site-packages\\telegram\\ext\\updater.py\", line 597, in polling_action_cb\n",
      "    updates = self.bot.get_updates(\n",
      "  File \"C:\\Users\\alexb\\AppData\\Local\\Packages\\PythonSoftwareFoundation.Python.3.8_qbz5n2kfra8p0\\LocalCache\\local-packages\\Python38\\site-packages\\telegram\\ext\\extbot.py\", line 222, in get_updates\n",
      "    updates = super().get_updates(\n",
      "  File \"C:\\Users\\alexb\\AppData\\Local\\Packages\\PythonSoftwareFoundation.Python.3.8_qbz5n2kfra8p0\\LocalCache\\local-packages\\Python38\\site-packages\\telegram\\bot.py\", line 130, in decorator\n",
      "    result = func(*args, **kwargs)\n",
      "  File \"C:\\Users\\alexb\\AppData\\Local\\Packages\\PythonSoftwareFoundation.Python.3.8_qbz5n2kfra8p0\\LocalCache\\local-packages\\Python38\\site-packages\\telegram\\bot.py\", line 2861, in get_updates\n",
      "    self._post(\n",
      "  File \"C:\\Users\\alexb\\AppData\\Local\\Packages\\PythonSoftwareFoundation.Python.3.8_qbz5n2kfra8p0\\LocalCache\\local-packages\\Python38\\site-packages\\telegram\\bot.py\", line 295, in _post\n",
      "    return self.request.post(\n",
      "  File \"C:\\Users\\alexb\\AppData\\Local\\Packages\\PythonSoftwareFoundation.Python.3.8_qbz5n2kfra8p0\\LocalCache\\local-packages\\Python38\\site-packages\\telegram\\utils\\request.py\", line 356, in post\n",
      "    result = self._request_wrapper(\n",
      "  File \"C:\\Users\\alexb\\AppData\\Local\\Packages\\PythonSoftwareFoundation.Python.3.8_qbz5n2kfra8p0\\LocalCache\\local-packages\\Python38\\site-packages\\telegram\\utils\\request.py\", line 283, in _request_wrapper\n",
      "    raise Conflict(message)\n",
      "telegram.error.Conflict: Conflict: terminated by other getUpdates request; make sure that only one bot instance is running\n",
      "Error while getting Updates: Conflict: terminated by other getUpdates request; make sure that only one bot instance is running\n",
      "No error handlers are registered, logging exception.\n",
      "Traceback (most recent call last):\n",
      "  File \"C:\\Users\\alexb\\AppData\\Local\\Packages\\PythonSoftwareFoundation.Python.3.8_qbz5n2kfra8p0\\LocalCache\\local-packages\\Python38\\site-packages\\telegram\\ext\\updater.py\", line 646, in _network_loop_retry\n",
      "    if not action_cb():\n",
      "  File \"C:\\Users\\alexb\\AppData\\Local\\Packages\\PythonSoftwareFoundation.Python.3.8_qbz5n2kfra8p0\\LocalCache\\local-packages\\Python38\\site-packages\\telegram\\ext\\updater.py\", line 597, in polling_action_cb\n",
      "    updates = self.bot.get_updates(\n",
      "  File \"C:\\Users\\alexb\\AppData\\Local\\Packages\\PythonSoftwareFoundation.Python.3.8_qbz5n2kfra8p0\\LocalCache\\local-packages\\Python38\\site-packages\\telegram\\ext\\extbot.py\", line 222, in get_updates\n",
      "    updates = super().get_updates(\n",
      "  File \"C:\\Users\\alexb\\AppData\\Local\\Packages\\PythonSoftwareFoundation.Python.3.8_qbz5n2kfra8p0\\LocalCache\\local-packages\\Python38\\site-packages\\telegram\\bot.py\", line 130, in decorator\n",
      "    result = func(*args, **kwargs)\n",
      "  File \"C:\\Users\\alexb\\AppData\\Local\\Packages\\PythonSoftwareFoundation.Python.3.8_qbz5n2kfra8p0\\LocalCache\\local-packages\\Python38\\site-packages\\telegram\\bot.py\", line 2861, in get_updates\n",
      "    self._post(\n",
      "  File \"C:\\Users\\alexb\\AppData\\Local\\Packages\\PythonSoftwareFoundation.Python.3.8_qbz5n2kfra8p0\\LocalCache\\local-packages\\Python38\\site-packages\\telegram\\bot.py\", line 295, in _post\n",
      "    return self.request.post(\n",
      "  File \"C:\\Users\\alexb\\AppData\\Local\\Packages\\PythonSoftwareFoundation.Python.3.8_qbz5n2kfra8p0\\LocalCache\\local-packages\\Python38\\site-packages\\telegram\\utils\\request.py\", line 356, in post\n",
      "    result = self._request_wrapper(\n",
      "  File \"C:\\Users\\alexb\\AppData\\Local\\Packages\\PythonSoftwareFoundation.Python.3.8_qbz5n2kfra8p0\\LocalCache\\local-packages\\Python38\\site-packages\\telegram\\utils\\request.py\", line 283, in _request_wrapper\n",
      "    raise Conflict(message)\n",
      "telegram.error.Conflict: Conflict: terminated by other getUpdates request; make sure that only one bot instance is running\n",
      "Error while getting Updates: Conflict: terminated by other getUpdates request; make sure that only one bot instance is running\n",
      "No error handlers are registered, logging exception.\n",
      "Traceback (most recent call last):\n",
      "  File \"C:\\Users\\alexb\\AppData\\Local\\Packages\\PythonSoftwareFoundation.Python.3.8_qbz5n2kfra8p0\\LocalCache\\local-packages\\Python38\\site-packages\\telegram\\ext\\updater.py\", line 646, in _network_loop_retry\n",
      "    if not action_cb():\n",
      "  File \"C:\\Users\\alexb\\AppData\\Local\\Packages\\PythonSoftwareFoundation.Python.3.8_qbz5n2kfra8p0\\LocalCache\\local-packages\\Python38\\site-packages\\telegram\\ext\\updater.py\", line 597, in polling_action_cb\n",
      "    updates = self.bot.get_updates(\n",
      "  File \"C:\\Users\\alexb\\AppData\\Local\\Packages\\PythonSoftwareFoundation.Python.3.8_qbz5n2kfra8p0\\LocalCache\\local-packages\\Python38\\site-packages\\telegram\\ext\\extbot.py\", line 222, in get_updates\n",
      "    updates = super().get_updates(\n",
      "  File \"C:\\Users\\alexb\\AppData\\Local\\Packages\\PythonSoftwareFoundation.Python.3.8_qbz5n2kfra8p0\\LocalCache\\local-packages\\Python38\\site-packages\\telegram\\bot.py\", line 130, in decorator\n",
      "    result = func(*args, **kwargs)\n",
      "  File \"C:\\Users\\alexb\\AppData\\Local\\Packages\\PythonSoftwareFoundation.Python.3.8_qbz5n2kfra8p0\\LocalCache\\local-packages\\Python38\\site-packages\\telegram\\bot.py\", line 2861, in get_updates\n",
      "    self._post(\n",
      "  File \"C:\\Users\\alexb\\AppData\\Local\\Packages\\PythonSoftwareFoundation.Python.3.8_qbz5n2kfra8p0\\LocalCache\\local-packages\\Python38\\site-packages\\telegram\\bot.py\", line 295, in _post\n",
      "    return self.request.post(\n",
      "  File \"C:\\Users\\alexb\\AppData\\Local\\Packages\\PythonSoftwareFoundation.Python.3.8_qbz5n2kfra8p0\\LocalCache\\local-packages\\Python38\\site-packages\\telegram\\utils\\request.py\", line 356, in post\n",
      "    result = self._request_wrapper(\n",
      "  File \"C:\\Users\\alexb\\AppData\\Local\\Packages\\PythonSoftwareFoundation.Python.3.8_qbz5n2kfra8p0\\LocalCache\\local-packages\\Python38\\site-packages\\telegram\\utils\\request.py\", line 283, in _request_wrapper\n",
      "    raise Conflict(message)\n",
      "telegram.error.Conflict: Conflict: terminated by other getUpdates request; make sure that only one bot instance is running\n",
      "Error while getting Updates: Conflict: terminated by other getUpdates request; make sure that only one bot instance is running\n",
      "No error handlers are registered, logging exception.\n",
      "Traceback (most recent call last):\n",
      "  File \"C:\\Users\\alexb\\AppData\\Local\\Packages\\PythonSoftwareFoundation.Python.3.8_qbz5n2kfra8p0\\LocalCache\\local-packages\\Python38\\site-packages\\telegram\\ext\\updater.py\", line 646, in _network_loop_retry\n",
      "    if not action_cb():\n",
      "  File \"C:\\Users\\alexb\\AppData\\Local\\Packages\\PythonSoftwareFoundation.Python.3.8_qbz5n2kfra8p0\\LocalCache\\local-packages\\Python38\\site-packages\\telegram\\ext\\updater.py\", line 597, in polling_action_cb\n",
      "    updates = self.bot.get_updates(\n",
      "  File \"C:\\Users\\alexb\\AppData\\Local\\Packages\\PythonSoftwareFoundation.Python.3.8_qbz5n2kfra8p0\\LocalCache\\local-packages\\Python38\\site-packages\\telegram\\ext\\extbot.py\", line 222, in get_updates\n",
      "    updates = super().get_updates(\n",
      "  File \"C:\\Users\\alexb\\AppData\\Local\\Packages\\PythonSoftwareFoundation.Python.3.8_qbz5n2kfra8p0\\LocalCache\\local-packages\\Python38\\site-packages\\telegram\\bot.py\", line 130, in decorator\n",
      "    result = func(*args, **kwargs)\n",
      "  File \"C:\\Users\\alexb\\AppData\\Local\\Packages\\PythonSoftwareFoundation.Python.3.8_qbz5n2kfra8p0\\LocalCache\\local-packages\\Python38\\site-packages\\telegram\\bot.py\", line 2861, in get_updates\n",
      "    self._post(\n",
      "  File \"C:\\Users\\alexb\\AppData\\Local\\Packages\\PythonSoftwareFoundation.Python.3.8_qbz5n2kfra8p0\\LocalCache\\local-packages\\Python38\\site-packages\\telegram\\bot.py\", line 295, in _post\n",
      "    return self.request.post(\n",
      "  File \"C:\\Users\\alexb\\AppData\\Local\\Packages\\PythonSoftwareFoundation.Python.3.8_qbz5n2kfra8p0\\LocalCache\\local-packages\\Python38\\site-packages\\telegram\\utils\\request.py\", line 356, in post\n",
      "    result = self._request_wrapper(\n",
      "  File \"C:\\Users\\alexb\\AppData\\Local\\Packages\\PythonSoftwareFoundation.Python.3.8_qbz5n2kfra8p0\\LocalCache\\local-packages\\Python38\\site-packages\\telegram\\utils\\request.py\", line 283, in _request_wrapper\n",
      "    raise Conflict(message)\n",
      "telegram.error.Conflict: Conflict: terminated by other getUpdates request; make sure that only one bot instance is running\n",
      "Error while getting Updates: Conflict: terminated by other getUpdates request; make sure that only one bot instance is running\n",
      "No error handlers are registered, logging exception.\n",
      "Traceback (most recent call last):\n",
      "  File \"C:\\Users\\alexb\\AppData\\Local\\Packages\\PythonSoftwareFoundation.Python.3.8_qbz5n2kfra8p0\\LocalCache\\local-packages\\Python38\\site-packages\\telegram\\ext\\updater.py\", line 646, in _network_loop_retry\n",
      "    if not action_cb():\n",
      "  File \"C:\\Users\\alexb\\AppData\\Local\\Packages\\PythonSoftwareFoundation.Python.3.8_qbz5n2kfra8p0\\LocalCache\\local-packages\\Python38\\site-packages\\telegram\\ext\\updater.py\", line 597, in polling_action_cb\n",
      "    updates = self.bot.get_updates(\n",
      "  File \"C:\\Users\\alexb\\AppData\\Local\\Packages\\PythonSoftwareFoundation.Python.3.8_qbz5n2kfra8p0\\LocalCache\\local-packages\\Python38\\site-packages\\telegram\\ext\\extbot.py\", line 222, in get_updates\n",
      "    updates = super().get_updates(\n",
      "  File \"C:\\Users\\alexb\\AppData\\Local\\Packages\\PythonSoftwareFoundation.Python.3.8_qbz5n2kfra8p0\\LocalCache\\local-packages\\Python38\\site-packages\\telegram\\bot.py\", line 130, in decorator\n",
      "    result = func(*args, **kwargs)\n",
      "  File \"C:\\Users\\alexb\\AppData\\Local\\Packages\\PythonSoftwareFoundation.Python.3.8_qbz5n2kfra8p0\\LocalCache\\local-packages\\Python38\\site-packages\\telegram\\bot.py\", line 2861, in get_updates\n",
      "    self._post(\n",
      "  File \"C:\\Users\\alexb\\AppData\\Local\\Packages\\PythonSoftwareFoundation.Python.3.8_qbz5n2kfra8p0\\LocalCache\\local-packages\\Python38\\site-packages\\telegram\\bot.py\", line 295, in _post\n",
      "    return self.request.post(\n",
      "  File \"C:\\Users\\alexb\\AppData\\Local\\Packages\\PythonSoftwareFoundation.Python.3.8_qbz5n2kfra8p0\\LocalCache\\local-packages\\Python38\\site-packages\\telegram\\utils\\request.py\", line 356, in post\n",
      "    result = self._request_wrapper(\n",
      "  File \"C:\\Users\\alexb\\AppData\\Local\\Packages\\PythonSoftwareFoundation.Python.3.8_qbz5n2kfra8p0\\LocalCache\\local-packages\\Python38\\site-packages\\telegram\\utils\\request.py\", line 283, in _request_wrapper\n",
      "    raise Conflict(message)\n",
      "telegram.error.Conflict: Conflict: terminated by other getUpdates request; make sure that only one bot instance is running\n",
      "Error while getting Updates: Conflict: terminated by other getUpdates request; make sure that only one bot instance is running\n",
      "No error handlers are registered, logging exception.\n",
      "Traceback (most recent call last):\n",
      "  File \"C:\\Users\\alexb\\AppData\\Local\\Packages\\PythonSoftwareFoundation.Python.3.8_qbz5n2kfra8p0\\LocalCache\\local-packages\\Python38\\site-packages\\telegram\\ext\\updater.py\", line 646, in _network_loop_retry\n",
      "    if not action_cb():\n",
      "  File \"C:\\Users\\alexb\\AppData\\Local\\Packages\\PythonSoftwareFoundation.Python.3.8_qbz5n2kfra8p0\\LocalCache\\local-packages\\Python38\\site-packages\\telegram\\ext\\updater.py\", line 597, in polling_action_cb\n",
      "    updates = self.bot.get_updates(\n",
      "  File \"C:\\Users\\alexb\\AppData\\Local\\Packages\\PythonSoftwareFoundation.Python.3.8_qbz5n2kfra8p0\\LocalCache\\local-packages\\Python38\\site-packages\\telegram\\ext\\extbot.py\", line 222, in get_updates\n",
      "    updates = super().get_updates(\n",
      "  File \"C:\\Users\\alexb\\AppData\\Local\\Packages\\PythonSoftwareFoundation.Python.3.8_qbz5n2kfra8p0\\LocalCache\\local-packages\\Python38\\site-packages\\telegram\\bot.py\", line 130, in decorator\n",
      "    result = func(*args, **kwargs)\n",
      "  File \"C:\\Users\\alexb\\AppData\\Local\\Packages\\PythonSoftwareFoundation.Python.3.8_qbz5n2kfra8p0\\LocalCache\\local-packages\\Python38\\site-packages\\telegram\\bot.py\", line 2861, in get_updates\n",
      "    self._post(\n",
      "  File \"C:\\Users\\alexb\\AppData\\Local\\Packages\\PythonSoftwareFoundation.Python.3.8_qbz5n2kfra8p0\\LocalCache\\local-packages\\Python38\\site-packages\\telegram\\bot.py\", line 295, in _post\n",
      "    return self.request.post(\n",
      "  File \"C:\\Users\\alexb\\AppData\\Local\\Packages\\PythonSoftwareFoundation.Python.3.8_qbz5n2kfra8p0\\LocalCache\\local-packages\\Python38\\site-packages\\telegram\\utils\\request.py\", line 356, in post\n",
      "    result = self._request_wrapper(\n",
      "  File \"C:\\Users\\alexb\\AppData\\Local\\Packages\\PythonSoftwareFoundation.Python.3.8_qbz5n2kfra8p0\\LocalCache\\local-packages\\Python38\\site-packages\\telegram\\utils\\request.py\", line 283, in _request_wrapper\n",
      "    raise Conflict(message)\n",
      "telegram.error.Conflict: Conflict: terminated by other getUpdates request; make sure that only one bot instance is running\n",
      "Error while getting Updates: Conflict: terminated by other getUpdates request; make sure that only one bot instance is running\n",
      "No error handlers are registered, logging exception.\n",
      "Traceback (most recent call last):\n",
      "  File \"C:\\Users\\alexb\\AppData\\Local\\Packages\\PythonSoftwareFoundation.Python.3.8_qbz5n2kfra8p0\\LocalCache\\local-packages\\Python38\\site-packages\\telegram\\ext\\updater.py\", line 646, in _network_loop_retry\n",
      "    if not action_cb():\n",
      "  File \"C:\\Users\\alexb\\AppData\\Local\\Packages\\PythonSoftwareFoundation.Python.3.8_qbz5n2kfra8p0\\LocalCache\\local-packages\\Python38\\site-packages\\telegram\\ext\\updater.py\", line 597, in polling_action_cb\n",
      "    updates = self.bot.get_updates(\n",
      "  File \"C:\\Users\\alexb\\AppData\\Local\\Packages\\PythonSoftwareFoundation.Python.3.8_qbz5n2kfra8p0\\LocalCache\\local-packages\\Python38\\site-packages\\telegram\\ext\\extbot.py\", line 222, in get_updates\n",
      "    updates = super().get_updates(\n",
      "  File \"C:\\Users\\alexb\\AppData\\Local\\Packages\\PythonSoftwareFoundation.Python.3.8_qbz5n2kfra8p0\\LocalCache\\local-packages\\Python38\\site-packages\\telegram\\bot.py\", line 130, in decorator\n",
      "    result = func(*args, **kwargs)\n",
      "  File \"C:\\Users\\alexb\\AppData\\Local\\Packages\\PythonSoftwareFoundation.Python.3.8_qbz5n2kfra8p0\\LocalCache\\local-packages\\Python38\\site-packages\\telegram\\bot.py\", line 2861, in get_updates\n",
      "    self._post(\n",
      "  File \"C:\\Users\\alexb\\AppData\\Local\\Packages\\PythonSoftwareFoundation.Python.3.8_qbz5n2kfra8p0\\LocalCache\\local-packages\\Python38\\site-packages\\telegram\\bot.py\", line 295, in _post\n",
      "    return self.request.post(\n",
      "  File \"C:\\Users\\alexb\\AppData\\Local\\Packages\\PythonSoftwareFoundation.Python.3.8_qbz5n2kfra8p0\\LocalCache\\local-packages\\Python38\\site-packages\\telegram\\utils\\request.py\", line 356, in post\n",
      "    result = self._request_wrapper(\n",
      "  File \"C:\\Users\\alexb\\AppData\\Local\\Packages\\PythonSoftwareFoundation.Python.3.8_qbz5n2kfra8p0\\LocalCache\\local-packages\\Python38\\site-packages\\telegram\\utils\\request.py\", line 283, in _request_wrapper\n",
      "    raise Conflict(message)\n",
      "telegram.error.Conflict: Conflict: terminated by other getUpdates request; make sure that only one bot instance is running\n",
      "Error while getting Updates: Conflict: terminated by other getUpdates request; make sure that only one bot instance is running\n",
      "No error handlers are registered, logging exception.\n",
      "Traceback (most recent call last):\n",
      "  File \"C:\\Users\\alexb\\AppData\\Local\\Packages\\PythonSoftwareFoundation.Python.3.8_qbz5n2kfra8p0\\LocalCache\\local-packages\\Python38\\site-packages\\telegram\\ext\\updater.py\", line 646, in _network_loop_retry\n",
      "    if not action_cb():\n",
      "  File \"C:\\Users\\alexb\\AppData\\Local\\Packages\\PythonSoftwareFoundation.Python.3.8_qbz5n2kfra8p0\\LocalCache\\local-packages\\Python38\\site-packages\\telegram\\ext\\updater.py\", line 597, in polling_action_cb\n",
      "    updates = self.bot.get_updates(\n",
      "  File \"C:\\Users\\alexb\\AppData\\Local\\Packages\\PythonSoftwareFoundation.Python.3.8_qbz5n2kfra8p0\\LocalCache\\local-packages\\Python38\\site-packages\\telegram\\ext\\extbot.py\", line 222, in get_updates\n",
      "    updates = super().get_updates(\n",
      "  File \"C:\\Users\\alexb\\AppData\\Local\\Packages\\PythonSoftwareFoundation.Python.3.8_qbz5n2kfra8p0\\LocalCache\\local-packages\\Python38\\site-packages\\telegram\\bot.py\", line 130, in decorator\n",
      "    result = func(*args, **kwargs)\n",
      "  File \"C:\\Users\\alexb\\AppData\\Local\\Packages\\PythonSoftwareFoundation.Python.3.8_qbz5n2kfra8p0\\LocalCache\\local-packages\\Python38\\site-packages\\telegram\\bot.py\", line 2861, in get_updates\n",
      "    self._post(\n",
      "  File \"C:\\Users\\alexb\\AppData\\Local\\Packages\\PythonSoftwareFoundation.Python.3.8_qbz5n2kfra8p0\\LocalCache\\local-packages\\Python38\\site-packages\\telegram\\bot.py\", line 295, in _post\n",
      "    return self.request.post(\n",
      "  File \"C:\\Users\\alexb\\AppData\\Local\\Packages\\PythonSoftwareFoundation.Python.3.8_qbz5n2kfra8p0\\LocalCache\\local-packages\\Python38\\site-packages\\telegram\\utils\\request.py\", line 356, in post\n",
      "    result = self._request_wrapper(\n",
      "  File \"C:\\Users\\alexb\\AppData\\Local\\Packages\\PythonSoftwareFoundation.Python.3.8_qbz5n2kfra8p0\\LocalCache\\local-packages\\Python38\\site-packages\\telegram\\utils\\request.py\", line 283, in _request_wrapper\n",
      "    raise Conflict(message)\n",
      "telegram.error.Conflict: Conflict: terminated by other getUpdates request; make sure that only one bot instance is running\n",
      "Error while getting Updates: Conflict: terminated by other getUpdates request; make sure that only one bot instance is running\n",
      "No error handlers are registered, logging exception.\n",
      "Traceback (most recent call last):\n",
      "  File \"C:\\Users\\alexb\\AppData\\Local\\Packages\\PythonSoftwareFoundation.Python.3.8_qbz5n2kfra8p0\\LocalCache\\local-packages\\Python38\\site-packages\\telegram\\ext\\updater.py\", line 646, in _network_loop_retry\n",
      "    if not action_cb():\n",
      "  File \"C:\\Users\\alexb\\AppData\\Local\\Packages\\PythonSoftwareFoundation.Python.3.8_qbz5n2kfra8p0\\LocalCache\\local-packages\\Python38\\site-packages\\telegram\\ext\\updater.py\", line 597, in polling_action_cb\n",
      "    updates = self.bot.get_updates(\n",
      "  File \"C:\\Users\\alexb\\AppData\\Local\\Packages\\PythonSoftwareFoundation.Python.3.8_qbz5n2kfra8p0\\LocalCache\\local-packages\\Python38\\site-packages\\telegram\\ext\\extbot.py\", line 222, in get_updates\n",
      "    updates = super().get_updates(\n",
      "  File \"C:\\Users\\alexb\\AppData\\Local\\Packages\\PythonSoftwareFoundation.Python.3.8_qbz5n2kfra8p0\\LocalCache\\local-packages\\Python38\\site-packages\\telegram\\bot.py\", line 130, in decorator\n",
      "    result = func(*args, **kwargs)\n",
      "  File \"C:\\Users\\alexb\\AppData\\Local\\Packages\\PythonSoftwareFoundation.Python.3.8_qbz5n2kfra8p0\\LocalCache\\local-packages\\Python38\\site-packages\\telegram\\bot.py\", line 2861, in get_updates\n",
      "    self._post(\n",
      "  File \"C:\\Users\\alexb\\AppData\\Local\\Packages\\PythonSoftwareFoundation.Python.3.8_qbz5n2kfra8p0\\LocalCache\\local-packages\\Python38\\site-packages\\telegram\\bot.py\", line 295, in _post\n",
      "    return self.request.post(\n",
      "  File \"C:\\Users\\alexb\\AppData\\Local\\Packages\\PythonSoftwareFoundation.Python.3.8_qbz5n2kfra8p0\\LocalCache\\local-packages\\Python38\\site-packages\\telegram\\utils\\request.py\", line 356, in post\n",
      "    result = self._request_wrapper(\n",
      "  File \"C:\\Users\\alexb\\AppData\\Local\\Packages\\PythonSoftwareFoundation.Python.3.8_qbz5n2kfra8p0\\LocalCache\\local-packages\\Python38\\site-packages\\telegram\\utils\\request.py\", line 283, in _request_wrapper\n",
      "    raise Conflict(message)\n",
      "telegram.error.Conflict: Conflict: terminated by other getUpdates request; make sure that only one bot instance is running\n",
      "Error while getting Updates: Conflict: terminated by other getUpdates request; make sure that only one bot instance is running\n",
      "No error handlers are registered, logging exception.\n",
      "Traceback (most recent call last):\n",
      "  File \"C:\\Users\\alexb\\AppData\\Local\\Packages\\PythonSoftwareFoundation.Python.3.8_qbz5n2kfra8p0\\LocalCache\\local-packages\\Python38\\site-packages\\telegram\\ext\\updater.py\", line 646, in _network_loop_retry\n",
      "    if not action_cb():\n",
      "  File \"C:\\Users\\alexb\\AppData\\Local\\Packages\\PythonSoftwareFoundation.Python.3.8_qbz5n2kfra8p0\\LocalCache\\local-packages\\Python38\\site-packages\\telegram\\ext\\updater.py\", line 597, in polling_action_cb\n",
      "    updates = self.bot.get_updates(\n",
      "  File \"C:\\Users\\alexb\\AppData\\Local\\Packages\\PythonSoftwareFoundation.Python.3.8_qbz5n2kfra8p0\\LocalCache\\local-packages\\Python38\\site-packages\\telegram\\ext\\extbot.py\", line 222, in get_updates\n",
      "    updates = super().get_updates(\n",
      "  File \"C:\\Users\\alexb\\AppData\\Local\\Packages\\PythonSoftwareFoundation.Python.3.8_qbz5n2kfra8p0\\LocalCache\\local-packages\\Python38\\site-packages\\telegram\\bot.py\", line 130, in decorator\n",
      "    result = func(*args, **kwargs)\n",
      "  File \"C:\\Users\\alexb\\AppData\\Local\\Packages\\PythonSoftwareFoundation.Python.3.8_qbz5n2kfra8p0\\LocalCache\\local-packages\\Python38\\site-packages\\telegram\\bot.py\", line 2861, in get_updates\n",
      "    self._post(\n",
      "  File \"C:\\Users\\alexb\\AppData\\Local\\Packages\\PythonSoftwareFoundation.Python.3.8_qbz5n2kfra8p0\\LocalCache\\local-packages\\Python38\\site-packages\\telegram\\bot.py\", line 295, in _post\n",
      "    return self.request.post(\n",
      "  File \"C:\\Users\\alexb\\AppData\\Local\\Packages\\PythonSoftwareFoundation.Python.3.8_qbz5n2kfra8p0\\LocalCache\\local-packages\\Python38\\site-packages\\telegram\\utils\\request.py\", line 356, in post\n",
      "    result = self._request_wrapper(\n",
      "  File \"C:\\Users\\alexb\\AppData\\Local\\Packages\\PythonSoftwareFoundation.Python.3.8_qbz5n2kfra8p0\\LocalCache\\local-packages\\Python38\\site-packages\\telegram\\utils\\request.py\", line 283, in _request_wrapper\n",
      "    raise Conflict(message)\n",
      "telegram.error.Conflict: Conflict: terminated by other getUpdates request; make sure that only one bot instance is running\n",
      "Error while getting Updates: Conflict: terminated by other getUpdates request; make sure that only one bot instance is running\n",
      "No error handlers are registered, logging exception.\n",
      "Traceback (most recent call last):\n",
      "  File \"C:\\Users\\alexb\\AppData\\Local\\Packages\\PythonSoftwareFoundation.Python.3.8_qbz5n2kfra8p0\\LocalCache\\local-packages\\Python38\\site-packages\\telegram\\ext\\updater.py\", line 646, in _network_loop_retry\n",
      "    if not action_cb():\n",
      "  File \"C:\\Users\\alexb\\AppData\\Local\\Packages\\PythonSoftwareFoundation.Python.3.8_qbz5n2kfra8p0\\LocalCache\\local-packages\\Python38\\site-packages\\telegram\\ext\\updater.py\", line 597, in polling_action_cb\n",
      "    updates = self.bot.get_updates(\n",
      "  File \"C:\\Users\\alexb\\AppData\\Local\\Packages\\PythonSoftwareFoundation.Python.3.8_qbz5n2kfra8p0\\LocalCache\\local-packages\\Python38\\site-packages\\telegram\\ext\\extbot.py\", line 222, in get_updates\n",
      "    updates = super().get_updates(\n",
      "  File \"C:\\Users\\alexb\\AppData\\Local\\Packages\\PythonSoftwareFoundation.Python.3.8_qbz5n2kfra8p0\\LocalCache\\local-packages\\Python38\\site-packages\\telegram\\bot.py\", line 130, in decorator\n",
      "    result = func(*args, **kwargs)\n",
      "  File \"C:\\Users\\alexb\\AppData\\Local\\Packages\\PythonSoftwareFoundation.Python.3.8_qbz5n2kfra8p0\\LocalCache\\local-packages\\Python38\\site-packages\\telegram\\bot.py\", line 2861, in get_updates\n",
      "    self._post(\n",
      "  File \"C:\\Users\\alexb\\AppData\\Local\\Packages\\PythonSoftwareFoundation.Python.3.8_qbz5n2kfra8p0\\LocalCache\\local-packages\\Python38\\site-packages\\telegram\\bot.py\", line 295, in _post\n",
      "    return self.request.post(\n",
      "  File \"C:\\Users\\alexb\\AppData\\Local\\Packages\\PythonSoftwareFoundation.Python.3.8_qbz5n2kfra8p0\\LocalCache\\local-packages\\Python38\\site-packages\\telegram\\utils\\request.py\", line 356, in post\n",
      "    result = self._request_wrapper(\n",
      "  File \"C:\\Users\\alexb\\AppData\\Local\\Packages\\PythonSoftwareFoundation.Python.3.8_qbz5n2kfra8p0\\LocalCache\\local-packages\\Python38\\site-packages\\telegram\\utils\\request.py\", line 283, in _request_wrapper\n",
      "    raise Conflict(message)\n",
      "telegram.error.Conflict: Conflict: terminated by other getUpdates request; make sure that only one bot instance is running\n",
      "Error while getting Updates: Conflict: terminated by other getUpdates request; make sure that only one bot instance is running\n",
      "No error handlers are registered, logging exception.\n",
      "Traceback (most recent call last):\n",
      "  File \"C:\\Users\\alexb\\AppData\\Local\\Packages\\PythonSoftwareFoundation.Python.3.8_qbz5n2kfra8p0\\LocalCache\\local-packages\\Python38\\site-packages\\telegram\\ext\\updater.py\", line 646, in _network_loop_retry\n",
      "    if not action_cb():\n",
      "  File \"C:\\Users\\alexb\\AppData\\Local\\Packages\\PythonSoftwareFoundation.Python.3.8_qbz5n2kfra8p0\\LocalCache\\local-packages\\Python38\\site-packages\\telegram\\ext\\updater.py\", line 597, in polling_action_cb\n",
      "    updates = self.bot.get_updates(\n",
      "  File \"C:\\Users\\alexb\\AppData\\Local\\Packages\\PythonSoftwareFoundation.Python.3.8_qbz5n2kfra8p0\\LocalCache\\local-packages\\Python38\\site-packages\\telegram\\ext\\extbot.py\", line 222, in get_updates\n",
      "    updates = super().get_updates(\n",
      "  File \"C:\\Users\\alexb\\AppData\\Local\\Packages\\PythonSoftwareFoundation.Python.3.8_qbz5n2kfra8p0\\LocalCache\\local-packages\\Python38\\site-packages\\telegram\\bot.py\", line 130, in decorator\n",
      "    result = func(*args, **kwargs)\n",
      "  File \"C:\\Users\\alexb\\AppData\\Local\\Packages\\PythonSoftwareFoundation.Python.3.8_qbz5n2kfra8p0\\LocalCache\\local-packages\\Python38\\site-packages\\telegram\\bot.py\", line 2861, in get_updates\n",
      "    self._post(\n",
      "  File \"C:\\Users\\alexb\\AppData\\Local\\Packages\\PythonSoftwareFoundation.Python.3.8_qbz5n2kfra8p0\\LocalCache\\local-packages\\Python38\\site-packages\\telegram\\bot.py\", line 295, in _post\n",
      "    return self.request.post(\n",
      "  File \"C:\\Users\\alexb\\AppData\\Local\\Packages\\PythonSoftwareFoundation.Python.3.8_qbz5n2kfra8p0\\LocalCache\\local-packages\\Python38\\site-packages\\telegram\\utils\\request.py\", line 356, in post\n",
      "    result = self._request_wrapper(\n",
      "  File \"C:\\Users\\alexb\\AppData\\Local\\Packages\\PythonSoftwareFoundation.Python.3.8_qbz5n2kfra8p0\\LocalCache\\local-packages\\Python38\\site-packages\\telegram\\utils\\request.py\", line 283, in _request_wrapper\n",
      "    raise Conflict(message)\n",
      "telegram.error.Conflict: Conflict: terminated by other getUpdates request; make sure that only one bot instance is running\n",
      "Error while getting Updates: Conflict: terminated by other getUpdates request; make sure that only one bot instance is running\n",
      "No error handlers are registered, logging exception.\n",
      "Traceback (most recent call last):\n",
      "  File \"C:\\Users\\alexb\\AppData\\Local\\Packages\\PythonSoftwareFoundation.Python.3.8_qbz5n2kfra8p0\\LocalCache\\local-packages\\Python38\\site-packages\\telegram\\ext\\updater.py\", line 646, in _network_loop_retry\n",
      "    if not action_cb():\n",
      "  File \"C:\\Users\\alexb\\AppData\\Local\\Packages\\PythonSoftwareFoundation.Python.3.8_qbz5n2kfra8p0\\LocalCache\\local-packages\\Python38\\site-packages\\telegram\\ext\\updater.py\", line 597, in polling_action_cb\n",
      "    updates = self.bot.get_updates(\n",
      "  File \"C:\\Users\\alexb\\AppData\\Local\\Packages\\PythonSoftwareFoundation.Python.3.8_qbz5n2kfra8p0\\LocalCache\\local-packages\\Python38\\site-packages\\telegram\\ext\\extbot.py\", line 222, in get_updates\n",
      "    updates = super().get_updates(\n",
      "  File \"C:\\Users\\alexb\\AppData\\Local\\Packages\\PythonSoftwareFoundation.Python.3.8_qbz5n2kfra8p0\\LocalCache\\local-packages\\Python38\\site-packages\\telegram\\bot.py\", line 130, in decorator\n",
      "    result = func(*args, **kwargs)\n",
      "  File \"C:\\Users\\alexb\\AppData\\Local\\Packages\\PythonSoftwareFoundation.Python.3.8_qbz5n2kfra8p0\\LocalCache\\local-packages\\Python38\\site-packages\\telegram\\bot.py\", line 2861, in get_updates\n",
      "    self._post(\n",
      "  File \"C:\\Users\\alexb\\AppData\\Local\\Packages\\PythonSoftwareFoundation.Python.3.8_qbz5n2kfra8p0\\LocalCache\\local-packages\\Python38\\site-packages\\telegram\\bot.py\", line 295, in _post\n",
      "    return self.request.post(\n",
      "  File \"C:\\Users\\alexb\\AppData\\Local\\Packages\\PythonSoftwareFoundation.Python.3.8_qbz5n2kfra8p0\\LocalCache\\local-packages\\Python38\\site-packages\\telegram\\utils\\request.py\", line 356, in post\n",
      "    result = self._request_wrapper(\n",
      "  File \"C:\\Users\\alexb\\AppData\\Local\\Packages\\PythonSoftwareFoundation.Python.3.8_qbz5n2kfra8p0\\LocalCache\\local-packages\\Python38\\site-packages\\telegram\\utils\\request.py\", line 283, in _request_wrapper\n",
      "    raise Conflict(message)\n",
      "telegram.error.Conflict: Conflict: terminated by other getUpdates request; make sure that only one bot instance is running\n"
     ]
    }
   ],
   "source": [
    "import telegram\n",
    "from telegram.ext import Updater, CommandHandler, MessageHandler, Filters\n",
    "\n",
    "def start(update, context):\n",
    "    context.bot.send_message(chat_id=update.effective_chat.id, text=\"Hello! What's your name?\")\n",
    "\n",
    "def echo(update, context):\n",
    "    user_input = update.message.text\n",
    "    context.bot.send_message(chat_id=update.effective_chat.id, text=\"Hi, \"+user_input+\"!\")\n",
    "\n",
    "def main():\n",
    "    updater = Updater(token='6027981425:AAHdSWkDWAgxMvZZTdXXKmoTK6eo_JJmTto', use_context=True)\n",
    "    dispatcher = updater.dispatcher\n",
    "    dispatcher.add_handler(CommandHandler('start', start))\n",
    "    dispatcher.add_handler(MessageHandler(Filters.text & ~Filters.command, echo))\n",
    "    updater.start_polling(poll_interval=0.5)\n"
   ]
  }
 ],
 "metadata": {
  "kernelspec": {
   "display_name": "Python 3",
   "language": "python",
   "name": "python3"
  },
  "language_info": {
   "codemirror_mode": {
    "name": "ipython",
    "version": 3
   },
   "file_extension": ".py",
   "mimetype": "text/x-python",
   "name": "python",
   "nbconvert_exporter": "python",
   "pygments_lexer": "ipython3",
   "version": "3.8.10"
  },
  "orig_nbformat": 4
 },
 "nbformat": 4,
 "nbformat_minor": 2
}
