{
 "cells": [
  {
   "cell_type": "code",
   "execution_count": 15,
   "metadata": {},
   "outputs": [
    {
     "name": "stdout",
     "output_type": "stream",
     "text": [
      "[\n",
      "\t{\n",
      "\t\t\"type\": \"stop\",\n",
      "\t\t\"id\": \"900000012156\",\n",
      "\t\t\"name\": \"Alexandrinenstr.\",\n",
      "\t\t\"location\": {\n",
      "\t\t\t\"type\": \"location\",\n",
      "\t\t\t\"id\": \"900012156\",\n",
      "\t\t\t\"latitude\": 52.505157,\n",
      "\t\t\t\"longitude\": 13.405326\n",
      "\t\t},\n",
      "\t\t\"products\": {\n",
      "\t\t\t\"suburban\": false,\n",
      "\t\t\t\"subway\": false,\n",
      "\t\t\t\"tram\": false,\n",
      "\t\t\t\"bus\": true,\n",
      "\t\t\t\"ferry\": false,\n",
      "\t\t\t\"express\": false,\n",
      "\t\t\t\"regional\": false\n",
      "\t\t},\n",
      "\t\t\"stationDHID\": \"de:11000:900012156\"\n",
      "\t},\n",
      "\t{\n",
      "\t\t\"type\": \"stop\",\n",
      "\t\t\"id\": \"900000100003\",\n",
      "\t\t\"name\": \"S+U Alexanderplatz\",\n",
      "\t\t\"location\": {\n",
      "\t\t\t\"type\": \"location\",\n",
      "\t\t\t\"id\": \"900100003\",\n",
      "\t\t\t\"latitude\": 52.521508,\n",
      "\t\t\t\"longitude\": 13.411267\n",
      "\t\t},\n",
      "\t\t\"products\": {\n",
      "\t\t\t\"suburban\": true,\n",
      "\t\t\t\"subway\": true,\n",
      "\t\t\t\"tram\": true,\n",
      "\t\t\t\"bus\": true,\n",
      "\t\t\t\"ferry\": false,\n",
      "\t\t\t\"express\": false,\n",
      "\t\t\t\"regional\": true\n",
      "\t\t},\n",
      "\t\t\"stationDHID\": \"de:11000:900100003\"\n",
      "\t},\n",
      "\t{\n",
      "\t\t\"type\": \"stop\",\n",
      "\t\t\"id\": \"900000100731\",\n",
      "\t\t\"name\": \"S+U Alexanderpl/Memhardstr.\",\n",
      "\t\t\"location\": {\n",
      "\t\t\t\"type\": \"location\",\n",
      "\t\t\t\"id\": \"900100731\",\n",
      "\t\t\t\"latitude\": 52.523513,\n",
      "\t\t\t\"longitude\": 13.411366\n",
      "\t\t},\n",
      "\t\t\"products\": {\n",
      "\t\t\t\"suburban\": true,\n",
      "\t\t\t\"subway\": true,\n",
      "\t\t\t\"tram\": true,\n",
      "\t\t\t\"bus\": true,\n",
      "\t\t\t\"ferry\": false,\n",
      "\t\t\t\"express\": false,\n",
      "\t\t\t\"regional\": true\n",
      "\t\t},\n",
      "\t\t\"stationDHID\": \"de:11000:900100731\"\n",
      "\t}\n",
      "]\n"
     ]
    }
   ],
   "source": [
    "#basic html reguest to get the html code of a website and print it out \n",
    "import urllib.request\n",
    "import urllib.parse\n",
    "import urllib.error\n",
    "url = 'https://v5.bvg.transport.rest/locations?query=alexander&results=3&fuzzy=true'\n",
    "html = urllib.request.urlopen(url).read()\n",
    "print(html.decode())\n"
   ]
  },
  {
   "cell_type": "code",
   "execution_count": 27,
   "metadata": {},
   "outputs": [
    {
     "name": "stdout",
     "output_type": "stream",
     "text": [
      "18\n",
      "[\n",
      "\t{\n",
      "\t\t\"type\": \"stop\",\n",
      "\t\t\"id\": \"900000100026\",\n",
      "\t\t\"name\": \"S+U Alexanderplatz/Gontardstr.\",\n",
      "\t\t\"location\": {\n",
      "\t\t\t\"type\": \"location\",\n",
      "\t\t\t\"id\": \"900100026\",\n",
      "\t\t\t\"latitude\": 52.52105,\n",
      "\t\t\t\"longitude\": 13.411285\n",
      "\t\t},\n",
      "\t\t\"products\": {\n",
      "\t\t\t\"suburban\": false,\n",
      "\t\t\t\"subway\": false,\n",
      "\t\t\t\"tram\": true,\n",
      "\t\t\t\"bus\": false,\n",
      "\t\t\t\"ferry\": false,\n",
      "\t\t\t\"express\": false,\n",
      "\t\t\t\"regional\": false\n",
      "\t\t},\n",
      "\t\t\"stationDHID\": \"de:11000:900100026\",\n",
      "\t\t\"distance\": 59\n",
      "\t},\n",
      "\t{\n",
      "\t\t\"type\": \"stop\",\n",
      "\t\t\"id\": \"900000100024\",\n",
      "\t\t\"name\": \"S+U Alexanderplatz/Dircksenstr.\",\n",
      "\t\t\"location\": {\n",
      "\t\t\t\"type\": \"location\",\n",
      "\t\t\t\"id\": \"900100024\",\n",
      "\t\t\t\"latitude\": 52.521481,\n",
      "\t\t\t\"longitude\": 13.411924\n",
      "\t\t},\n",
      "\t\t\"products\": {\n",
      "\t\t\t\"suburban\": false,\n",
      "\t\t\t\"subway\": false,\n",
      "\t\t\t\"tram\": true,\n",
      "\t\t\t\"bus\": false,\n",
      "\t\t\t\"ferry\": false,\n",
      "\t\t\t\"express\": false,\n",
      "\t\t\t\"regional\": false\n",
      "\t\t},\n",
      "\t\t\"stationDHID\": \"de:11000:900100024\",\n",
      "\t\t\"distance\": 92\n",
      "\t},\n",
      "\t{\n",
      "\t\t\"type\": \"stop\",\n",
      "\t\t\"id\": \"900000100003\",\n",
      "\t\t\"name\": \"S+U Alexanderplatz\",\n",
      "\t\t\"location\": {\n",
      "\t\t\t\"type\": \"location\",\n",
      "\t\t\t\"id\": \"900100003\",\n",
      "\t\t\t\"latitude\": 52.521508,\n",
      "\t\t\t\"longitude\": 13.411267\n",
      "\t\t},\n",
      "\t\t\"products\": {\n",
      "\t\t\t\"suburban\": true,\n",
      "\t\t\t\"subway\": false,\n",
      "\t\t\t\"tram\": false,\n",
      "\t\t\t\"bus\": false,\n",
      "\t\t\t\"ferry\": false,\n",
      "\t\t\t\"express\": false,\n",
      "\t\t\t\"regional\": true\n",
      "\t\t},\n",
      "\t\t\"stationDHID\": \"de:11000:900100003\",\n",
      "\t\t\"distance\": 103\n",
      "\t},\n",
      "\t{\n",
      "\t\t\"type\": \"stop\",\n",
      "\t\t\"id\": \"900000100705\",\n",
      "\t\t\"name\": \"S+U Alexanderplatz [U8]\",\n",
      "\t\t\"location\": {\n",
      "\t\t\t\"type\": \"location\",\n",
      "\t\t\t\"id\": \"900100705\",\n",
      "\t\t\t\"latitude\": 52.521616,\n",
      "\t\t\t\"longitude\": 13.412121\n",
      "\t\t},\n",
      "\t\t\"products\": {\n",
      "\t\t\t\"suburban\": false,\n",
      "\t\t\t\"subway\": true,\n",
      "\t\t\t\"tram\": false,\n",
      "\t\t\t\"bus\": false,\n",
      "\t\t\t\"ferry\": false,\n",
      "\t\t\t\"express\": false,\n",
      "\t\t\t\"regional\": false\n",
      "\t\t},\n",
      "\t\t\"stationDHID\": \"de:11000:900100705\",\n",
      "\t\t\"distance\": 108\n",
      "\t},\n",
      "\t{\n",
      "\t\t\"type\": \"stop\",\n",
      "\t\t\"id\": \"900000100704\",\n",
      "\t\t\"name\": \"S+U Alexanderplatz [U5]\",\n",
      "\t\t\"location\": {\n",
      "\t\t\t\"type\": \"location\",\n",
      "\t\t\t\"id\": \"900100704\",\n",
      "\t\t\t\"latitude\": 52.521607,\n",
      "\t\t\t\"longitude\": 13.41311\n",
      "\t\t},\n",
      "\t\t\"products\": {\n",
      "\t\t\t\"suburban\": false,\n",
      "\t\t\t\"subway\": true,\n",
      "\t\t\t\"tram\": false,\n",
      "\t\t\t\"bus\": false,\n",
      "\t\t\t\"ferry\": false,\n",
      "\t\t\t\"express\": false,\n",
      "\t\t\t\"regional\": false\n",
      "\t\t},\n",
      "\t\t\"stationDHID\": \"de:11000:900100704\",\n",
      "\t\t\"distance\": 134\n",
      "\t},\n",
      "\t{\n",
      "\t\t\"type\": \"stop\",\n",
      "\t\t\"id\": \"900000100560\",\n",
      "\t\t\"name\": \"Littenstr.\",\n",
      "\t\t\"location\": {\n",
      "\t\t\t\"type\": \"location\",\n",
      "\t\t\t\"id\": \"900100560\",\n",
      "\t\t\t\"latitude\": 52.519647,\n",
      "\t\t\t\"longitude\": 13.413641\n",
      "\t\t},\n",
      "\t\t\"products\": {\n",
      "\t\t\t\"suburban\": false,\n",
      "\t\t\t\"subway\": false,\n",
      "\t\t\t\"tram\": false,\n",
      "\t\t\t\"bus\": true,\n",
      "\t\t\t\"ferry\": false,\n",
      "\t\t\t\"express\": false,\n",
      "\t\t\t\"regional\": false\n",
      "\t\t},\n",
      "\t\t\"stationDHID\": \"de:11000:900100560\",\n",
      "\t\t\"distance\": 163\n",
      "\t},\n",
      "\t{\n",
      "\t\t\"type\": \"stop\",\n",
      "\t\t\"id\": \"900000100711\",\n",
      "\t\t\"name\": \"S+U Alexanderpl./Grunerstr [Grunerstr.]\",\n",
      "\t\t\"location\": {\n",
      "\t\t\t\"type\": \"location\",\n",
      "\t\t\t\"id\": \"900100711\",\n",
      "\t\t\t\"latitude\": 52.520618,\n",
      "\t\t\t\"longitude\": 13.414674\n",
      "\t\t},\n",
      "\t\t\"products\": {\n",
      "\t\t\t\"suburban\": false,\n",
      "\t\t\t\"subway\": false,\n",
      "\t\t\t\"tram\": false,\n",
      "\t\t\t\"bus\": true,\n",
      "\t\t\t\"ferry\": false,\n",
      "\t\t\t\"express\": false,\n",
      "\t\t\t\"regional\": false\n",
      "\t\t},\n",
      "\t\t\"stationDHID\": \"de:11000:900100711\",\n",
      "\t\t\"distance\": 189\n",
      "\t},\n",
      "\t{\n",
      "\t\t\"type\": \"stop\",\n",
      "\t\t\"id\": \"900000100703\",\n",
      "\t\t\"name\": \"S+U Alexanderplatz [U2]\",\n",
      "\t\t\"location\": {\n",
      "\t\t\t\"type\": \"location\",\n",
      "\t\t\t\"id\": \"900100703\",\n",
      "\t\t\t\"latitude\": 52.522075,\n",
      "\t\t\t\"longitude\": 13.413596\n",
      "\t\t},\n",
      "\t\t\"products\": {\n",
      "\t\t\t\"suburban\": false,\n",
      "\t\t\t\"subway\": true,\n",
      "\t\t\t\"tram\": false,\n",
      "\t\t\t\"bus\": false,\n",
      "\t\t\t\"ferry\": false,\n",
      "\t\t\t\"express\": false,\n",
      "\t\t\t\"regional\": false\n",
      "\t\t},\n",
      "\t\t\"stationDHID\": \"de:11000:900100703\",\n",
      "\t\t\"distance\": 196\n",
      "\t},\n",
      "\t{\n",
      "\t\t\"type\": \"stop\",\n",
      "\t\t\"id\": \"900000100005\",\n",
      "\t\t\"name\": \"U Alexanderplatz [Tram]\",\n",
      "\t\t\"location\": {\n",
      "\t\t\t\"type\": \"location\",\n",
      "\t\t\t\"id\": \"900100005\",\n",
      "\t\t\t\"latitude\": 52.522083,\n",
      "\t\t\t\"longitude\": 13.414593\n",
      "\t\t},\n",
      "\t\t\"products\": {\n",
      "\t\t\t\"suburban\": false,\n",
      "\t\t\t\"subway\": false,\n",
      "\t\t\t\"tram\": true,\n",
      "\t\t\t\"bus\": false,\n",
      "\t\t\t\"ferry\": false,\n",
      "\t\t\t\"express\": false,\n",
      "\t\t\t\"regional\": false\n",
      "\t\t},\n",
      "\t\t\"stationDHID\": \"de:11000:900100005\",\n",
      "\t\t\"distance\": 242\n",
      "\t},\n",
      "\t{\n",
      "\t\t\"type\": \"stop\",\n",
      "\t\t\"id\": \"900000100031\",\n",
      "\t\t\"name\": \"S+U Alexanderplatz/Memhardstr.\",\n",
      "\t\t\"location\": {\n",
      "\t\t\t\"type\": \"location\",\n",
      "\t\t\t\"id\": \"900100031\",\n",
      "\t\t\t\"latitude\": 52.522937,\n",
      "\t\t\t\"longitude\": 13.410755\n",
      "\t\t},\n",
      "\t\t\"products\": {\n",
      "\t\t\t\"suburban\": false,\n",
      "\t\t\t\"subway\": false,\n",
      "\t\t\t\"tram\": false,\n",
      "\t\t\t\"bus\": true,\n",
      "\t\t\t\"ferry\": false,\n",
      "\t\t\t\"express\": false,\n",
      "\t\t\t\"regional\": false\n",
      "\t\t},\n",
      "\t\t\"stationDHID\": \"de:11000:900100031\",\n",
      "\t\t\"distance\": 265\n",
      "\t},\n",
      "\t{\n",
      "\t\t\"type\": \"stop\",\n",
      "\t\t\"id\": \"900000100559\",\n",
      "\t\t\"name\": \"Jüdenstr.\",\n",
      "\t\t\"location\": {\n",
      "\t\t\t\"type\": \"location\",\n",
      "\t\t\t\"id\": \"900100559\",\n",
      "\t\t\t\"latitude\": 52.518317,\n",
      "\t\t\t\"longitude\": 13.410396\n",
      "\t\t},\n",
      "\t\t\"products\": {\n",
      "\t\t\t\"suburban\": false,\n",
      "\t\t\t\"subway\": false,\n",
      "\t\t\t\"tram\": false,\n",
      "\t\t\t\"bus\": true,\n",
      "\t\t\t\"ferry\": false,\n",
      "\t\t\t\"express\": false,\n",
      "\t\t\t\"regional\": false\n",
      "\t\t},\n",
      "\t\t\"stationDHID\": \"de:11000:900100559\",\n",
      "\t\t\"distance\": 278\n",
      "\t},\n",
      "\t{\n",
      "\t\t\"type\": \"stop\",\n",
      "\t\t\"id\": \"900000100731\",\n",
      "\t\t\"name\": \"S+U Alexanderpl/Memhardstr.\",\n",
      "\t\t\"location\": {\n",
      "\t\t\t\"type\": \"location\",\n",
      "\t\t\t\"id\": \"900100731\",\n",
      "\t\t\t\"latitude\": 52.523513,\n",
      "\t\t\t\"longitude\": 13.411366\n",
      "\t\t},\n",
      "\t\t\"products\": {\n",
      "\t\t\t\"suburban\": false,\n",
      "\t\t\t\"subway\": false,\n",
      "\t\t\t\"tram\": true,\n",
      "\t\t\t\"bus\": false,\n",
      "\t\t\t\"ferry\": false,\n",
      "\t\t\t\"express\": false,\n",
      "\t\t\t\"regional\": false\n",
      "\t\t},\n",
      "\t\t\"stationDHID\": \"de:11000:900100731\",\n",
      "\t\t\"distance\": 319\n",
      "\t},\n",
      "\t{\n",
      "\t\t\"type\": \"stop\",\n",
      "\t\t\"id\": \"900000100015\",\n",
      "\t\t\"name\": \"U Klosterstr.\",\n",
      "\t\t\"location\": {\n",
      "\t\t\t\"type\": \"location\",\n",
      "\t\t\t\"id\": \"900100015\",\n",
      "\t\t\t\"latitude\": 52.517229,\n",
      "\t\t\t\"longitude\": 13.412454\n",
      "\t\t},\n",
      "\t\t\"products\": {\n",
      "\t\t\t\"suburban\": false,\n",
      "\t\t\t\"subway\": true,\n",
      "\t\t\t\"tram\": false,\n",
      "\t\t\t\"bus\": false,\n",
      "\t\t\t\"ferry\": false,\n",
      "\t\t\t\"express\": false,\n",
      "\t\t\t\"regional\": false\n",
      "\t\t},\n",
      "\t\t\"stationDHID\": \"de:11000:900100015\",\n",
      "\t\t\"distance\": 382\n",
      "\t},\n",
      "\t{\n",
      "\t\t\"type\": \"stop\",\n",
      "\t\t\"id\": \"900000100002\",\n",
      "\t\t\"name\": \"S Hackescher Markt\",\n",
      "\t\t\"location\": {\n",
      "\t\t\t\"type\": \"location\",\n",
      "\t\t\t\"id\": \"900100002\",\n",
      "\t\t\t\"latitude\": 52.522605,\n",
      "\t\t\t\"longitude\": 13.402359\n",
      "\t\t},\n",
      "\t\t\"products\": {\n",
      "\t\t\t\"suburban\": true,\n",
      "\t\t\t\"subway\": false,\n",
      "\t\t\t\"tram\": true,\n",
      "\t\t\t\"bus\": true,\n",
      "\t\t\t\"ferry\": false,\n",
      "\t\t\t\"express\": false,\n",
      "\t\t\t\"regional\": false\n",
      "\t\t},\n",
      "\t\t\"stationDHID\": \"de:11000:900100002\",\n",
      "\t\t\"distance\": 679\n",
      "\t},\n",
      "\t{\n",
      "\t\t\"type\": \"stop\",\n",
      "\t\t\"id\": \"900000100004\",\n",
      "\t\t\"name\": \"S+U Jannowitzbrücke\",\n",
      "\t\t\"location\": {\n",
      "\t\t\t\"type\": \"location\",\n",
      "\t\t\t\"id\": \"900100004\",\n",
      "\t\t\t\"latitude\": 52.515503,\n",
      "\t\t\t\"longitude\": 13.418027\n",
      "\t\t},\n",
      "\t\t\"products\": {\n",
      "\t\t\t\"suburban\": true,\n",
      "\t\t\t\"subway\": true,\n",
      "\t\t\t\"tram\": false,\n",
      "\t\t\t\"bus\": true,\n",
      "\t\t\t\"ferry\": false,\n",
      "\t\t\t\"express\": false,\n",
      "\t\t\t\"regional\": false\n",
      "\t\t},\n",
      "\t\t\"stationDHID\": \"de:11000:900100004\",\n",
      "\t\t\"distance\": 708\n",
      "\t},\n",
      "\t{\n",
      "\t\t\"type\": \"stop\",\n",
      "\t\t\"id\": \"900000100007\",\n",
      "\t\t\"name\": \"S Oranienburger Str.\",\n",
      "\t\t\"location\": {\n",
      "\t\t\t\"type\": \"location\",\n",
      "\t\t\t\"id\": \"900100007\",\n",
      "\t\t\t\"latitude\": 52.525158,\n",
      "\t\t\t\"longitude\": 13.393064\n",
      "\t\t},\n",
      "\t\t\"products\": {\n",
      "\t\t\t\"suburban\": true,\n",
      "\t\t\t\"subway\": false,\n",
      "\t\t\t\"tram\": true,\n",
      "\t\t\t\"bus\": true,\n",
      "\t\t\t\"ferry\": false,\n",
      "\t\t\t\"express\": false,\n",
      "\t\t\t\"regional\": false\n",
      "\t\t},\n",
      "\t\t\"stationDHID\": \"de:11000:900100007\",\n",
      "\t\t\"distance\": 1368\n",
      "\t},\n",
      "\t{\n",
      "\t\t\"type\": \"stop\",\n",
      "\t\t\"id\": \"900000100001\",\n",
      "\t\t\"name\": \"S+U Friedrichstr.\",\n",
      "\t\t\"location\": {\n",
      "\t\t\t\"type\": \"location\",\n",
      "\t\t\t\"id\": \"900100001\",\n",
      "\t\t\t\"latitude\": 52.520519,\n",
      "\t\t\t\"longitude\": 13.386448\n",
      "\t\t},\n",
      "\t\t\"products\": {\n",
      "\t\t\t\"suburban\": true,\n",
      "\t\t\t\"subway\": true,\n",
      "\t\t\t\"tram\": true,\n",
      "\t\t\t\"bus\": true,\n",
      "\t\t\t\"ferry\": false,\n",
      "\t\t\t\"express\": false,\n",
      "\t\t\t\"regional\": true\n",
      "\t\t},\n",
      "\t\t\"stationDHID\": \"de:11000:900100001\",\n",
      "\t\t\"distance\": 1721\n",
      "\t},\n",
      "\t{\n",
      "\t\t\"type\": \"stop\",\n",
      "\t\t\"id\": \"900000120005\",\n",
      "\t\t\"name\": \"S Ostbahnhof\",\n",
      "\t\t\"location\": {\n",
      "\t\t\t\"type\": \"location\",\n",
      "\t\t\t\"id\": \"900120005\",\n",
      "\t\t\t\"latitude\": 52.510335,\n",
      "\t\t\t\"longitude\": 13.435089\n",
      "\t\t},\n",
      "\t\t\"products\": {\n",
      "\t\t\t\"suburban\": true,\n",
      "\t\t\t\"subway\": false,\n",
      "\t\t\t\"tram\": false,\n",
      "\t\t\t\"bus\": true,\n",
      "\t\t\t\"ferry\": false,\n",
      "\t\t\t\"express\": true,\n",
      "\t\t\t\"regional\": true\n",
      "\t\t},\n",
      "\t\t\"stationDHID\": \"de:11000:900120005\",\n",
      "\t\t\"distance\": 1945\n",
      "\t}\n",
      "]\n"
     ]
    }
   ],
   "source": [
    "import json\n",
    "url = 'https://v5.bvg.transport.rest/stops/nearby?latitude=52.520658&longitude=13.411875&results=20'\n",
    "html = urllib.request.urlopen(url).read()\n",
    "x= json.loads(html) #make json from html\n",
    "print(len(x))\n",
    "print(html.decode())\n"
   ]
  },
  {
   "cell_type": "code",
   "execution_count": null,
   "metadata": {},
   "outputs": [
    {
     "name": "stderr",
     "output_type": "stream",
     "text": [
      "Error while getting Updates: Conflict: terminated by other getUpdates request; make sure that only one bot instance is running\n",
      "No error handlers are registered, logging exception.\n",
      "Traceback (most recent call last):\n",
      "  File \"C:\\Users\\alexb\\AppData\\Local\\Packages\\PythonSoftwareFoundation.Python.3.8_qbz5n2kfra8p0\\LocalCache\\local-packages\\Python38\\site-packages\\telegram\\ext\\updater.py\", line 646, in _network_loop_retry\n",
      "    if not action_cb():\n",
      "  File \"C:\\Users\\alexb\\AppData\\Local\\Packages\\PythonSoftwareFoundation.Python.3.8_qbz5n2kfra8p0\\LocalCache\\local-packages\\Python38\\site-packages\\telegram\\ext\\updater.py\", line 597, in polling_action_cb\n",
      "    updates = self.bot.get_updates(\n",
      "  File \"C:\\Users\\alexb\\AppData\\Local\\Packages\\PythonSoftwareFoundation.Python.3.8_qbz5n2kfra8p0\\LocalCache\\local-packages\\Python38\\site-packages\\telegram\\ext\\extbot.py\", line 222, in get_updates\n",
      "    updates = super().get_updates(\n",
      "  File \"C:\\Users\\alexb\\AppData\\Local\\Packages\\PythonSoftwareFoundation.Python.3.8_qbz5n2kfra8p0\\LocalCache\\local-packages\\Python38\\site-packages\\telegram\\bot.py\", line 130, in decorator\n",
      "    result = func(*args, **kwargs)\n",
      "  File \"C:\\Users\\alexb\\AppData\\Local\\Packages\\PythonSoftwareFoundation.Python.3.8_qbz5n2kfra8p0\\LocalCache\\local-packages\\Python38\\site-packages\\telegram\\bot.py\", line 2861, in get_updates\n",
      "    self._post(\n",
      "  File \"C:\\Users\\alexb\\AppData\\Local\\Packages\\PythonSoftwareFoundation.Python.3.8_qbz5n2kfra8p0\\LocalCache\\local-packages\\Python38\\site-packages\\telegram\\bot.py\", line 295, in _post\n",
      "    return self.request.post(\n",
      "  File \"C:\\Users\\alexb\\AppData\\Local\\Packages\\PythonSoftwareFoundation.Python.3.8_qbz5n2kfra8p0\\LocalCache\\local-packages\\Python38\\site-packages\\telegram\\utils\\request.py\", line 356, in post\n",
      "    result = self._request_wrapper(\n",
      "  File \"C:\\Users\\alexb\\AppData\\Local\\Packages\\PythonSoftwareFoundation.Python.3.8_qbz5n2kfra8p0\\LocalCache\\local-packages\\Python38\\site-packages\\telegram\\utils\\request.py\", line 283, in _request_wrapper\n",
      "    raise Conflict(message)\n",
      "telegram.error.Conflict: Conflict: terminated by other getUpdates request; make sure that only one bot instance is running\n",
      "Error while getting Updates: Conflict: terminated by other getUpdates request; make sure that only one bot instance is running\n",
      "No error handlers are registered, logging exception.\n",
      "Traceback (most recent call last):\n",
      "  File \"C:\\Users\\alexb\\AppData\\Local\\Packages\\PythonSoftwareFoundation.Python.3.8_qbz5n2kfra8p0\\LocalCache\\local-packages\\Python38\\site-packages\\telegram\\ext\\updater.py\", line 646, in _network_loop_retry\n",
      "    if not action_cb():\n",
      "  File \"C:\\Users\\alexb\\AppData\\Local\\Packages\\PythonSoftwareFoundation.Python.3.8_qbz5n2kfra8p0\\LocalCache\\local-packages\\Python38\\site-packages\\telegram\\ext\\updater.py\", line 597, in polling_action_cb\n",
      "    updates = self.bot.get_updates(\n",
      "  File \"C:\\Users\\alexb\\AppData\\Local\\Packages\\PythonSoftwareFoundation.Python.3.8_qbz5n2kfra8p0\\LocalCache\\local-packages\\Python38\\site-packages\\telegram\\ext\\extbot.py\", line 222, in get_updates\n",
      "    updates = super().get_updates(\n",
      "  File \"C:\\Users\\alexb\\AppData\\Local\\Packages\\PythonSoftwareFoundation.Python.3.8_qbz5n2kfra8p0\\LocalCache\\local-packages\\Python38\\site-packages\\telegram\\bot.py\", line 130, in decorator\n",
      "    result = func(*args, **kwargs)\n",
      "  File \"C:\\Users\\alexb\\AppData\\Local\\Packages\\PythonSoftwareFoundation.Python.3.8_qbz5n2kfra8p0\\LocalCache\\local-packages\\Python38\\site-packages\\telegram\\bot.py\", line 2861, in get_updates\n",
      "    self._post(\n",
      "  File \"C:\\Users\\alexb\\AppData\\Local\\Packages\\PythonSoftwareFoundation.Python.3.8_qbz5n2kfra8p0\\LocalCache\\local-packages\\Python38\\site-packages\\telegram\\bot.py\", line 295, in _post\n",
      "    return self.request.post(\n",
      "  File \"C:\\Users\\alexb\\AppData\\Local\\Packages\\PythonSoftwareFoundation.Python.3.8_qbz5n2kfra8p0\\LocalCache\\local-packages\\Python38\\site-packages\\telegram\\utils\\request.py\", line 356, in post\n",
      "    result = self._request_wrapper(\n",
      "  File \"C:\\Users\\alexb\\AppData\\Local\\Packages\\PythonSoftwareFoundation.Python.3.8_qbz5n2kfra8p0\\LocalCache\\local-packages\\Python38\\site-packages\\telegram\\utils\\request.py\", line 283, in _request_wrapper\n",
      "    raise Conflict(message)\n",
      "telegram.error.Conflict: Conflict: terminated by other getUpdates request; make sure that only one bot instance is running\n",
      "Error while getting Updates: Conflict: terminated by other getUpdates request; make sure that only one bot instance is running\n",
      "No error handlers are registered, logging exception.\n",
      "Traceback (most recent call last):\n",
      "  File \"C:\\Users\\alexb\\AppData\\Local\\Packages\\PythonSoftwareFoundation.Python.3.8_qbz5n2kfra8p0\\LocalCache\\local-packages\\Python38\\site-packages\\telegram\\ext\\updater.py\", line 646, in _network_loop_retry\n",
      "    if not action_cb():\n",
      "  File \"C:\\Users\\alexb\\AppData\\Local\\Packages\\PythonSoftwareFoundation.Python.3.8_qbz5n2kfra8p0\\LocalCache\\local-packages\\Python38\\site-packages\\telegram\\ext\\updater.py\", line 597, in polling_action_cb\n",
      "    updates = self.bot.get_updates(\n",
      "  File \"C:\\Users\\alexb\\AppData\\Local\\Packages\\PythonSoftwareFoundation.Python.3.8_qbz5n2kfra8p0\\LocalCache\\local-packages\\Python38\\site-packages\\telegram\\ext\\extbot.py\", line 222, in get_updates\n",
      "    updates = super().get_updates(\n",
      "  File \"C:\\Users\\alexb\\AppData\\Local\\Packages\\PythonSoftwareFoundation.Python.3.8_qbz5n2kfra8p0\\LocalCache\\local-packages\\Python38\\site-packages\\telegram\\bot.py\", line 130, in decorator\n",
      "    result = func(*args, **kwargs)\n",
      "  File \"C:\\Users\\alexb\\AppData\\Local\\Packages\\PythonSoftwareFoundation.Python.3.8_qbz5n2kfra8p0\\LocalCache\\local-packages\\Python38\\site-packages\\telegram\\bot.py\", line 2861, in get_updates\n",
      "    self._post(\n",
      "  File \"C:\\Users\\alexb\\AppData\\Local\\Packages\\PythonSoftwareFoundation.Python.3.8_qbz5n2kfra8p0\\LocalCache\\local-packages\\Python38\\site-packages\\telegram\\bot.py\", line 295, in _post\n",
      "    return self.request.post(\n",
      "  File \"C:\\Users\\alexb\\AppData\\Local\\Packages\\PythonSoftwareFoundation.Python.3.8_qbz5n2kfra8p0\\LocalCache\\local-packages\\Python38\\site-packages\\telegram\\utils\\request.py\", line 356, in post\n",
      "    result = self._request_wrapper(\n",
      "  File \"C:\\Users\\alexb\\AppData\\Local\\Packages\\PythonSoftwareFoundation.Python.3.8_qbz5n2kfra8p0\\LocalCache\\local-packages\\Python38\\site-packages\\telegram\\utils\\request.py\", line 283, in _request_wrapper\n",
      "    raise Conflict(message)\n",
      "telegram.error.Conflict: Conflict: terminated by other getUpdates request; make sure that only one bot instance is running\n",
      "Error while getting Updates: Conflict: terminated by other getUpdates request; make sure that only one bot instance is running\n",
      "No error handlers are registered, logging exception.\n",
      "Traceback (most recent call last):\n",
      "  File \"C:\\Users\\alexb\\AppData\\Local\\Packages\\PythonSoftwareFoundation.Python.3.8_qbz5n2kfra8p0\\LocalCache\\local-packages\\Python38\\site-packages\\telegram\\ext\\updater.py\", line 646, in _network_loop_retry\n",
      "    if not action_cb():\n",
      "  File \"C:\\Users\\alexb\\AppData\\Local\\Packages\\PythonSoftwareFoundation.Python.3.8_qbz5n2kfra8p0\\LocalCache\\local-packages\\Python38\\site-packages\\telegram\\ext\\updater.py\", line 597, in polling_action_cb\n",
      "    updates = self.bot.get_updates(\n",
      "  File \"C:\\Users\\alexb\\AppData\\Local\\Packages\\PythonSoftwareFoundation.Python.3.8_qbz5n2kfra8p0\\LocalCache\\local-packages\\Python38\\site-packages\\telegram\\ext\\extbot.py\", line 222, in get_updates\n",
      "    updates = super().get_updates(\n",
      "  File \"C:\\Users\\alexb\\AppData\\Local\\Packages\\PythonSoftwareFoundation.Python.3.8_qbz5n2kfra8p0\\LocalCache\\local-packages\\Python38\\site-packages\\telegram\\bot.py\", line 130, in decorator\n",
      "    result = func(*args, **kwargs)\n",
      "  File \"C:\\Users\\alexb\\AppData\\Local\\Packages\\PythonSoftwareFoundation.Python.3.8_qbz5n2kfra8p0\\LocalCache\\local-packages\\Python38\\site-packages\\telegram\\bot.py\", line 2861, in get_updates\n",
      "    self._post(\n",
      "  File \"C:\\Users\\alexb\\AppData\\Local\\Packages\\PythonSoftwareFoundation.Python.3.8_qbz5n2kfra8p0\\LocalCache\\local-packages\\Python38\\site-packages\\telegram\\bot.py\", line 295, in _post\n",
      "    return self.request.post(\n",
      "  File \"C:\\Users\\alexb\\AppData\\Local\\Packages\\PythonSoftwareFoundation.Python.3.8_qbz5n2kfra8p0\\LocalCache\\local-packages\\Python38\\site-packages\\telegram\\utils\\request.py\", line 356, in post\n",
      "    result = self._request_wrapper(\n",
      "  File \"C:\\Users\\alexb\\AppData\\Local\\Packages\\PythonSoftwareFoundation.Python.3.8_qbz5n2kfra8p0\\LocalCache\\local-packages\\Python38\\site-packages\\telegram\\utils\\request.py\", line 283, in _request_wrapper\n",
      "    raise Conflict(message)\n",
      "telegram.error.Conflict: Conflict: terminated by other getUpdates request; make sure that only one bot instance is running\n",
      "Error while getting Updates: Conflict: terminated by other getUpdates request; make sure that only one bot instance is running\n",
      "No error handlers are registered, logging exception.\n",
      "Traceback (most recent call last):\n",
      "  File \"C:\\Users\\alexb\\AppData\\Local\\Packages\\PythonSoftwareFoundation.Python.3.8_qbz5n2kfra8p0\\LocalCache\\local-packages\\Python38\\site-packages\\telegram\\ext\\updater.py\", line 646, in _network_loop_retry\n",
      "    if not action_cb():\n",
      "  File \"C:\\Users\\alexb\\AppData\\Local\\Packages\\PythonSoftwareFoundation.Python.3.8_qbz5n2kfra8p0\\LocalCache\\local-packages\\Python38\\site-packages\\telegram\\ext\\updater.py\", line 597, in polling_action_cb\n",
      "    updates = self.bot.get_updates(\n",
      "  File \"C:\\Users\\alexb\\AppData\\Local\\Packages\\PythonSoftwareFoundation.Python.3.8_qbz5n2kfra8p0\\LocalCache\\local-packages\\Python38\\site-packages\\telegram\\ext\\extbot.py\", line 222, in get_updates\n",
      "    updates = super().get_updates(\n",
      "  File \"C:\\Users\\alexb\\AppData\\Local\\Packages\\PythonSoftwareFoundation.Python.3.8_qbz5n2kfra8p0\\LocalCache\\local-packages\\Python38\\site-packages\\telegram\\bot.py\", line 130, in decorator\n",
      "    result = func(*args, **kwargs)\n",
      "  File \"C:\\Users\\alexb\\AppData\\Local\\Packages\\PythonSoftwareFoundation.Python.3.8_qbz5n2kfra8p0\\LocalCache\\local-packages\\Python38\\site-packages\\telegram\\bot.py\", line 2861, in get_updates\n",
      "    self._post(\n",
      "  File \"C:\\Users\\alexb\\AppData\\Local\\Packages\\PythonSoftwareFoundation.Python.3.8_qbz5n2kfra8p0\\LocalCache\\local-packages\\Python38\\site-packages\\telegram\\bot.py\", line 295, in _post\n",
      "    return self.request.post(\n",
      "  File \"C:\\Users\\alexb\\AppData\\Local\\Packages\\PythonSoftwareFoundation.Python.3.8_qbz5n2kfra8p0\\LocalCache\\local-packages\\Python38\\site-packages\\telegram\\utils\\request.py\", line 356, in post\n",
      "    result = self._request_wrapper(\n",
      "  File \"C:\\Users\\alexb\\AppData\\Local\\Packages\\PythonSoftwareFoundation.Python.3.8_qbz5n2kfra8p0\\LocalCache\\local-packages\\Python38\\site-packages\\telegram\\utils\\request.py\", line 283, in _request_wrapper\n",
      "    raise Conflict(message)\n",
      "telegram.error.Conflict: Conflict: terminated by other getUpdates request; make sure that only one bot instance is running\n",
      "Error while getting Updates: Conflict: terminated by other getUpdates request; make sure that only one bot instance is running\n",
      "No error handlers are registered, logging exception.\n",
      "Traceback (most recent call last):\n",
      "  File \"C:\\Users\\alexb\\AppData\\Local\\Packages\\PythonSoftwareFoundation.Python.3.8_qbz5n2kfra8p0\\LocalCache\\local-packages\\Python38\\site-packages\\telegram\\ext\\updater.py\", line 646, in _network_loop_retry\n",
      "    if not action_cb():\n",
      "  File \"C:\\Users\\alexb\\AppData\\Local\\Packages\\PythonSoftwareFoundation.Python.3.8_qbz5n2kfra8p0\\LocalCache\\local-packages\\Python38\\site-packages\\telegram\\ext\\updater.py\", line 597, in polling_action_cb\n",
      "    updates = self.bot.get_updates(\n",
      "  File \"C:\\Users\\alexb\\AppData\\Local\\Packages\\PythonSoftwareFoundation.Python.3.8_qbz5n2kfra8p0\\LocalCache\\local-packages\\Python38\\site-packages\\telegram\\ext\\extbot.py\", line 222, in get_updates\n",
      "    updates = super().get_updates(\n",
      "  File \"C:\\Users\\alexb\\AppData\\Local\\Packages\\PythonSoftwareFoundation.Python.3.8_qbz5n2kfra8p0\\LocalCache\\local-packages\\Python38\\site-packages\\telegram\\bot.py\", line 130, in decorator\n",
      "    result = func(*args, **kwargs)\n",
      "  File \"C:\\Users\\alexb\\AppData\\Local\\Packages\\PythonSoftwareFoundation.Python.3.8_qbz5n2kfra8p0\\LocalCache\\local-packages\\Python38\\site-packages\\telegram\\bot.py\", line 2861, in get_updates\n",
      "    self._post(\n",
      "  File \"C:\\Users\\alexb\\AppData\\Local\\Packages\\PythonSoftwareFoundation.Python.3.8_qbz5n2kfra8p0\\LocalCache\\local-packages\\Python38\\site-packages\\telegram\\bot.py\", line 295, in _post\n",
      "    return self.request.post(\n",
      "  File \"C:\\Users\\alexb\\AppData\\Local\\Packages\\PythonSoftwareFoundation.Python.3.8_qbz5n2kfra8p0\\LocalCache\\local-packages\\Python38\\site-packages\\telegram\\utils\\request.py\", line 356, in post\n",
      "    result = self._request_wrapper(\n",
      "  File \"C:\\Users\\alexb\\AppData\\Local\\Packages\\PythonSoftwareFoundation.Python.3.8_qbz5n2kfra8p0\\LocalCache\\local-packages\\Python38\\site-packages\\telegram\\utils\\request.py\", line 283, in _request_wrapper\n",
      "    raise Conflict(message)\n",
      "telegram.error.Conflict: Conflict: terminated by other getUpdates request; make sure that only one bot instance is running\n",
      "Error while getting Updates: Conflict: terminated by other getUpdates request; make sure that only one bot instance is running\n",
      "No error handlers are registered, logging exception.\n",
      "Traceback (most recent call last):\n",
      "  File \"C:\\Users\\alexb\\AppData\\Local\\Packages\\PythonSoftwareFoundation.Python.3.8_qbz5n2kfra8p0\\LocalCache\\local-packages\\Python38\\site-packages\\telegram\\ext\\updater.py\", line 646, in _network_loop_retry\n",
      "    if not action_cb():\n",
      "  File \"C:\\Users\\alexb\\AppData\\Local\\Packages\\PythonSoftwareFoundation.Python.3.8_qbz5n2kfra8p0\\LocalCache\\local-packages\\Python38\\site-packages\\telegram\\ext\\updater.py\", line 597, in polling_action_cb\n",
      "    updates = self.bot.get_updates(\n",
      "  File \"C:\\Users\\alexb\\AppData\\Local\\Packages\\PythonSoftwareFoundation.Python.3.8_qbz5n2kfra8p0\\LocalCache\\local-packages\\Python38\\site-packages\\telegram\\ext\\extbot.py\", line 222, in get_updates\n",
      "    updates = super().get_updates(\n",
      "  File \"C:\\Users\\alexb\\AppData\\Local\\Packages\\PythonSoftwareFoundation.Python.3.8_qbz5n2kfra8p0\\LocalCache\\local-packages\\Python38\\site-packages\\telegram\\bot.py\", line 130, in decorator\n",
      "    result = func(*args, **kwargs)\n",
      "  File \"C:\\Users\\alexb\\AppData\\Local\\Packages\\PythonSoftwareFoundation.Python.3.8_qbz5n2kfra8p0\\LocalCache\\local-packages\\Python38\\site-packages\\telegram\\bot.py\", line 2861, in get_updates\n",
      "    self._post(\n",
      "  File \"C:\\Users\\alexb\\AppData\\Local\\Packages\\PythonSoftwareFoundation.Python.3.8_qbz5n2kfra8p0\\LocalCache\\local-packages\\Python38\\site-packages\\telegram\\bot.py\", line 295, in _post\n",
      "    return self.request.post(\n",
      "  File \"C:\\Users\\alexb\\AppData\\Local\\Packages\\PythonSoftwareFoundation.Python.3.8_qbz5n2kfra8p0\\LocalCache\\local-packages\\Python38\\site-packages\\telegram\\utils\\request.py\", line 356, in post\n",
      "    result = self._request_wrapper(\n",
      "  File \"C:\\Users\\alexb\\AppData\\Local\\Packages\\PythonSoftwareFoundation.Python.3.8_qbz5n2kfra8p0\\LocalCache\\local-packages\\Python38\\site-packages\\telegram\\utils\\request.py\", line 283, in _request_wrapper\n",
      "    raise Conflict(message)\n",
      "telegram.error.Conflict: Conflict: terminated by other getUpdates request; make sure that only one bot instance is running\n",
      "Error while getting Updates: Conflict: terminated by other getUpdates request; make sure that only one bot instance is running\n",
      "No error handlers are registered, logging exception.\n",
      "Traceback (most recent call last):\n",
      "  File \"C:\\Users\\alexb\\AppData\\Local\\Packages\\PythonSoftwareFoundation.Python.3.8_qbz5n2kfra8p0\\LocalCache\\local-packages\\Python38\\site-packages\\telegram\\ext\\updater.py\", line 646, in _network_loop_retry\n",
      "    if not action_cb():\n",
      "  File \"C:\\Users\\alexb\\AppData\\Local\\Packages\\PythonSoftwareFoundation.Python.3.8_qbz5n2kfra8p0\\LocalCache\\local-packages\\Python38\\site-packages\\telegram\\ext\\updater.py\", line 597, in polling_action_cb\n",
      "    updates = self.bot.get_updates(\n",
      "  File \"C:\\Users\\alexb\\AppData\\Local\\Packages\\PythonSoftwareFoundation.Python.3.8_qbz5n2kfra8p0\\LocalCache\\local-packages\\Python38\\site-packages\\telegram\\ext\\extbot.py\", line 222, in get_updates\n",
      "    updates = super().get_updates(\n",
      "  File \"C:\\Users\\alexb\\AppData\\Local\\Packages\\PythonSoftwareFoundation.Python.3.8_qbz5n2kfra8p0\\LocalCache\\local-packages\\Python38\\site-packages\\telegram\\bot.py\", line 130, in decorator\n",
      "    result = func(*args, **kwargs)\n",
      "  File \"C:\\Users\\alexb\\AppData\\Local\\Packages\\PythonSoftwareFoundation.Python.3.8_qbz5n2kfra8p0\\LocalCache\\local-packages\\Python38\\site-packages\\telegram\\bot.py\", line 2861, in get_updates\n",
      "    self._post(\n",
      "  File \"C:\\Users\\alexb\\AppData\\Local\\Packages\\PythonSoftwareFoundation.Python.3.8_qbz5n2kfra8p0\\LocalCache\\local-packages\\Python38\\site-packages\\telegram\\bot.py\", line 295, in _post\n",
      "    return self.request.post(\n",
      "  File \"C:\\Users\\alexb\\AppData\\Local\\Packages\\PythonSoftwareFoundation.Python.3.8_qbz5n2kfra8p0\\LocalCache\\local-packages\\Python38\\site-packages\\telegram\\utils\\request.py\", line 356, in post\n",
      "    result = self._request_wrapper(\n",
      "  File \"C:\\Users\\alexb\\AppData\\Local\\Packages\\PythonSoftwareFoundation.Python.3.8_qbz5n2kfra8p0\\LocalCache\\local-packages\\Python38\\site-packages\\telegram\\utils\\request.py\", line 283, in _request_wrapper\n",
      "    raise Conflict(message)\n",
      "telegram.error.Conflict: Conflict: terminated by other getUpdates request; make sure that only one bot instance is running\n",
      "Error while getting Updates: Conflict: terminated by other getUpdates request; make sure that only one bot instance is running\n",
      "No error handlers are registered, logging exception.\n",
      "Traceback (most recent call last):\n",
      "  File \"C:\\Users\\alexb\\AppData\\Local\\Packages\\PythonSoftwareFoundation.Python.3.8_qbz5n2kfra8p0\\LocalCache\\local-packages\\Python38\\site-packages\\telegram\\ext\\updater.py\", line 646, in _network_loop_retry\n",
      "    if not action_cb():\n",
      "  File \"C:\\Users\\alexb\\AppData\\Local\\Packages\\PythonSoftwareFoundation.Python.3.8_qbz5n2kfra8p0\\LocalCache\\local-packages\\Python38\\site-packages\\telegram\\ext\\updater.py\", line 597, in polling_action_cb\n",
      "    updates = self.bot.get_updates(\n",
      "  File \"C:\\Users\\alexb\\AppData\\Local\\Packages\\PythonSoftwareFoundation.Python.3.8_qbz5n2kfra8p0\\LocalCache\\local-packages\\Python38\\site-packages\\telegram\\ext\\extbot.py\", line 222, in get_updates\n",
      "    updates = super().get_updates(\n",
      "  File \"C:\\Users\\alexb\\AppData\\Local\\Packages\\PythonSoftwareFoundation.Python.3.8_qbz5n2kfra8p0\\LocalCache\\local-packages\\Python38\\site-packages\\telegram\\bot.py\", line 130, in decorator\n",
      "    result = func(*args, **kwargs)\n",
      "  File \"C:\\Users\\alexb\\AppData\\Local\\Packages\\PythonSoftwareFoundation.Python.3.8_qbz5n2kfra8p0\\LocalCache\\local-packages\\Python38\\site-packages\\telegram\\bot.py\", line 2861, in get_updates\n",
      "    self._post(\n",
      "  File \"C:\\Users\\alexb\\AppData\\Local\\Packages\\PythonSoftwareFoundation.Python.3.8_qbz5n2kfra8p0\\LocalCache\\local-packages\\Python38\\site-packages\\telegram\\bot.py\", line 295, in _post\n",
      "    return self.request.post(\n",
      "  File \"C:\\Users\\alexb\\AppData\\Local\\Packages\\PythonSoftwareFoundation.Python.3.8_qbz5n2kfra8p0\\LocalCache\\local-packages\\Python38\\site-packages\\telegram\\utils\\request.py\", line 356, in post\n",
      "    result = self._request_wrapper(\n",
      "  File \"C:\\Users\\alexb\\AppData\\Local\\Packages\\PythonSoftwareFoundation.Python.3.8_qbz5n2kfra8p0\\LocalCache\\local-packages\\Python38\\site-packages\\telegram\\utils\\request.py\", line 283, in _request_wrapper\n",
      "    raise Conflict(message)\n",
      "telegram.error.Conflict: Conflict: terminated by other getUpdates request; make sure that only one bot instance is running\n",
      "Error while getting Updates: Conflict: terminated by other getUpdates request; make sure that only one bot instance is running\n",
      "No error handlers are registered, logging exception.\n",
      "Traceback (most recent call last):\n",
      "  File \"C:\\Users\\alexb\\AppData\\Local\\Packages\\PythonSoftwareFoundation.Python.3.8_qbz5n2kfra8p0\\LocalCache\\local-packages\\Python38\\site-packages\\telegram\\ext\\updater.py\", line 646, in _network_loop_retry\n",
      "    if not action_cb():\n",
      "  File \"C:\\Users\\alexb\\AppData\\Local\\Packages\\PythonSoftwareFoundation.Python.3.8_qbz5n2kfra8p0\\LocalCache\\local-packages\\Python38\\site-packages\\telegram\\ext\\updater.py\", line 597, in polling_action_cb\n",
      "    updates = self.bot.get_updates(\n",
      "  File \"C:\\Users\\alexb\\AppData\\Local\\Packages\\PythonSoftwareFoundation.Python.3.8_qbz5n2kfra8p0\\LocalCache\\local-packages\\Python38\\site-packages\\telegram\\ext\\extbot.py\", line 222, in get_updates\n",
      "    updates = super().get_updates(\n",
      "  File \"C:\\Users\\alexb\\AppData\\Local\\Packages\\PythonSoftwareFoundation.Python.3.8_qbz5n2kfra8p0\\LocalCache\\local-packages\\Python38\\site-packages\\telegram\\bot.py\", line 130, in decorator\n",
      "    result = func(*args, **kwargs)\n",
      "  File \"C:\\Users\\alexb\\AppData\\Local\\Packages\\PythonSoftwareFoundation.Python.3.8_qbz5n2kfra8p0\\LocalCache\\local-packages\\Python38\\site-packages\\telegram\\bot.py\", line 2861, in get_updates\n",
      "    self._post(\n",
      "  File \"C:\\Users\\alexb\\AppData\\Local\\Packages\\PythonSoftwareFoundation.Python.3.8_qbz5n2kfra8p0\\LocalCache\\local-packages\\Python38\\site-packages\\telegram\\bot.py\", line 295, in _post\n",
      "    return self.request.post(\n",
      "  File \"C:\\Users\\alexb\\AppData\\Local\\Packages\\PythonSoftwareFoundation.Python.3.8_qbz5n2kfra8p0\\LocalCache\\local-packages\\Python38\\site-packages\\telegram\\utils\\request.py\", line 356, in post\n",
      "    result = self._request_wrapper(\n",
      "  File \"C:\\Users\\alexb\\AppData\\Local\\Packages\\PythonSoftwareFoundation.Python.3.8_qbz5n2kfra8p0\\LocalCache\\local-packages\\Python38\\site-packages\\telegram\\utils\\request.py\", line 283, in _request_wrapper\n",
      "    raise Conflict(message)\n",
      "telegram.error.Conflict: Conflict: terminated by other getUpdates request; make sure that only one bot instance is running\n",
      "Error while getting Updates: Conflict: terminated by other getUpdates request; make sure that only one bot instance is running\n",
      "No error handlers are registered, logging exception.\n",
      "Traceback (most recent call last):\n",
      "  File \"C:\\Users\\alexb\\AppData\\Local\\Packages\\PythonSoftwareFoundation.Python.3.8_qbz5n2kfra8p0\\LocalCache\\local-packages\\Python38\\site-packages\\telegram\\ext\\updater.py\", line 646, in _network_loop_retry\n",
      "    if not action_cb():\n",
      "  File \"C:\\Users\\alexb\\AppData\\Local\\Packages\\PythonSoftwareFoundation.Python.3.8_qbz5n2kfra8p0\\LocalCache\\local-packages\\Python38\\site-packages\\telegram\\ext\\updater.py\", line 597, in polling_action_cb\n",
      "    updates = self.bot.get_updates(\n",
      "  File \"C:\\Users\\alexb\\AppData\\Local\\Packages\\PythonSoftwareFoundation.Python.3.8_qbz5n2kfra8p0\\LocalCache\\local-packages\\Python38\\site-packages\\telegram\\ext\\extbot.py\", line 222, in get_updates\n",
      "    updates = super().get_updates(\n",
      "  File \"C:\\Users\\alexb\\AppData\\Local\\Packages\\PythonSoftwareFoundation.Python.3.8_qbz5n2kfra8p0\\LocalCache\\local-packages\\Python38\\site-packages\\telegram\\bot.py\", line 130, in decorator\n",
      "    result = func(*args, **kwargs)\n",
      "  File \"C:\\Users\\alexb\\AppData\\Local\\Packages\\PythonSoftwareFoundation.Python.3.8_qbz5n2kfra8p0\\LocalCache\\local-packages\\Python38\\site-packages\\telegram\\bot.py\", line 2861, in get_updates\n",
      "    self._post(\n",
      "  File \"C:\\Users\\alexb\\AppData\\Local\\Packages\\PythonSoftwareFoundation.Python.3.8_qbz5n2kfra8p0\\LocalCache\\local-packages\\Python38\\site-packages\\telegram\\bot.py\", line 295, in _post\n",
      "    return self.request.post(\n",
      "  File \"C:\\Users\\alexb\\AppData\\Local\\Packages\\PythonSoftwareFoundation.Python.3.8_qbz5n2kfra8p0\\LocalCache\\local-packages\\Python38\\site-packages\\telegram\\utils\\request.py\", line 356, in post\n",
      "    result = self._request_wrapper(\n",
      "  File \"C:\\Users\\alexb\\AppData\\Local\\Packages\\PythonSoftwareFoundation.Python.3.8_qbz5n2kfra8p0\\LocalCache\\local-packages\\Python38\\site-packages\\telegram\\utils\\request.py\", line 283, in _request_wrapper\n",
      "    raise Conflict(message)\n",
      "telegram.error.Conflict: Conflict: terminated by other getUpdates request; make sure that only one bot instance is running\n",
      "Error while getting Updates: Conflict: terminated by other getUpdates request; make sure that only one bot instance is running\n",
      "No error handlers are registered, logging exception.\n",
      "Traceback (most recent call last):\n",
      "  File \"C:\\Users\\alexb\\AppData\\Local\\Packages\\PythonSoftwareFoundation.Python.3.8_qbz5n2kfra8p0\\LocalCache\\local-packages\\Python38\\site-packages\\telegram\\ext\\updater.py\", line 646, in _network_loop_retry\n",
      "    if not action_cb():\n",
      "  File \"C:\\Users\\alexb\\AppData\\Local\\Packages\\PythonSoftwareFoundation.Python.3.8_qbz5n2kfra8p0\\LocalCache\\local-packages\\Python38\\site-packages\\telegram\\ext\\updater.py\", line 597, in polling_action_cb\n",
      "    updates = self.bot.get_updates(\n",
      "  File \"C:\\Users\\alexb\\AppData\\Local\\Packages\\PythonSoftwareFoundation.Python.3.8_qbz5n2kfra8p0\\LocalCache\\local-packages\\Python38\\site-packages\\telegram\\ext\\extbot.py\", line 222, in get_updates\n",
      "    updates = super().get_updates(\n",
      "  File \"C:\\Users\\alexb\\AppData\\Local\\Packages\\PythonSoftwareFoundation.Python.3.8_qbz5n2kfra8p0\\LocalCache\\local-packages\\Python38\\site-packages\\telegram\\bot.py\", line 130, in decorator\n",
      "    result = func(*args, **kwargs)\n",
      "  File \"C:\\Users\\alexb\\AppData\\Local\\Packages\\PythonSoftwareFoundation.Python.3.8_qbz5n2kfra8p0\\LocalCache\\local-packages\\Python38\\site-packages\\telegram\\bot.py\", line 2861, in get_updates\n",
      "    self._post(\n",
      "  File \"C:\\Users\\alexb\\AppData\\Local\\Packages\\PythonSoftwareFoundation.Python.3.8_qbz5n2kfra8p0\\LocalCache\\local-packages\\Python38\\site-packages\\telegram\\bot.py\", line 295, in _post\n",
      "    return self.request.post(\n",
      "  File \"C:\\Users\\alexb\\AppData\\Local\\Packages\\PythonSoftwareFoundation.Python.3.8_qbz5n2kfra8p0\\LocalCache\\local-packages\\Python38\\site-packages\\telegram\\utils\\request.py\", line 356, in post\n",
      "    result = self._request_wrapper(\n",
      "  File \"C:\\Users\\alexb\\AppData\\Local\\Packages\\PythonSoftwareFoundation.Python.3.8_qbz5n2kfra8p0\\LocalCache\\local-packages\\Python38\\site-packages\\telegram\\utils\\request.py\", line 283, in _request_wrapper\n",
      "    raise Conflict(message)\n",
      "telegram.error.Conflict: Conflict: terminated by other getUpdates request; make sure that only one bot instance is running\n",
      "Error while getting Updates: Conflict: terminated by other getUpdates request; make sure that only one bot instance is running\n",
      "No error handlers are registered, logging exception.\n",
      "Traceback (most recent call last):\n",
      "  File \"C:\\Users\\alexb\\AppData\\Local\\Packages\\PythonSoftwareFoundation.Python.3.8_qbz5n2kfra8p0\\LocalCache\\local-packages\\Python38\\site-packages\\telegram\\ext\\updater.py\", line 646, in _network_loop_retry\n",
      "    if not action_cb():\n",
      "  File \"C:\\Users\\alexb\\AppData\\Local\\Packages\\PythonSoftwareFoundation.Python.3.8_qbz5n2kfra8p0\\LocalCache\\local-packages\\Python38\\site-packages\\telegram\\ext\\updater.py\", line 597, in polling_action_cb\n",
      "    updates = self.bot.get_updates(\n",
      "  File \"C:\\Users\\alexb\\AppData\\Local\\Packages\\PythonSoftwareFoundation.Python.3.8_qbz5n2kfra8p0\\LocalCache\\local-packages\\Python38\\site-packages\\telegram\\ext\\extbot.py\", line 222, in get_updates\n",
      "    updates = super().get_updates(\n",
      "  File \"C:\\Users\\alexb\\AppData\\Local\\Packages\\PythonSoftwareFoundation.Python.3.8_qbz5n2kfra8p0\\LocalCache\\local-packages\\Python38\\site-packages\\telegram\\bot.py\", line 130, in decorator\n",
      "    result = func(*args, **kwargs)\n",
      "  File \"C:\\Users\\alexb\\AppData\\Local\\Packages\\PythonSoftwareFoundation.Python.3.8_qbz5n2kfra8p0\\LocalCache\\local-packages\\Python38\\site-packages\\telegram\\bot.py\", line 2861, in get_updates\n",
      "    self._post(\n",
      "  File \"C:\\Users\\alexb\\AppData\\Local\\Packages\\PythonSoftwareFoundation.Python.3.8_qbz5n2kfra8p0\\LocalCache\\local-packages\\Python38\\site-packages\\telegram\\bot.py\", line 295, in _post\n",
      "    return self.request.post(\n",
      "  File \"C:\\Users\\alexb\\AppData\\Local\\Packages\\PythonSoftwareFoundation.Python.3.8_qbz5n2kfra8p0\\LocalCache\\local-packages\\Python38\\site-packages\\telegram\\utils\\request.py\", line 356, in post\n",
      "    result = self._request_wrapper(\n",
      "  File \"C:\\Users\\alexb\\AppData\\Local\\Packages\\PythonSoftwareFoundation.Python.3.8_qbz5n2kfra8p0\\LocalCache\\local-packages\\Python38\\site-packages\\telegram\\utils\\request.py\", line 283, in _request_wrapper\n",
      "    raise Conflict(message)\n",
      "telegram.error.Conflict: Conflict: terminated by other getUpdates request; make sure that only one bot instance is running\n",
      "Error while getting Updates: Conflict: terminated by other getUpdates request; make sure that only one bot instance is running\n",
      "No error handlers are registered, logging exception.\n",
      "Traceback (most recent call last):\n",
      "  File \"C:\\Users\\alexb\\AppData\\Local\\Packages\\PythonSoftwareFoundation.Python.3.8_qbz5n2kfra8p0\\LocalCache\\local-packages\\Python38\\site-packages\\telegram\\ext\\updater.py\", line 646, in _network_loop_retry\n",
      "    if not action_cb():\n",
      "  File \"C:\\Users\\alexb\\AppData\\Local\\Packages\\PythonSoftwareFoundation.Python.3.8_qbz5n2kfra8p0\\LocalCache\\local-packages\\Python38\\site-packages\\telegram\\ext\\updater.py\", line 597, in polling_action_cb\n",
      "    updates = self.bot.get_updates(\n",
      "  File \"C:\\Users\\alexb\\AppData\\Local\\Packages\\PythonSoftwareFoundation.Python.3.8_qbz5n2kfra8p0\\LocalCache\\local-packages\\Python38\\site-packages\\telegram\\ext\\extbot.py\", line 222, in get_updates\n",
      "    updates = super().get_updates(\n",
      "  File \"C:\\Users\\alexb\\AppData\\Local\\Packages\\PythonSoftwareFoundation.Python.3.8_qbz5n2kfra8p0\\LocalCache\\local-packages\\Python38\\site-packages\\telegram\\bot.py\", line 130, in decorator\n",
      "    result = func(*args, **kwargs)\n",
      "  File \"C:\\Users\\alexb\\AppData\\Local\\Packages\\PythonSoftwareFoundation.Python.3.8_qbz5n2kfra8p0\\LocalCache\\local-packages\\Python38\\site-packages\\telegram\\bot.py\", line 2861, in get_updates\n",
      "    self._post(\n",
      "  File \"C:\\Users\\alexb\\AppData\\Local\\Packages\\PythonSoftwareFoundation.Python.3.8_qbz5n2kfra8p0\\LocalCache\\local-packages\\Python38\\site-packages\\telegram\\bot.py\", line 295, in _post\n",
      "    return self.request.post(\n",
      "  File \"C:\\Users\\alexb\\AppData\\Local\\Packages\\PythonSoftwareFoundation.Python.3.8_qbz5n2kfra8p0\\LocalCache\\local-packages\\Python38\\site-packages\\telegram\\utils\\request.py\", line 356, in post\n",
      "    result = self._request_wrapper(\n",
      "  File \"C:\\Users\\alexb\\AppData\\Local\\Packages\\PythonSoftwareFoundation.Python.3.8_qbz5n2kfra8p0\\LocalCache\\local-packages\\Python38\\site-packages\\telegram\\utils\\request.py\", line 283, in _request_wrapper\n",
      "    raise Conflict(message)\n",
      "telegram.error.Conflict: Conflict: terminated by other getUpdates request; make sure that only one bot instance is running\n",
      "Error while getting Updates: Conflict: terminated by other getUpdates request; make sure that only one bot instance is running\n",
      "No error handlers are registered, logging exception.\n",
      "Traceback (most recent call last):\n",
      "  File \"C:\\Users\\alexb\\AppData\\Local\\Packages\\PythonSoftwareFoundation.Python.3.8_qbz5n2kfra8p0\\LocalCache\\local-packages\\Python38\\site-packages\\telegram\\ext\\updater.py\", line 646, in _network_loop_retry\n",
      "    if not action_cb():\n",
      "  File \"C:\\Users\\alexb\\AppData\\Local\\Packages\\PythonSoftwareFoundation.Python.3.8_qbz5n2kfra8p0\\LocalCache\\local-packages\\Python38\\site-packages\\telegram\\ext\\updater.py\", line 597, in polling_action_cb\n",
      "    updates = self.bot.get_updates(\n",
      "  File \"C:\\Users\\alexb\\AppData\\Local\\Packages\\PythonSoftwareFoundation.Python.3.8_qbz5n2kfra8p0\\LocalCache\\local-packages\\Python38\\site-packages\\telegram\\ext\\extbot.py\", line 222, in get_updates\n",
      "    updates = super().get_updates(\n",
      "  File \"C:\\Users\\alexb\\AppData\\Local\\Packages\\PythonSoftwareFoundation.Python.3.8_qbz5n2kfra8p0\\LocalCache\\local-packages\\Python38\\site-packages\\telegram\\bot.py\", line 130, in decorator\n",
      "    result = func(*args, **kwargs)\n",
      "  File \"C:\\Users\\alexb\\AppData\\Local\\Packages\\PythonSoftwareFoundation.Python.3.8_qbz5n2kfra8p0\\LocalCache\\local-packages\\Python38\\site-packages\\telegram\\bot.py\", line 2861, in get_updates\n",
      "    self._post(\n",
      "  File \"C:\\Users\\alexb\\AppData\\Local\\Packages\\PythonSoftwareFoundation.Python.3.8_qbz5n2kfra8p0\\LocalCache\\local-packages\\Python38\\site-packages\\telegram\\bot.py\", line 295, in _post\n",
      "    return self.request.post(\n",
      "  File \"C:\\Users\\alexb\\AppData\\Local\\Packages\\PythonSoftwareFoundation.Python.3.8_qbz5n2kfra8p0\\LocalCache\\local-packages\\Python38\\site-packages\\telegram\\utils\\request.py\", line 356, in post\n",
      "    result = self._request_wrapper(\n",
      "  File \"C:\\Users\\alexb\\AppData\\Local\\Packages\\PythonSoftwareFoundation.Python.3.8_qbz5n2kfra8p0\\LocalCache\\local-packages\\Python38\\site-packages\\telegram\\utils\\request.py\", line 283, in _request_wrapper\n",
      "    raise Conflict(message)\n",
      "telegram.error.Conflict: Conflict: terminated by other getUpdates request; make sure that only one bot instance is running\n",
      "Error while getting Updates: Conflict: terminated by other getUpdates request; make sure that only one bot instance is running\n",
      "No error handlers are registered, logging exception.\n",
      "Traceback (most recent call last):\n",
      "  File \"C:\\Users\\alexb\\AppData\\Local\\Packages\\PythonSoftwareFoundation.Python.3.8_qbz5n2kfra8p0\\LocalCache\\local-packages\\Python38\\site-packages\\telegram\\ext\\updater.py\", line 646, in _network_loop_retry\n",
      "    if not action_cb():\n",
      "  File \"C:\\Users\\alexb\\AppData\\Local\\Packages\\PythonSoftwareFoundation.Python.3.8_qbz5n2kfra8p0\\LocalCache\\local-packages\\Python38\\site-packages\\telegram\\ext\\updater.py\", line 597, in polling_action_cb\n",
      "    updates = self.bot.get_updates(\n",
      "  File \"C:\\Users\\alexb\\AppData\\Local\\Packages\\PythonSoftwareFoundation.Python.3.8_qbz5n2kfra8p0\\LocalCache\\local-packages\\Python38\\site-packages\\telegram\\ext\\extbot.py\", line 222, in get_updates\n",
      "    updates = super().get_updates(\n",
      "  File \"C:\\Users\\alexb\\AppData\\Local\\Packages\\PythonSoftwareFoundation.Python.3.8_qbz5n2kfra8p0\\LocalCache\\local-packages\\Python38\\site-packages\\telegram\\bot.py\", line 130, in decorator\n",
      "    result = func(*args, **kwargs)\n",
      "  File \"C:\\Users\\alexb\\AppData\\Local\\Packages\\PythonSoftwareFoundation.Python.3.8_qbz5n2kfra8p0\\LocalCache\\local-packages\\Python38\\site-packages\\telegram\\bot.py\", line 2861, in get_updates\n",
      "    self._post(\n",
      "  File \"C:\\Users\\alexb\\AppData\\Local\\Packages\\PythonSoftwareFoundation.Python.3.8_qbz5n2kfra8p0\\LocalCache\\local-packages\\Python38\\site-packages\\telegram\\bot.py\", line 295, in _post\n",
      "    return self.request.post(\n",
      "  File \"C:\\Users\\alexb\\AppData\\Local\\Packages\\PythonSoftwareFoundation.Python.3.8_qbz5n2kfra8p0\\LocalCache\\local-packages\\Python38\\site-packages\\telegram\\utils\\request.py\", line 356, in post\n",
      "    result = self._request_wrapper(\n",
      "  File \"C:\\Users\\alexb\\AppData\\Local\\Packages\\PythonSoftwareFoundation.Python.3.8_qbz5n2kfra8p0\\LocalCache\\local-packages\\Python38\\site-packages\\telegram\\utils\\request.py\", line 283, in _request_wrapper\n",
      "    raise Conflict(message)\n",
      "telegram.error.Conflict: Conflict: terminated by other getUpdates request; make sure that only one bot instance is running\n",
      "Error while getting Updates: Conflict: terminated by other getUpdates request; make sure that only one bot instance is running\n",
      "No error handlers are registered, logging exception.\n",
      "Traceback (most recent call last):\n",
      "  File \"C:\\Users\\alexb\\AppData\\Local\\Packages\\PythonSoftwareFoundation.Python.3.8_qbz5n2kfra8p0\\LocalCache\\local-packages\\Python38\\site-packages\\telegram\\ext\\updater.py\", line 646, in _network_loop_retry\n",
      "    if not action_cb():\n",
      "  File \"C:\\Users\\alexb\\AppData\\Local\\Packages\\PythonSoftwareFoundation.Python.3.8_qbz5n2kfra8p0\\LocalCache\\local-packages\\Python38\\site-packages\\telegram\\ext\\updater.py\", line 597, in polling_action_cb\n",
      "    updates = self.bot.get_updates(\n",
      "  File \"C:\\Users\\alexb\\AppData\\Local\\Packages\\PythonSoftwareFoundation.Python.3.8_qbz5n2kfra8p0\\LocalCache\\local-packages\\Python38\\site-packages\\telegram\\ext\\extbot.py\", line 222, in get_updates\n",
      "    updates = super().get_updates(\n",
      "  File \"C:\\Users\\alexb\\AppData\\Local\\Packages\\PythonSoftwareFoundation.Python.3.8_qbz5n2kfra8p0\\LocalCache\\local-packages\\Python38\\site-packages\\telegram\\bot.py\", line 130, in decorator\n",
      "    result = func(*args, **kwargs)\n",
      "  File \"C:\\Users\\alexb\\AppData\\Local\\Packages\\PythonSoftwareFoundation.Python.3.8_qbz5n2kfra8p0\\LocalCache\\local-packages\\Python38\\site-packages\\telegram\\bot.py\", line 2861, in get_updates\n",
      "    self._post(\n",
      "  File \"C:\\Users\\alexb\\AppData\\Local\\Packages\\PythonSoftwareFoundation.Python.3.8_qbz5n2kfra8p0\\LocalCache\\local-packages\\Python38\\site-packages\\telegram\\bot.py\", line 295, in _post\n",
      "    return self.request.post(\n",
      "  File \"C:\\Users\\alexb\\AppData\\Local\\Packages\\PythonSoftwareFoundation.Python.3.8_qbz5n2kfra8p0\\LocalCache\\local-packages\\Python38\\site-packages\\telegram\\utils\\request.py\", line 356, in post\n",
      "    result = self._request_wrapper(\n",
      "  File \"C:\\Users\\alexb\\AppData\\Local\\Packages\\PythonSoftwareFoundation.Python.3.8_qbz5n2kfra8p0\\LocalCache\\local-packages\\Python38\\site-packages\\telegram\\utils\\request.py\", line 283, in _request_wrapper\n",
      "    raise Conflict(message)\n",
      "telegram.error.Conflict: Conflict: terminated by other getUpdates request; make sure that only one bot instance is running\n",
      "Error while getting Updates: Conflict: terminated by other getUpdates request; make sure that only one bot instance is running\n",
      "No error handlers are registered, logging exception.\n",
      "Traceback (most recent call last):\n",
      "  File \"C:\\Users\\alexb\\AppData\\Local\\Packages\\PythonSoftwareFoundation.Python.3.8_qbz5n2kfra8p0\\LocalCache\\local-packages\\Python38\\site-packages\\telegram\\ext\\updater.py\", line 646, in _network_loop_retry\n",
      "    if not action_cb():\n",
      "  File \"C:\\Users\\alexb\\AppData\\Local\\Packages\\PythonSoftwareFoundation.Python.3.8_qbz5n2kfra8p0\\LocalCache\\local-packages\\Python38\\site-packages\\telegram\\ext\\updater.py\", line 597, in polling_action_cb\n",
      "    updates = self.bot.get_updates(\n",
      "  File \"C:\\Users\\alexb\\AppData\\Local\\Packages\\PythonSoftwareFoundation.Python.3.8_qbz5n2kfra8p0\\LocalCache\\local-packages\\Python38\\site-packages\\telegram\\ext\\extbot.py\", line 222, in get_updates\n",
      "    updates = super().get_updates(\n",
      "  File \"C:\\Users\\alexb\\AppData\\Local\\Packages\\PythonSoftwareFoundation.Python.3.8_qbz5n2kfra8p0\\LocalCache\\local-packages\\Python38\\site-packages\\telegram\\bot.py\", line 130, in decorator\n",
      "    result = func(*args, **kwargs)\n",
      "  File \"C:\\Users\\alexb\\AppData\\Local\\Packages\\PythonSoftwareFoundation.Python.3.8_qbz5n2kfra8p0\\LocalCache\\local-packages\\Python38\\site-packages\\telegram\\bot.py\", line 2861, in get_updates\n",
      "    self._post(\n",
      "  File \"C:\\Users\\alexb\\AppData\\Local\\Packages\\PythonSoftwareFoundation.Python.3.8_qbz5n2kfra8p0\\LocalCache\\local-packages\\Python38\\site-packages\\telegram\\bot.py\", line 295, in _post\n",
      "    return self.request.post(\n",
      "  File \"C:\\Users\\alexb\\AppData\\Local\\Packages\\PythonSoftwareFoundation.Python.3.8_qbz5n2kfra8p0\\LocalCache\\local-packages\\Python38\\site-packages\\telegram\\utils\\request.py\", line 356, in post\n",
      "    result = self._request_wrapper(\n",
      "  File \"C:\\Users\\alexb\\AppData\\Local\\Packages\\PythonSoftwareFoundation.Python.3.8_qbz5n2kfra8p0\\LocalCache\\local-packages\\Python38\\site-packages\\telegram\\utils\\request.py\", line 283, in _request_wrapper\n",
      "    raise Conflict(message)\n",
      "telegram.error.Conflict: Conflict: terminated by other getUpdates request; make sure that only one bot instance is running\n",
      "Error while getting Updates: Conflict: terminated by other getUpdates request; make sure that only one bot instance is running\n",
      "No error handlers are registered, logging exception.\n",
      "Traceback (most recent call last):\n",
      "  File \"C:\\Users\\alexb\\AppData\\Local\\Packages\\PythonSoftwareFoundation.Python.3.8_qbz5n2kfra8p0\\LocalCache\\local-packages\\Python38\\site-packages\\telegram\\ext\\updater.py\", line 646, in _network_loop_retry\n",
      "    if not action_cb():\n",
      "  File \"C:\\Users\\alexb\\AppData\\Local\\Packages\\PythonSoftwareFoundation.Python.3.8_qbz5n2kfra8p0\\LocalCache\\local-packages\\Python38\\site-packages\\telegram\\ext\\updater.py\", line 597, in polling_action_cb\n",
      "    updates = self.bot.get_updates(\n",
      "  File \"C:\\Users\\alexb\\AppData\\Local\\Packages\\PythonSoftwareFoundation.Python.3.8_qbz5n2kfra8p0\\LocalCache\\local-packages\\Python38\\site-packages\\telegram\\ext\\extbot.py\", line 222, in get_updates\n",
      "    updates = super().get_updates(\n",
      "  File \"C:\\Users\\alexb\\AppData\\Local\\Packages\\PythonSoftwareFoundation.Python.3.8_qbz5n2kfra8p0\\LocalCache\\local-packages\\Python38\\site-packages\\telegram\\bot.py\", line 130, in decorator\n",
      "    result = func(*args, **kwargs)\n",
      "  File \"C:\\Users\\alexb\\AppData\\Local\\Packages\\PythonSoftwareFoundation.Python.3.8_qbz5n2kfra8p0\\LocalCache\\local-packages\\Python38\\site-packages\\telegram\\bot.py\", line 2861, in get_updates\n",
      "    self._post(\n",
      "  File \"C:\\Users\\alexb\\AppData\\Local\\Packages\\PythonSoftwareFoundation.Python.3.8_qbz5n2kfra8p0\\LocalCache\\local-packages\\Python38\\site-packages\\telegram\\bot.py\", line 295, in _post\n",
      "    return self.request.post(\n",
      "  File \"C:\\Users\\alexb\\AppData\\Local\\Packages\\PythonSoftwareFoundation.Python.3.8_qbz5n2kfra8p0\\LocalCache\\local-packages\\Python38\\site-packages\\telegram\\utils\\request.py\", line 356, in post\n",
      "    result = self._request_wrapper(\n",
      "  File \"C:\\Users\\alexb\\AppData\\Local\\Packages\\PythonSoftwareFoundation.Python.3.8_qbz5n2kfra8p0\\LocalCache\\local-packages\\Python38\\site-packages\\telegram\\utils\\request.py\", line 283, in _request_wrapper\n",
      "    raise Conflict(message)\n",
      "telegram.error.Conflict: Conflict: terminated by other getUpdates request; make sure that only one bot instance is running\n",
      "Error while getting Updates: Conflict: terminated by other getUpdates request; make sure that only one bot instance is running\n",
      "No error handlers are registered, logging exception.\n",
      "Traceback (most recent call last):\n",
      "  File \"C:\\Users\\alexb\\AppData\\Local\\Packages\\PythonSoftwareFoundation.Python.3.8_qbz5n2kfra8p0\\LocalCache\\local-packages\\Python38\\site-packages\\telegram\\ext\\updater.py\", line 646, in _network_loop_retry\n",
      "    if not action_cb():\n",
      "  File \"C:\\Users\\alexb\\AppData\\Local\\Packages\\PythonSoftwareFoundation.Python.3.8_qbz5n2kfra8p0\\LocalCache\\local-packages\\Python38\\site-packages\\telegram\\ext\\updater.py\", line 597, in polling_action_cb\n",
      "    updates = self.bot.get_updates(\n",
      "  File \"C:\\Users\\alexb\\AppData\\Local\\Packages\\PythonSoftwareFoundation.Python.3.8_qbz5n2kfra8p0\\LocalCache\\local-packages\\Python38\\site-packages\\telegram\\ext\\extbot.py\", line 222, in get_updates\n",
      "    updates = super().get_updates(\n",
      "  File \"C:\\Users\\alexb\\AppData\\Local\\Packages\\PythonSoftwareFoundation.Python.3.8_qbz5n2kfra8p0\\LocalCache\\local-packages\\Python38\\site-packages\\telegram\\bot.py\", line 130, in decorator\n",
      "    result = func(*args, **kwargs)\n",
      "  File \"C:\\Users\\alexb\\AppData\\Local\\Packages\\PythonSoftwareFoundation.Python.3.8_qbz5n2kfra8p0\\LocalCache\\local-packages\\Python38\\site-packages\\telegram\\bot.py\", line 2861, in get_updates\n",
      "    self._post(\n",
      "  File \"C:\\Users\\alexb\\AppData\\Local\\Packages\\PythonSoftwareFoundation.Python.3.8_qbz5n2kfra8p0\\LocalCache\\local-packages\\Python38\\site-packages\\telegram\\bot.py\", line 295, in _post\n",
      "    return self.request.post(\n",
      "  File \"C:\\Users\\alexb\\AppData\\Local\\Packages\\PythonSoftwareFoundation.Python.3.8_qbz5n2kfra8p0\\LocalCache\\local-packages\\Python38\\site-packages\\telegram\\utils\\request.py\", line 356, in post\n",
      "    result = self._request_wrapper(\n",
      "  File \"C:\\Users\\alexb\\AppData\\Local\\Packages\\PythonSoftwareFoundation.Python.3.8_qbz5n2kfra8p0\\LocalCache\\local-packages\\Python38\\site-packages\\telegram\\utils\\request.py\", line 283, in _request_wrapper\n",
      "    raise Conflict(message)\n",
      "telegram.error.Conflict: Conflict: terminated by other getUpdates request; make sure that only one bot instance is running\n",
      "Error while getting Updates: Conflict: terminated by other getUpdates request; make sure that only one bot instance is running\n",
      "No error handlers are registered, logging exception.\n",
      "Traceback (most recent call last):\n",
      "  File \"C:\\Users\\alexb\\AppData\\Local\\Packages\\PythonSoftwareFoundation.Python.3.8_qbz5n2kfra8p0\\LocalCache\\local-packages\\Python38\\site-packages\\telegram\\ext\\updater.py\", line 646, in _network_loop_retry\n",
      "    if not action_cb():\n",
      "  File \"C:\\Users\\alexb\\AppData\\Local\\Packages\\PythonSoftwareFoundation.Python.3.8_qbz5n2kfra8p0\\LocalCache\\local-packages\\Python38\\site-packages\\telegram\\ext\\updater.py\", line 597, in polling_action_cb\n",
      "    updates = self.bot.get_updates(\n",
      "  File \"C:\\Users\\alexb\\AppData\\Local\\Packages\\PythonSoftwareFoundation.Python.3.8_qbz5n2kfra8p0\\LocalCache\\local-packages\\Python38\\site-packages\\telegram\\ext\\extbot.py\", line 222, in get_updates\n",
      "    updates = super().get_updates(\n",
      "  File \"C:\\Users\\alexb\\AppData\\Local\\Packages\\PythonSoftwareFoundation.Python.3.8_qbz5n2kfra8p0\\LocalCache\\local-packages\\Python38\\site-packages\\telegram\\bot.py\", line 130, in decorator\n",
      "    result = func(*args, **kwargs)\n",
      "  File \"C:\\Users\\alexb\\AppData\\Local\\Packages\\PythonSoftwareFoundation.Python.3.8_qbz5n2kfra8p0\\LocalCache\\local-packages\\Python38\\site-packages\\telegram\\bot.py\", line 2861, in get_updates\n",
      "    self._post(\n",
      "  File \"C:\\Users\\alexb\\AppData\\Local\\Packages\\PythonSoftwareFoundation.Python.3.8_qbz5n2kfra8p0\\LocalCache\\local-packages\\Python38\\site-packages\\telegram\\bot.py\", line 295, in _post\n",
      "    return self.request.post(\n",
      "  File \"C:\\Users\\alexb\\AppData\\Local\\Packages\\PythonSoftwareFoundation.Python.3.8_qbz5n2kfra8p0\\LocalCache\\local-packages\\Python38\\site-packages\\telegram\\utils\\request.py\", line 356, in post\n",
      "    result = self._request_wrapper(\n",
      "  File \"C:\\Users\\alexb\\AppData\\Local\\Packages\\PythonSoftwareFoundation.Python.3.8_qbz5n2kfra8p0\\LocalCache\\local-packages\\Python38\\site-packages\\telegram\\utils\\request.py\", line 283, in _request_wrapper\n",
      "    raise Conflict(message)\n",
      "telegram.error.Conflict: Conflict: terminated by other getUpdates request; make sure that only one bot instance is running\n",
      "Error while getting Updates: Conflict: terminated by other getUpdates request; make sure that only one bot instance is running\n",
      "No error handlers are registered, logging exception.\n",
      "Traceback (most recent call last):\n",
      "  File \"C:\\Users\\alexb\\AppData\\Local\\Packages\\PythonSoftwareFoundation.Python.3.8_qbz5n2kfra8p0\\LocalCache\\local-packages\\Python38\\site-packages\\telegram\\ext\\updater.py\", line 646, in _network_loop_retry\n",
      "    if not action_cb():\n",
      "  File \"C:\\Users\\alexb\\AppData\\Local\\Packages\\PythonSoftwareFoundation.Python.3.8_qbz5n2kfra8p0\\LocalCache\\local-packages\\Python38\\site-packages\\telegram\\ext\\updater.py\", line 597, in polling_action_cb\n",
      "    updates = self.bot.get_updates(\n",
      "  File \"C:\\Users\\alexb\\AppData\\Local\\Packages\\PythonSoftwareFoundation.Python.3.8_qbz5n2kfra8p0\\LocalCache\\local-packages\\Python38\\site-packages\\telegram\\ext\\extbot.py\", line 222, in get_updates\n",
      "    updates = super().get_updates(\n",
      "  File \"C:\\Users\\alexb\\AppData\\Local\\Packages\\PythonSoftwareFoundation.Python.3.8_qbz5n2kfra8p0\\LocalCache\\local-packages\\Python38\\site-packages\\telegram\\bot.py\", line 130, in decorator\n",
      "    result = func(*args, **kwargs)\n",
      "  File \"C:\\Users\\alexb\\AppData\\Local\\Packages\\PythonSoftwareFoundation.Python.3.8_qbz5n2kfra8p0\\LocalCache\\local-packages\\Python38\\site-packages\\telegram\\bot.py\", line 2861, in get_updates\n",
      "    self._post(\n",
      "  File \"C:\\Users\\alexb\\AppData\\Local\\Packages\\PythonSoftwareFoundation.Python.3.8_qbz5n2kfra8p0\\LocalCache\\local-packages\\Python38\\site-packages\\telegram\\bot.py\", line 295, in _post\n",
      "    return self.request.post(\n",
      "  File \"C:\\Users\\alexb\\AppData\\Local\\Packages\\PythonSoftwareFoundation.Python.3.8_qbz5n2kfra8p0\\LocalCache\\local-packages\\Python38\\site-packages\\telegram\\utils\\request.py\", line 356, in post\n",
      "    result = self._request_wrapper(\n",
      "  File \"C:\\Users\\alexb\\AppData\\Local\\Packages\\PythonSoftwareFoundation.Python.3.8_qbz5n2kfra8p0\\LocalCache\\local-packages\\Python38\\site-packages\\telegram\\utils\\request.py\", line 283, in _request_wrapper\n",
      "    raise Conflict(message)\n",
      "telegram.error.Conflict: Conflict: terminated by other getUpdates request; make sure that only one bot instance is running\n",
      "Error while getting Updates: Conflict: terminated by other getUpdates request; make sure that only one bot instance is running\n",
      "No error handlers are registered, logging exception.\n",
      "Traceback (most recent call last):\n",
      "  File \"C:\\Users\\alexb\\AppData\\Local\\Packages\\PythonSoftwareFoundation.Python.3.8_qbz5n2kfra8p0\\LocalCache\\local-packages\\Python38\\site-packages\\telegram\\ext\\updater.py\", line 646, in _network_loop_retry\n",
      "    if not action_cb():\n",
      "  File \"C:\\Users\\alexb\\AppData\\Local\\Packages\\PythonSoftwareFoundation.Python.3.8_qbz5n2kfra8p0\\LocalCache\\local-packages\\Python38\\site-packages\\telegram\\ext\\updater.py\", line 597, in polling_action_cb\n",
      "    updates = self.bot.get_updates(\n",
      "  File \"C:\\Users\\alexb\\AppData\\Local\\Packages\\PythonSoftwareFoundation.Python.3.8_qbz5n2kfra8p0\\LocalCache\\local-packages\\Python38\\site-packages\\telegram\\ext\\extbot.py\", line 222, in get_updates\n",
      "    updates = super().get_updates(\n",
      "  File \"C:\\Users\\alexb\\AppData\\Local\\Packages\\PythonSoftwareFoundation.Python.3.8_qbz5n2kfra8p0\\LocalCache\\local-packages\\Python38\\site-packages\\telegram\\bot.py\", line 130, in decorator\n",
      "    result = func(*args, **kwargs)\n",
      "  File \"C:\\Users\\alexb\\AppData\\Local\\Packages\\PythonSoftwareFoundation.Python.3.8_qbz5n2kfra8p0\\LocalCache\\local-packages\\Python38\\site-packages\\telegram\\bot.py\", line 2861, in get_updates\n",
      "    self._post(\n",
      "  File \"C:\\Users\\alexb\\AppData\\Local\\Packages\\PythonSoftwareFoundation.Python.3.8_qbz5n2kfra8p0\\LocalCache\\local-packages\\Python38\\site-packages\\telegram\\bot.py\", line 295, in _post\n",
      "    return self.request.post(\n",
      "  File \"C:\\Users\\alexb\\AppData\\Local\\Packages\\PythonSoftwareFoundation.Python.3.8_qbz5n2kfra8p0\\LocalCache\\local-packages\\Python38\\site-packages\\telegram\\utils\\request.py\", line 356, in post\n",
      "    result = self._request_wrapper(\n",
      "  File \"C:\\Users\\alexb\\AppData\\Local\\Packages\\PythonSoftwareFoundation.Python.3.8_qbz5n2kfra8p0\\LocalCache\\local-packages\\Python38\\site-packages\\telegram\\utils\\request.py\", line 283, in _request_wrapper\n",
      "    raise Conflict(message)\n",
      "telegram.error.Conflict: Conflict: terminated by other getUpdates request; make sure that only one bot instance is running\n",
      "Error while getting Updates: Conflict: terminated by other getUpdates request; make sure that only one bot instance is running\n",
      "No error handlers are registered, logging exception.\n",
      "Traceback (most recent call last):\n",
      "  File \"C:\\Users\\alexb\\AppData\\Local\\Packages\\PythonSoftwareFoundation.Python.3.8_qbz5n2kfra8p0\\LocalCache\\local-packages\\Python38\\site-packages\\telegram\\ext\\updater.py\", line 646, in _network_loop_retry\n",
      "    if not action_cb():\n",
      "  File \"C:\\Users\\alexb\\AppData\\Local\\Packages\\PythonSoftwareFoundation.Python.3.8_qbz5n2kfra8p0\\LocalCache\\local-packages\\Python38\\site-packages\\telegram\\ext\\updater.py\", line 597, in polling_action_cb\n",
      "    updates = self.bot.get_updates(\n",
      "  File \"C:\\Users\\alexb\\AppData\\Local\\Packages\\PythonSoftwareFoundation.Python.3.8_qbz5n2kfra8p0\\LocalCache\\local-packages\\Python38\\site-packages\\telegram\\ext\\extbot.py\", line 222, in get_updates\n",
      "    updates = super().get_updates(\n",
      "  File \"C:\\Users\\alexb\\AppData\\Local\\Packages\\PythonSoftwareFoundation.Python.3.8_qbz5n2kfra8p0\\LocalCache\\local-packages\\Python38\\site-packages\\telegram\\bot.py\", line 130, in decorator\n",
      "    result = func(*args, **kwargs)\n",
      "  File \"C:\\Users\\alexb\\AppData\\Local\\Packages\\PythonSoftwareFoundation.Python.3.8_qbz5n2kfra8p0\\LocalCache\\local-packages\\Python38\\site-packages\\telegram\\bot.py\", line 2861, in get_updates\n",
      "    self._post(\n",
      "  File \"C:\\Users\\alexb\\AppData\\Local\\Packages\\PythonSoftwareFoundation.Python.3.8_qbz5n2kfra8p0\\LocalCache\\local-packages\\Python38\\site-packages\\telegram\\bot.py\", line 295, in _post\n",
      "    return self.request.post(\n",
      "  File \"C:\\Users\\alexb\\AppData\\Local\\Packages\\PythonSoftwareFoundation.Python.3.8_qbz5n2kfra8p0\\LocalCache\\local-packages\\Python38\\site-packages\\telegram\\utils\\request.py\", line 356, in post\n",
      "    result = self._request_wrapper(\n",
      "  File \"C:\\Users\\alexb\\AppData\\Local\\Packages\\PythonSoftwareFoundation.Python.3.8_qbz5n2kfra8p0\\LocalCache\\local-packages\\Python38\\site-packages\\telegram\\utils\\request.py\", line 283, in _request_wrapper\n",
      "    raise Conflict(message)\n",
      "telegram.error.Conflict: Conflict: terminated by other getUpdates request; make sure that only one bot instance is running\n",
      "Error while getting Updates: Conflict: terminated by other getUpdates request; make sure that only one bot instance is running\n",
      "No error handlers are registered, logging exception.\n",
      "Traceback (most recent call last):\n",
      "  File \"C:\\Users\\alexb\\AppData\\Local\\Packages\\PythonSoftwareFoundation.Python.3.8_qbz5n2kfra8p0\\LocalCache\\local-packages\\Python38\\site-packages\\telegram\\ext\\updater.py\", line 646, in _network_loop_retry\n",
      "    if not action_cb():\n",
      "  File \"C:\\Users\\alexb\\AppData\\Local\\Packages\\PythonSoftwareFoundation.Python.3.8_qbz5n2kfra8p0\\LocalCache\\local-packages\\Python38\\site-packages\\telegram\\ext\\updater.py\", line 597, in polling_action_cb\n",
      "    updates = self.bot.get_updates(\n",
      "  File \"C:\\Users\\alexb\\AppData\\Local\\Packages\\PythonSoftwareFoundation.Python.3.8_qbz5n2kfra8p0\\LocalCache\\local-packages\\Python38\\site-packages\\telegram\\ext\\extbot.py\", line 222, in get_updates\n",
      "    updates = super().get_updates(\n",
      "  File \"C:\\Users\\alexb\\AppData\\Local\\Packages\\PythonSoftwareFoundation.Python.3.8_qbz5n2kfra8p0\\LocalCache\\local-packages\\Python38\\site-packages\\telegram\\bot.py\", line 130, in decorator\n",
      "    result = func(*args, **kwargs)\n",
      "  File \"C:\\Users\\alexb\\AppData\\Local\\Packages\\PythonSoftwareFoundation.Python.3.8_qbz5n2kfra8p0\\LocalCache\\local-packages\\Python38\\site-packages\\telegram\\bot.py\", line 2861, in get_updates\n",
      "    self._post(\n",
      "  File \"C:\\Users\\alexb\\AppData\\Local\\Packages\\PythonSoftwareFoundation.Python.3.8_qbz5n2kfra8p0\\LocalCache\\local-packages\\Python38\\site-packages\\telegram\\bot.py\", line 295, in _post\n",
      "    return self.request.post(\n",
      "  File \"C:\\Users\\alexb\\AppData\\Local\\Packages\\PythonSoftwareFoundation.Python.3.8_qbz5n2kfra8p0\\LocalCache\\local-packages\\Python38\\site-packages\\telegram\\utils\\request.py\", line 356, in post\n",
      "    result = self._request_wrapper(\n",
      "  File \"C:\\Users\\alexb\\AppData\\Local\\Packages\\PythonSoftwareFoundation.Python.3.8_qbz5n2kfra8p0\\LocalCache\\local-packages\\Python38\\site-packages\\telegram\\utils\\request.py\", line 283, in _request_wrapper\n",
      "    raise Conflict(message)\n",
      "telegram.error.Conflict: Conflict: terminated by other getUpdates request; make sure that only one bot instance is running\n",
      "Error while getting Updates: Conflict: terminated by other getUpdates request; make sure that only one bot instance is running\n",
      "No error handlers are registered, logging exception.\n",
      "Traceback (most recent call last):\n",
      "  File \"C:\\Users\\alexb\\AppData\\Local\\Packages\\PythonSoftwareFoundation.Python.3.8_qbz5n2kfra8p0\\LocalCache\\local-packages\\Python38\\site-packages\\telegram\\ext\\updater.py\", line 646, in _network_loop_retry\n",
      "    if not action_cb():\n",
      "  File \"C:\\Users\\alexb\\AppData\\Local\\Packages\\PythonSoftwareFoundation.Python.3.8_qbz5n2kfra8p0\\LocalCache\\local-packages\\Python38\\site-packages\\telegram\\ext\\updater.py\", line 597, in polling_action_cb\n",
      "    updates = self.bot.get_updates(\n",
      "  File \"C:\\Users\\alexb\\AppData\\Local\\Packages\\PythonSoftwareFoundation.Python.3.8_qbz5n2kfra8p0\\LocalCache\\local-packages\\Python38\\site-packages\\telegram\\ext\\extbot.py\", line 222, in get_updates\n",
      "    updates = super().get_updates(\n",
      "  File \"C:\\Users\\alexb\\AppData\\Local\\Packages\\PythonSoftwareFoundation.Python.3.8_qbz5n2kfra8p0\\LocalCache\\local-packages\\Python38\\site-packages\\telegram\\bot.py\", line 130, in decorator\n",
      "    result = func(*args, **kwargs)\n",
      "  File \"C:\\Users\\alexb\\AppData\\Local\\Packages\\PythonSoftwareFoundation.Python.3.8_qbz5n2kfra8p0\\LocalCache\\local-packages\\Python38\\site-packages\\telegram\\bot.py\", line 2861, in get_updates\n",
      "    self._post(\n",
      "  File \"C:\\Users\\alexb\\AppData\\Local\\Packages\\PythonSoftwareFoundation.Python.3.8_qbz5n2kfra8p0\\LocalCache\\local-packages\\Python38\\site-packages\\telegram\\bot.py\", line 295, in _post\n",
      "    return self.request.post(\n",
      "  File \"C:\\Users\\alexb\\AppData\\Local\\Packages\\PythonSoftwareFoundation.Python.3.8_qbz5n2kfra8p0\\LocalCache\\local-packages\\Python38\\site-packages\\telegram\\utils\\request.py\", line 356, in post\n",
      "    result = self._request_wrapper(\n",
      "  File \"C:\\Users\\alexb\\AppData\\Local\\Packages\\PythonSoftwareFoundation.Python.3.8_qbz5n2kfra8p0\\LocalCache\\local-packages\\Python38\\site-packages\\telegram\\utils\\request.py\", line 283, in _request_wrapper\n",
      "    raise Conflict(message)\n",
      "telegram.error.Conflict: Conflict: terminated by other getUpdates request; make sure that only one bot instance is running\n",
      "Error while getting Updates: Conflict: terminated by other getUpdates request; make sure that only one bot instance is running\n",
      "No error handlers are registered, logging exception.\n",
      "Traceback (most recent call last):\n",
      "  File \"C:\\Users\\alexb\\AppData\\Local\\Packages\\PythonSoftwareFoundation.Python.3.8_qbz5n2kfra8p0\\LocalCache\\local-packages\\Python38\\site-packages\\telegram\\ext\\updater.py\", line 646, in _network_loop_retry\n",
      "    if not action_cb():\n",
      "  File \"C:\\Users\\alexb\\AppData\\Local\\Packages\\PythonSoftwareFoundation.Python.3.8_qbz5n2kfra8p0\\LocalCache\\local-packages\\Python38\\site-packages\\telegram\\ext\\updater.py\", line 597, in polling_action_cb\n",
      "    updates = self.bot.get_updates(\n",
      "  File \"C:\\Users\\alexb\\AppData\\Local\\Packages\\PythonSoftwareFoundation.Python.3.8_qbz5n2kfra8p0\\LocalCache\\local-packages\\Python38\\site-packages\\telegram\\ext\\extbot.py\", line 222, in get_updates\n",
      "    updates = super().get_updates(\n",
      "  File \"C:\\Users\\alexb\\AppData\\Local\\Packages\\PythonSoftwareFoundation.Python.3.8_qbz5n2kfra8p0\\LocalCache\\local-packages\\Python38\\site-packages\\telegram\\bot.py\", line 130, in decorator\n",
      "    result = func(*args, **kwargs)\n",
      "  File \"C:\\Users\\alexb\\AppData\\Local\\Packages\\PythonSoftwareFoundation.Python.3.8_qbz5n2kfra8p0\\LocalCache\\local-packages\\Python38\\site-packages\\telegram\\bot.py\", line 2861, in get_updates\n",
      "    self._post(\n",
      "  File \"C:\\Users\\alexb\\AppData\\Local\\Packages\\PythonSoftwareFoundation.Python.3.8_qbz5n2kfra8p0\\LocalCache\\local-packages\\Python38\\site-packages\\telegram\\bot.py\", line 295, in _post\n",
      "    return self.request.post(\n",
      "  File \"C:\\Users\\alexb\\AppData\\Local\\Packages\\PythonSoftwareFoundation.Python.3.8_qbz5n2kfra8p0\\LocalCache\\local-packages\\Python38\\site-packages\\telegram\\utils\\request.py\", line 356, in post\n",
      "    result = self._request_wrapper(\n",
      "  File \"C:\\Users\\alexb\\AppData\\Local\\Packages\\PythonSoftwareFoundation.Python.3.8_qbz5n2kfra8p0\\LocalCache\\local-packages\\Python38\\site-packages\\telegram\\utils\\request.py\", line 283, in _request_wrapper\n",
      "    raise Conflict(message)\n",
      "telegram.error.Conflict: Conflict: terminated by other getUpdates request; make sure that only one bot instance is running\n",
      "Error while getting Updates: Conflict: terminated by other getUpdates request; make sure that only one bot instance is running\n",
      "No error handlers are registered, logging exception.\n",
      "Traceback (most recent call last):\n",
      "  File \"C:\\Users\\alexb\\AppData\\Local\\Packages\\PythonSoftwareFoundation.Python.3.8_qbz5n2kfra8p0\\LocalCache\\local-packages\\Python38\\site-packages\\telegram\\ext\\updater.py\", line 646, in _network_loop_retry\n",
      "    if not action_cb():\n",
      "  File \"C:\\Users\\alexb\\AppData\\Local\\Packages\\PythonSoftwareFoundation.Python.3.8_qbz5n2kfra8p0\\LocalCache\\local-packages\\Python38\\site-packages\\telegram\\ext\\updater.py\", line 597, in polling_action_cb\n",
      "    updates = self.bot.get_updates(\n",
      "  File \"C:\\Users\\alexb\\AppData\\Local\\Packages\\PythonSoftwareFoundation.Python.3.8_qbz5n2kfra8p0\\LocalCache\\local-packages\\Python38\\site-packages\\telegram\\ext\\extbot.py\", line 222, in get_updates\n",
      "    updates = super().get_updates(\n",
      "  File \"C:\\Users\\alexb\\AppData\\Local\\Packages\\PythonSoftwareFoundation.Python.3.8_qbz5n2kfra8p0\\LocalCache\\local-packages\\Python38\\site-packages\\telegram\\bot.py\", line 130, in decorator\n",
      "    result = func(*args, **kwargs)\n",
      "  File \"C:\\Users\\alexb\\AppData\\Local\\Packages\\PythonSoftwareFoundation.Python.3.8_qbz5n2kfra8p0\\LocalCache\\local-packages\\Python38\\site-packages\\telegram\\bot.py\", line 2861, in get_updates\n",
      "    self._post(\n",
      "  File \"C:\\Users\\alexb\\AppData\\Local\\Packages\\PythonSoftwareFoundation.Python.3.8_qbz5n2kfra8p0\\LocalCache\\local-packages\\Python38\\site-packages\\telegram\\bot.py\", line 295, in _post\n",
      "    return self.request.post(\n",
      "  File \"C:\\Users\\alexb\\AppData\\Local\\Packages\\PythonSoftwareFoundation.Python.3.8_qbz5n2kfra8p0\\LocalCache\\local-packages\\Python38\\site-packages\\telegram\\utils\\request.py\", line 356, in post\n",
      "    result = self._request_wrapper(\n",
      "  File \"C:\\Users\\alexb\\AppData\\Local\\Packages\\PythonSoftwareFoundation.Python.3.8_qbz5n2kfra8p0\\LocalCache\\local-packages\\Python38\\site-packages\\telegram\\utils\\request.py\", line 283, in _request_wrapper\n",
      "    raise Conflict(message)\n",
      "telegram.error.Conflict: Conflict: terminated by other getUpdates request; make sure that only one bot instance is running\n",
      "Error while getting Updates: Conflict: terminated by other getUpdates request; make sure that only one bot instance is running\n",
      "No error handlers are registered, logging exception.\n",
      "Traceback (most recent call last):\n",
      "  File \"C:\\Users\\alexb\\AppData\\Local\\Packages\\PythonSoftwareFoundation.Python.3.8_qbz5n2kfra8p0\\LocalCache\\local-packages\\Python38\\site-packages\\telegram\\ext\\updater.py\", line 646, in _network_loop_retry\n",
      "    if not action_cb():\n",
      "  File \"C:\\Users\\alexb\\AppData\\Local\\Packages\\PythonSoftwareFoundation.Python.3.8_qbz5n2kfra8p0\\LocalCache\\local-packages\\Python38\\site-packages\\telegram\\ext\\updater.py\", line 597, in polling_action_cb\n",
      "    updates = self.bot.get_updates(\n",
      "  File \"C:\\Users\\alexb\\AppData\\Local\\Packages\\PythonSoftwareFoundation.Python.3.8_qbz5n2kfra8p0\\LocalCache\\local-packages\\Python38\\site-packages\\telegram\\ext\\extbot.py\", line 222, in get_updates\n",
      "    updates = super().get_updates(\n",
      "  File \"C:\\Users\\alexb\\AppData\\Local\\Packages\\PythonSoftwareFoundation.Python.3.8_qbz5n2kfra8p0\\LocalCache\\local-packages\\Python38\\site-packages\\telegram\\bot.py\", line 130, in decorator\n",
      "    result = func(*args, **kwargs)\n",
      "  File \"C:\\Users\\alexb\\AppData\\Local\\Packages\\PythonSoftwareFoundation.Python.3.8_qbz5n2kfra8p0\\LocalCache\\local-packages\\Python38\\site-packages\\telegram\\bot.py\", line 2861, in get_updates\n",
      "    self._post(\n",
      "  File \"C:\\Users\\alexb\\AppData\\Local\\Packages\\PythonSoftwareFoundation.Python.3.8_qbz5n2kfra8p0\\LocalCache\\local-packages\\Python38\\site-packages\\telegram\\bot.py\", line 295, in _post\n",
      "    return self.request.post(\n",
      "  File \"C:\\Users\\alexb\\AppData\\Local\\Packages\\PythonSoftwareFoundation.Python.3.8_qbz5n2kfra8p0\\LocalCache\\local-packages\\Python38\\site-packages\\telegram\\utils\\request.py\", line 356, in post\n",
      "    result = self._request_wrapper(\n",
      "  File \"C:\\Users\\alexb\\AppData\\Local\\Packages\\PythonSoftwareFoundation.Python.3.8_qbz5n2kfra8p0\\LocalCache\\local-packages\\Python38\\site-packages\\telegram\\utils\\request.py\", line 283, in _request_wrapper\n",
      "    raise Conflict(message)\n",
      "telegram.error.Conflict: Conflict: terminated by other getUpdates request; make sure that only one bot instance is running\n",
      "Error while getting Updates: Conflict: terminated by other getUpdates request; make sure that only one bot instance is running\n",
      "No error handlers are registered, logging exception.\n",
      "Traceback (most recent call last):\n",
      "  File \"C:\\Users\\alexb\\AppData\\Local\\Packages\\PythonSoftwareFoundation.Python.3.8_qbz5n2kfra8p0\\LocalCache\\local-packages\\Python38\\site-packages\\telegram\\ext\\updater.py\", line 646, in _network_loop_retry\n",
      "    if not action_cb():\n",
      "  File \"C:\\Users\\alexb\\AppData\\Local\\Packages\\PythonSoftwareFoundation.Python.3.8_qbz5n2kfra8p0\\LocalCache\\local-packages\\Python38\\site-packages\\telegram\\ext\\updater.py\", line 597, in polling_action_cb\n",
      "    updates = self.bot.get_updates(\n",
      "  File \"C:\\Users\\alexb\\AppData\\Local\\Packages\\PythonSoftwareFoundation.Python.3.8_qbz5n2kfra8p0\\LocalCache\\local-packages\\Python38\\site-packages\\telegram\\ext\\extbot.py\", line 222, in get_updates\n",
      "    updates = super().get_updates(\n",
      "  File \"C:\\Users\\alexb\\AppData\\Local\\Packages\\PythonSoftwareFoundation.Python.3.8_qbz5n2kfra8p0\\LocalCache\\local-packages\\Python38\\site-packages\\telegram\\bot.py\", line 130, in decorator\n",
      "    result = func(*args, **kwargs)\n",
      "  File \"C:\\Users\\alexb\\AppData\\Local\\Packages\\PythonSoftwareFoundation.Python.3.8_qbz5n2kfra8p0\\LocalCache\\local-packages\\Python38\\site-packages\\telegram\\bot.py\", line 2861, in get_updates\n",
      "    self._post(\n",
      "  File \"C:\\Users\\alexb\\AppData\\Local\\Packages\\PythonSoftwareFoundation.Python.3.8_qbz5n2kfra8p0\\LocalCache\\local-packages\\Python38\\site-packages\\telegram\\bot.py\", line 295, in _post\n",
      "    return self.request.post(\n",
      "  File \"C:\\Users\\alexb\\AppData\\Local\\Packages\\PythonSoftwareFoundation.Python.3.8_qbz5n2kfra8p0\\LocalCache\\local-packages\\Python38\\site-packages\\telegram\\utils\\request.py\", line 356, in post\n",
      "    result = self._request_wrapper(\n",
      "  File \"C:\\Users\\alexb\\AppData\\Local\\Packages\\PythonSoftwareFoundation.Python.3.8_qbz5n2kfra8p0\\LocalCache\\local-packages\\Python38\\site-packages\\telegram\\utils\\request.py\", line 283, in _request_wrapper\n",
      "    raise Conflict(message)\n",
      "telegram.error.Conflict: Conflict: terminated by other getUpdates request; make sure that only one bot instance is running\n",
      "Error while getting Updates: Conflict: terminated by other getUpdates request; make sure that only one bot instance is running\n",
      "No error handlers are registered, logging exception.\n",
      "Traceback (most recent call last):\n",
      "  File \"C:\\Users\\alexb\\AppData\\Local\\Packages\\PythonSoftwareFoundation.Python.3.8_qbz5n2kfra8p0\\LocalCache\\local-packages\\Python38\\site-packages\\telegram\\ext\\updater.py\", line 646, in _network_loop_retry\n",
      "    if not action_cb():\n",
      "  File \"C:\\Users\\alexb\\AppData\\Local\\Packages\\PythonSoftwareFoundation.Python.3.8_qbz5n2kfra8p0\\LocalCache\\local-packages\\Python38\\site-packages\\telegram\\ext\\updater.py\", line 597, in polling_action_cb\n",
      "    updates = self.bot.get_updates(\n",
      "  File \"C:\\Users\\alexb\\AppData\\Local\\Packages\\PythonSoftwareFoundation.Python.3.8_qbz5n2kfra8p0\\LocalCache\\local-packages\\Python38\\site-packages\\telegram\\ext\\extbot.py\", line 222, in get_updates\n",
      "    updates = super().get_updates(\n",
      "  File \"C:\\Users\\alexb\\AppData\\Local\\Packages\\PythonSoftwareFoundation.Python.3.8_qbz5n2kfra8p0\\LocalCache\\local-packages\\Python38\\site-packages\\telegram\\bot.py\", line 130, in decorator\n",
      "    result = func(*args, **kwargs)\n",
      "  File \"C:\\Users\\alexb\\AppData\\Local\\Packages\\PythonSoftwareFoundation.Python.3.8_qbz5n2kfra8p0\\LocalCache\\local-packages\\Python38\\site-packages\\telegram\\bot.py\", line 2861, in get_updates\n",
      "    self._post(\n",
      "  File \"C:\\Users\\alexb\\AppData\\Local\\Packages\\PythonSoftwareFoundation.Python.3.8_qbz5n2kfra8p0\\LocalCache\\local-packages\\Python38\\site-packages\\telegram\\bot.py\", line 295, in _post\n",
      "    return self.request.post(\n",
      "  File \"C:\\Users\\alexb\\AppData\\Local\\Packages\\PythonSoftwareFoundation.Python.3.8_qbz5n2kfra8p0\\LocalCache\\local-packages\\Python38\\site-packages\\telegram\\utils\\request.py\", line 356, in post\n",
      "    result = self._request_wrapper(\n",
      "  File \"C:\\Users\\alexb\\AppData\\Local\\Packages\\PythonSoftwareFoundation.Python.3.8_qbz5n2kfra8p0\\LocalCache\\local-packages\\Python38\\site-packages\\telegram\\utils\\request.py\", line 283, in _request_wrapper\n",
      "    raise Conflict(message)\n",
      "telegram.error.Conflict: Conflict: terminated by other getUpdates request; make sure that only one bot instance is running\n",
      "Error while getting Updates: Conflict: terminated by other getUpdates request; make sure that only one bot instance is running\n",
      "No error handlers are registered, logging exception.\n",
      "Traceback (most recent call last):\n",
      "  File \"C:\\Users\\alexb\\AppData\\Local\\Packages\\PythonSoftwareFoundation.Python.3.8_qbz5n2kfra8p0\\LocalCache\\local-packages\\Python38\\site-packages\\telegram\\ext\\updater.py\", line 646, in _network_loop_retry\n",
      "    if not action_cb():\n",
      "  File \"C:\\Users\\alexb\\AppData\\Local\\Packages\\PythonSoftwareFoundation.Python.3.8_qbz5n2kfra8p0\\LocalCache\\local-packages\\Python38\\site-packages\\telegram\\ext\\updater.py\", line 597, in polling_action_cb\n",
      "    updates = self.bot.get_updates(\n",
      "  File \"C:\\Users\\alexb\\AppData\\Local\\Packages\\PythonSoftwareFoundation.Python.3.8_qbz5n2kfra8p0\\LocalCache\\local-packages\\Python38\\site-packages\\telegram\\ext\\extbot.py\", line 222, in get_updates\n",
      "    updates = super().get_updates(\n",
      "  File \"C:\\Users\\alexb\\AppData\\Local\\Packages\\PythonSoftwareFoundation.Python.3.8_qbz5n2kfra8p0\\LocalCache\\local-packages\\Python38\\site-packages\\telegram\\bot.py\", line 130, in decorator\n",
      "    result = func(*args, **kwargs)\n",
      "  File \"C:\\Users\\alexb\\AppData\\Local\\Packages\\PythonSoftwareFoundation.Python.3.8_qbz5n2kfra8p0\\LocalCache\\local-packages\\Python38\\site-packages\\telegram\\bot.py\", line 2861, in get_updates\n",
      "    self._post(\n",
      "  File \"C:\\Users\\alexb\\AppData\\Local\\Packages\\PythonSoftwareFoundation.Python.3.8_qbz5n2kfra8p0\\LocalCache\\local-packages\\Python38\\site-packages\\telegram\\bot.py\", line 295, in _post\n",
      "    return self.request.post(\n",
      "  File \"C:\\Users\\alexb\\AppData\\Local\\Packages\\PythonSoftwareFoundation.Python.3.8_qbz5n2kfra8p0\\LocalCache\\local-packages\\Python38\\site-packages\\telegram\\utils\\request.py\", line 356, in post\n",
      "    result = self._request_wrapper(\n",
      "  File \"C:\\Users\\alexb\\AppData\\Local\\Packages\\PythonSoftwareFoundation.Python.3.8_qbz5n2kfra8p0\\LocalCache\\local-packages\\Python38\\site-packages\\telegram\\utils\\request.py\", line 283, in _request_wrapper\n",
      "    raise Conflict(message)\n",
      "telegram.error.Conflict: Conflict: terminated by other getUpdates request; make sure that only one bot instance is running\n",
      "Error while getting Updates: Conflict: terminated by other getUpdates request; make sure that only one bot instance is running\n",
      "No error handlers are registered, logging exception.\n",
      "Traceback (most recent call last):\n",
      "  File \"C:\\Users\\alexb\\AppData\\Local\\Packages\\PythonSoftwareFoundation.Python.3.8_qbz5n2kfra8p0\\LocalCache\\local-packages\\Python38\\site-packages\\telegram\\ext\\updater.py\", line 646, in _network_loop_retry\n",
      "    if not action_cb():\n",
      "  File \"C:\\Users\\alexb\\AppData\\Local\\Packages\\PythonSoftwareFoundation.Python.3.8_qbz5n2kfra8p0\\LocalCache\\local-packages\\Python38\\site-packages\\telegram\\ext\\updater.py\", line 597, in polling_action_cb\n",
      "    updates = self.bot.get_updates(\n",
      "  File \"C:\\Users\\alexb\\AppData\\Local\\Packages\\PythonSoftwareFoundation.Python.3.8_qbz5n2kfra8p0\\LocalCache\\local-packages\\Python38\\site-packages\\telegram\\ext\\extbot.py\", line 222, in get_updates\n",
      "    updates = super().get_updates(\n",
      "  File \"C:\\Users\\alexb\\AppData\\Local\\Packages\\PythonSoftwareFoundation.Python.3.8_qbz5n2kfra8p0\\LocalCache\\local-packages\\Python38\\site-packages\\telegram\\bot.py\", line 130, in decorator\n",
      "    result = func(*args, **kwargs)\n",
      "  File \"C:\\Users\\alexb\\AppData\\Local\\Packages\\PythonSoftwareFoundation.Python.3.8_qbz5n2kfra8p0\\LocalCache\\local-packages\\Python38\\site-packages\\telegram\\bot.py\", line 2861, in get_updates\n",
      "    self._post(\n",
      "  File \"C:\\Users\\alexb\\AppData\\Local\\Packages\\PythonSoftwareFoundation.Python.3.8_qbz5n2kfra8p0\\LocalCache\\local-packages\\Python38\\site-packages\\telegram\\bot.py\", line 295, in _post\n",
      "    return self.request.post(\n",
      "  File \"C:\\Users\\alexb\\AppData\\Local\\Packages\\PythonSoftwareFoundation.Python.3.8_qbz5n2kfra8p0\\LocalCache\\local-packages\\Python38\\site-packages\\telegram\\utils\\request.py\", line 356, in post\n",
      "    result = self._request_wrapper(\n",
      "  File \"C:\\Users\\alexb\\AppData\\Local\\Packages\\PythonSoftwareFoundation.Python.3.8_qbz5n2kfra8p0\\LocalCache\\local-packages\\Python38\\site-packages\\telegram\\utils\\request.py\", line 283, in _request_wrapper\n",
      "    raise Conflict(message)\n",
      "telegram.error.Conflict: Conflict: terminated by other getUpdates request; make sure that only one bot instance is running\n",
      "Error while getting Updates: Conflict: terminated by other getUpdates request; make sure that only one bot instance is running\n",
      "No error handlers are registered, logging exception.\n",
      "Traceback (most recent call last):\n",
      "  File \"C:\\Users\\alexb\\AppData\\Local\\Packages\\PythonSoftwareFoundation.Python.3.8_qbz5n2kfra8p0\\LocalCache\\local-packages\\Python38\\site-packages\\telegram\\ext\\updater.py\", line 646, in _network_loop_retry\n",
      "    if not action_cb():\n",
      "  File \"C:\\Users\\alexb\\AppData\\Local\\Packages\\PythonSoftwareFoundation.Python.3.8_qbz5n2kfra8p0\\LocalCache\\local-packages\\Python38\\site-packages\\telegram\\ext\\updater.py\", line 597, in polling_action_cb\n",
      "    updates = self.bot.get_updates(\n",
      "  File \"C:\\Users\\alexb\\AppData\\Local\\Packages\\PythonSoftwareFoundation.Python.3.8_qbz5n2kfra8p0\\LocalCache\\local-packages\\Python38\\site-packages\\telegram\\ext\\extbot.py\", line 222, in get_updates\n",
      "    updates = super().get_updates(\n",
      "  File \"C:\\Users\\alexb\\AppData\\Local\\Packages\\PythonSoftwareFoundation.Python.3.8_qbz5n2kfra8p0\\LocalCache\\local-packages\\Python38\\site-packages\\telegram\\bot.py\", line 130, in decorator\n",
      "    result = func(*args, **kwargs)\n",
      "  File \"C:\\Users\\alexb\\AppData\\Local\\Packages\\PythonSoftwareFoundation.Python.3.8_qbz5n2kfra8p0\\LocalCache\\local-packages\\Python38\\site-packages\\telegram\\bot.py\", line 2861, in get_updates\n",
      "    self._post(\n",
      "  File \"C:\\Users\\alexb\\AppData\\Local\\Packages\\PythonSoftwareFoundation.Python.3.8_qbz5n2kfra8p0\\LocalCache\\local-packages\\Python38\\site-packages\\telegram\\bot.py\", line 295, in _post\n",
      "    return self.request.post(\n",
      "  File \"C:\\Users\\alexb\\AppData\\Local\\Packages\\PythonSoftwareFoundation.Python.3.8_qbz5n2kfra8p0\\LocalCache\\local-packages\\Python38\\site-packages\\telegram\\utils\\request.py\", line 356, in post\n",
      "    result = self._request_wrapper(\n",
      "  File \"C:\\Users\\alexb\\AppData\\Local\\Packages\\PythonSoftwareFoundation.Python.3.8_qbz5n2kfra8p0\\LocalCache\\local-packages\\Python38\\site-packages\\telegram\\utils\\request.py\", line 283, in _request_wrapper\n",
      "    raise Conflict(message)\n",
      "telegram.error.Conflict: Conflict: terminated by other getUpdates request; make sure that only one bot instance is running\n",
      "Error while getting Updates: Conflict: terminated by other getUpdates request; make sure that only one bot instance is running\n",
      "No error handlers are registered, logging exception.\n",
      "Traceback (most recent call last):\n",
      "  File \"C:\\Users\\alexb\\AppData\\Local\\Packages\\PythonSoftwareFoundation.Python.3.8_qbz5n2kfra8p0\\LocalCache\\local-packages\\Python38\\site-packages\\telegram\\ext\\updater.py\", line 646, in _network_loop_retry\n",
      "    if not action_cb():\n",
      "  File \"C:\\Users\\alexb\\AppData\\Local\\Packages\\PythonSoftwareFoundation.Python.3.8_qbz5n2kfra8p0\\LocalCache\\local-packages\\Python38\\site-packages\\telegram\\ext\\updater.py\", line 597, in polling_action_cb\n",
      "    updates = self.bot.get_updates(\n",
      "  File \"C:\\Users\\alexb\\AppData\\Local\\Packages\\PythonSoftwareFoundation.Python.3.8_qbz5n2kfra8p0\\LocalCache\\local-packages\\Python38\\site-packages\\telegram\\ext\\extbot.py\", line 222, in get_updates\n",
      "    updates = super().get_updates(\n",
      "  File \"C:\\Users\\alexb\\AppData\\Local\\Packages\\PythonSoftwareFoundation.Python.3.8_qbz5n2kfra8p0\\LocalCache\\local-packages\\Python38\\site-packages\\telegram\\bot.py\", line 130, in decorator\n",
      "    result = func(*args, **kwargs)\n",
      "  File \"C:\\Users\\alexb\\AppData\\Local\\Packages\\PythonSoftwareFoundation.Python.3.8_qbz5n2kfra8p0\\LocalCache\\local-packages\\Python38\\site-packages\\telegram\\bot.py\", line 2861, in get_updates\n",
      "    self._post(\n",
      "  File \"C:\\Users\\alexb\\AppData\\Local\\Packages\\PythonSoftwareFoundation.Python.3.8_qbz5n2kfra8p0\\LocalCache\\local-packages\\Python38\\site-packages\\telegram\\bot.py\", line 295, in _post\n",
      "    return self.request.post(\n",
      "  File \"C:\\Users\\alexb\\AppData\\Local\\Packages\\PythonSoftwareFoundation.Python.3.8_qbz5n2kfra8p0\\LocalCache\\local-packages\\Python38\\site-packages\\telegram\\utils\\request.py\", line 356, in post\n",
      "    result = self._request_wrapper(\n",
      "  File \"C:\\Users\\alexb\\AppData\\Local\\Packages\\PythonSoftwareFoundation.Python.3.8_qbz5n2kfra8p0\\LocalCache\\local-packages\\Python38\\site-packages\\telegram\\utils\\request.py\", line 283, in _request_wrapper\n",
      "    raise Conflict(message)\n",
      "telegram.error.Conflict: Conflict: terminated by other getUpdates request; make sure that only one bot instance is running\n",
      "Error while getting Updates: Conflict: terminated by other getUpdates request; make sure that only one bot instance is running\n",
      "No error handlers are registered, logging exception.\n",
      "Traceback (most recent call last):\n",
      "  File \"C:\\Users\\alexb\\AppData\\Local\\Packages\\PythonSoftwareFoundation.Python.3.8_qbz5n2kfra8p0\\LocalCache\\local-packages\\Python38\\site-packages\\telegram\\ext\\updater.py\", line 646, in _network_loop_retry\n",
      "    if not action_cb():\n",
      "  File \"C:\\Users\\alexb\\AppData\\Local\\Packages\\PythonSoftwareFoundation.Python.3.8_qbz5n2kfra8p0\\LocalCache\\local-packages\\Python38\\site-packages\\telegram\\ext\\updater.py\", line 597, in polling_action_cb\n",
      "    updates = self.bot.get_updates(\n",
      "  File \"C:\\Users\\alexb\\AppData\\Local\\Packages\\PythonSoftwareFoundation.Python.3.8_qbz5n2kfra8p0\\LocalCache\\local-packages\\Python38\\site-packages\\telegram\\ext\\extbot.py\", line 222, in get_updates\n",
      "    updates = super().get_updates(\n",
      "  File \"C:\\Users\\alexb\\AppData\\Local\\Packages\\PythonSoftwareFoundation.Python.3.8_qbz5n2kfra8p0\\LocalCache\\local-packages\\Python38\\site-packages\\telegram\\bot.py\", line 130, in decorator\n",
      "    result = func(*args, **kwargs)\n",
      "  File \"C:\\Users\\alexb\\AppData\\Local\\Packages\\PythonSoftwareFoundation.Python.3.8_qbz5n2kfra8p0\\LocalCache\\local-packages\\Python38\\site-packages\\telegram\\bot.py\", line 2861, in get_updates\n",
      "    self._post(\n",
      "  File \"C:\\Users\\alexb\\AppData\\Local\\Packages\\PythonSoftwareFoundation.Python.3.8_qbz5n2kfra8p0\\LocalCache\\local-packages\\Python38\\site-packages\\telegram\\bot.py\", line 295, in _post\n",
      "    return self.request.post(\n",
      "  File \"C:\\Users\\alexb\\AppData\\Local\\Packages\\PythonSoftwareFoundation.Python.3.8_qbz5n2kfra8p0\\LocalCache\\local-packages\\Python38\\site-packages\\telegram\\utils\\request.py\", line 356, in post\n",
      "    result = self._request_wrapper(\n",
      "  File \"C:\\Users\\alexb\\AppData\\Local\\Packages\\PythonSoftwareFoundation.Python.3.8_qbz5n2kfra8p0\\LocalCache\\local-packages\\Python38\\site-packages\\telegram\\utils\\request.py\", line 283, in _request_wrapper\n",
      "    raise Conflict(message)\n",
      "telegram.error.Conflict: Conflict: terminated by other getUpdates request; make sure that only one bot instance is running\n",
      "Error while getting Updates: Conflict: terminated by other getUpdates request; make sure that only one bot instance is running\n",
      "No error handlers are registered, logging exception.\n",
      "Traceback (most recent call last):\n",
      "  File \"C:\\Users\\alexb\\AppData\\Local\\Packages\\PythonSoftwareFoundation.Python.3.8_qbz5n2kfra8p0\\LocalCache\\local-packages\\Python38\\site-packages\\telegram\\ext\\updater.py\", line 646, in _network_loop_retry\n",
      "    if not action_cb():\n",
      "  File \"C:\\Users\\alexb\\AppData\\Local\\Packages\\PythonSoftwareFoundation.Python.3.8_qbz5n2kfra8p0\\LocalCache\\local-packages\\Python38\\site-packages\\telegram\\ext\\updater.py\", line 597, in polling_action_cb\n",
      "    updates = self.bot.get_updates(\n",
      "  File \"C:\\Users\\alexb\\AppData\\Local\\Packages\\PythonSoftwareFoundation.Python.3.8_qbz5n2kfra8p0\\LocalCache\\local-packages\\Python38\\site-packages\\telegram\\ext\\extbot.py\", line 222, in get_updates\n",
      "    updates = super().get_updates(\n",
      "  File \"C:\\Users\\alexb\\AppData\\Local\\Packages\\PythonSoftwareFoundation.Python.3.8_qbz5n2kfra8p0\\LocalCache\\local-packages\\Python38\\site-packages\\telegram\\bot.py\", line 130, in decorator\n",
      "    result = func(*args, **kwargs)\n",
      "  File \"C:\\Users\\alexb\\AppData\\Local\\Packages\\PythonSoftwareFoundation.Python.3.8_qbz5n2kfra8p0\\LocalCache\\local-packages\\Python38\\site-packages\\telegram\\bot.py\", line 2861, in get_updates\n",
      "    self._post(\n",
      "  File \"C:\\Users\\alexb\\AppData\\Local\\Packages\\PythonSoftwareFoundation.Python.3.8_qbz5n2kfra8p0\\LocalCache\\local-packages\\Python38\\site-packages\\telegram\\bot.py\", line 295, in _post\n",
      "    return self.request.post(\n",
      "  File \"C:\\Users\\alexb\\AppData\\Local\\Packages\\PythonSoftwareFoundation.Python.3.8_qbz5n2kfra8p0\\LocalCache\\local-packages\\Python38\\site-packages\\telegram\\utils\\request.py\", line 356, in post\n",
      "    result = self._request_wrapper(\n",
      "  File \"C:\\Users\\alexb\\AppData\\Local\\Packages\\PythonSoftwareFoundation.Python.3.8_qbz5n2kfra8p0\\LocalCache\\local-packages\\Python38\\site-packages\\telegram\\utils\\request.py\", line 283, in _request_wrapper\n",
      "    raise Conflict(message)\n",
      "telegram.error.Conflict: Conflict: terminated by other getUpdates request; make sure that only one bot instance is running\n",
      "Error while getting Updates: Conflict: terminated by other getUpdates request; make sure that only one bot instance is running\n",
      "No error handlers are registered, logging exception.\n",
      "Traceback (most recent call last):\n",
      "  File \"C:\\Users\\alexb\\AppData\\Local\\Packages\\PythonSoftwareFoundation.Python.3.8_qbz5n2kfra8p0\\LocalCache\\local-packages\\Python38\\site-packages\\telegram\\ext\\updater.py\", line 646, in _network_loop_retry\n",
      "    if not action_cb():\n",
      "  File \"C:\\Users\\alexb\\AppData\\Local\\Packages\\PythonSoftwareFoundation.Python.3.8_qbz5n2kfra8p0\\LocalCache\\local-packages\\Python38\\site-packages\\telegram\\ext\\updater.py\", line 597, in polling_action_cb\n",
      "    updates = self.bot.get_updates(\n",
      "  File \"C:\\Users\\alexb\\AppData\\Local\\Packages\\PythonSoftwareFoundation.Python.3.8_qbz5n2kfra8p0\\LocalCache\\local-packages\\Python38\\site-packages\\telegram\\ext\\extbot.py\", line 222, in get_updates\n",
      "    updates = super().get_updates(\n",
      "  File \"C:\\Users\\alexb\\AppData\\Local\\Packages\\PythonSoftwareFoundation.Python.3.8_qbz5n2kfra8p0\\LocalCache\\local-packages\\Python38\\site-packages\\telegram\\bot.py\", line 130, in decorator\n",
      "    result = func(*args, **kwargs)\n",
      "  File \"C:\\Users\\alexb\\AppData\\Local\\Packages\\PythonSoftwareFoundation.Python.3.8_qbz5n2kfra8p0\\LocalCache\\local-packages\\Python38\\site-packages\\telegram\\bot.py\", line 2861, in get_updates\n",
      "    self._post(\n",
      "  File \"C:\\Users\\alexb\\AppData\\Local\\Packages\\PythonSoftwareFoundation.Python.3.8_qbz5n2kfra8p0\\LocalCache\\local-packages\\Python38\\site-packages\\telegram\\bot.py\", line 295, in _post\n",
      "    return self.request.post(\n",
      "  File \"C:\\Users\\alexb\\AppData\\Local\\Packages\\PythonSoftwareFoundation.Python.3.8_qbz5n2kfra8p0\\LocalCache\\local-packages\\Python38\\site-packages\\telegram\\utils\\request.py\", line 356, in post\n",
      "    result = self._request_wrapper(\n",
      "  File \"C:\\Users\\alexb\\AppData\\Local\\Packages\\PythonSoftwareFoundation.Python.3.8_qbz5n2kfra8p0\\LocalCache\\local-packages\\Python38\\site-packages\\telegram\\utils\\request.py\", line 283, in _request_wrapper\n",
      "    raise Conflict(message)\n",
      "telegram.error.Conflict: Conflict: terminated by other getUpdates request; make sure that only one bot instance is running\n",
      "Error while getting Updates: Conflict: terminated by other getUpdates request; make sure that only one bot instance is running\n",
      "No error handlers are registered, logging exception.\n",
      "Traceback (most recent call last):\n",
      "  File \"C:\\Users\\alexb\\AppData\\Local\\Packages\\PythonSoftwareFoundation.Python.3.8_qbz5n2kfra8p0\\LocalCache\\local-packages\\Python38\\site-packages\\telegram\\ext\\updater.py\", line 646, in _network_loop_retry\n",
      "    if not action_cb():\n",
      "  File \"C:\\Users\\alexb\\AppData\\Local\\Packages\\PythonSoftwareFoundation.Python.3.8_qbz5n2kfra8p0\\LocalCache\\local-packages\\Python38\\site-packages\\telegram\\ext\\updater.py\", line 597, in polling_action_cb\n",
      "    updates = self.bot.get_updates(\n",
      "  File \"C:\\Users\\alexb\\AppData\\Local\\Packages\\PythonSoftwareFoundation.Python.3.8_qbz5n2kfra8p0\\LocalCache\\local-packages\\Python38\\site-packages\\telegram\\ext\\extbot.py\", line 222, in get_updates\n",
      "    updates = super().get_updates(\n",
      "  File \"C:\\Users\\alexb\\AppData\\Local\\Packages\\PythonSoftwareFoundation.Python.3.8_qbz5n2kfra8p0\\LocalCache\\local-packages\\Python38\\site-packages\\telegram\\bot.py\", line 130, in decorator\n",
      "    result = func(*args, **kwargs)\n",
      "  File \"C:\\Users\\alexb\\AppData\\Local\\Packages\\PythonSoftwareFoundation.Python.3.8_qbz5n2kfra8p0\\LocalCache\\local-packages\\Python38\\site-packages\\telegram\\bot.py\", line 2861, in get_updates\n",
      "    self._post(\n",
      "  File \"C:\\Users\\alexb\\AppData\\Local\\Packages\\PythonSoftwareFoundation.Python.3.8_qbz5n2kfra8p0\\LocalCache\\local-packages\\Python38\\site-packages\\telegram\\bot.py\", line 295, in _post\n",
      "    return self.request.post(\n",
      "  File \"C:\\Users\\alexb\\AppData\\Local\\Packages\\PythonSoftwareFoundation.Python.3.8_qbz5n2kfra8p0\\LocalCache\\local-packages\\Python38\\site-packages\\telegram\\utils\\request.py\", line 356, in post\n",
      "    result = self._request_wrapper(\n",
      "  File \"C:\\Users\\alexb\\AppData\\Local\\Packages\\PythonSoftwareFoundation.Python.3.8_qbz5n2kfra8p0\\LocalCache\\local-packages\\Python38\\site-packages\\telegram\\utils\\request.py\", line 283, in _request_wrapper\n",
      "    raise Conflict(message)\n",
      "telegram.error.Conflict: Conflict: terminated by other getUpdates request; make sure that only one bot instance is running\n",
      "Error while getting Updates: Conflict: terminated by other getUpdates request; make sure that only one bot instance is running\n",
      "No error handlers are registered, logging exception.\n",
      "Traceback (most recent call last):\n",
      "  File \"C:\\Users\\alexb\\AppData\\Local\\Packages\\PythonSoftwareFoundation.Python.3.8_qbz5n2kfra8p0\\LocalCache\\local-packages\\Python38\\site-packages\\telegram\\ext\\updater.py\", line 646, in _network_loop_retry\n",
      "    if not action_cb():\n",
      "  File \"C:\\Users\\alexb\\AppData\\Local\\Packages\\PythonSoftwareFoundation.Python.3.8_qbz5n2kfra8p0\\LocalCache\\local-packages\\Python38\\site-packages\\telegram\\ext\\updater.py\", line 597, in polling_action_cb\n",
      "    updates = self.bot.get_updates(\n",
      "  File \"C:\\Users\\alexb\\AppData\\Local\\Packages\\PythonSoftwareFoundation.Python.3.8_qbz5n2kfra8p0\\LocalCache\\local-packages\\Python38\\site-packages\\telegram\\ext\\extbot.py\", line 222, in get_updates\n",
      "    updates = super().get_updates(\n",
      "  File \"C:\\Users\\alexb\\AppData\\Local\\Packages\\PythonSoftwareFoundation.Python.3.8_qbz5n2kfra8p0\\LocalCache\\local-packages\\Python38\\site-packages\\telegram\\bot.py\", line 130, in decorator\n",
      "    result = func(*args, **kwargs)\n",
      "  File \"C:\\Users\\alexb\\AppData\\Local\\Packages\\PythonSoftwareFoundation.Python.3.8_qbz5n2kfra8p0\\LocalCache\\local-packages\\Python38\\site-packages\\telegram\\bot.py\", line 2861, in get_updates\n",
      "    self._post(\n",
      "  File \"C:\\Users\\alexb\\AppData\\Local\\Packages\\PythonSoftwareFoundation.Python.3.8_qbz5n2kfra8p0\\LocalCache\\local-packages\\Python38\\site-packages\\telegram\\bot.py\", line 295, in _post\n",
      "    return self.request.post(\n",
      "  File \"C:\\Users\\alexb\\AppData\\Local\\Packages\\PythonSoftwareFoundation.Python.3.8_qbz5n2kfra8p0\\LocalCache\\local-packages\\Python38\\site-packages\\telegram\\utils\\request.py\", line 356, in post\n",
      "    result = self._request_wrapper(\n",
      "  File \"C:\\Users\\alexb\\AppData\\Local\\Packages\\PythonSoftwareFoundation.Python.3.8_qbz5n2kfra8p0\\LocalCache\\local-packages\\Python38\\site-packages\\telegram\\utils\\request.py\", line 283, in _request_wrapper\n",
      "    raise Conflict(message)\n",
      "telegram.error.Conflict: Conflict: terminated by other getUpdates request; make sure that only one bot instance is running\n",
      "Error while getting Updates: Conflict: terminated by other getUpdates request; make sure that only one bot instance is running\n",
      "No error handlers are registered, logging exception.\n",
      "Traceback (most recent call last):\n",
      "  File \"C:\\Users\\alexb\\AppData\\Local\\Packages\\PythonSoftwareFoundation.Python.3.8_qbz5n2kfra8p0\\LocalCache\\local-packages\\Python38\\site-packages\\telegram\\ext\\updater.py\", line 646, in _network_loop_retry\n",
      "    if not action_cb():\n",
      "  File \"C:\\Users\\alexb\\AppData\\Local\\Packages\\PythonSoftwareFoundation.Python.3.8_qbz5n2kfra8p0\\LocalCache\\local-packages\\Python38\\site-packages\\telegram\\ext\\updater.py\", line 597, in polling_action_cb\n",
      "    updates = self.bot.get_updates(\n",
      "  File \"C:\\Users\\alexb\\AppData\\Local\\Packages\\PythonSoftwareFoundation.Python.3.8_qbz5n2kfra8p0\\LocalCache\\local-packages\\Python38\\site-packages\\telegram\\ext\\extbot.py\", line 222, in get_updates\n",
      "    updates = super().get_updates(\n",
      "  File \"C:\\Users\\alexb\\AppData\\Local\\Packages\\PythonSoftwareFoundation.Python.3.8_qbz5n2kfra8p0\\LocalCache\\local-packages\\Python38\\site-packages\\telegram\\bot.py\", line 130, in decorator\n",
      "    result = func(*args, **kwargs)\n",
      "  File \"C:\\Users\\alexb\\AppData\\Local\\Packages\\PythonSoftwareFoundation.Python.3.8_qbz5n2kfra8p0\\LocalCache\\local-packages\\Python38\\site-packages\\telegram\\bot.py\", line 2861, in get_updates\n",
      "    self._post(\n",
      "  File \"C:\\Users\\alexb\\AppData\\Local\\Packages\\PythonSoftwareFoundation.Python.3.8_qbz5n2kfra8p0\\LocalCache\\local-packages\\Python38\\site-packages\\telegram\\bot.py\", line 295, in _post\n",
      "    return self.request.post(\n",
      "  File \"C:\\Users\\alexb\\AppData\\Local\\Packages\\PythonSoftwareFoundation.Python.3.8_qbz5n2kfra8p0\\LocalCache\\local-packages\\Python38\\site-packages\\telegram\\utils\\request.py\", line 356, in post\n",
      "    result = self._request_wrapper(\n",
      "  File \"C:\\Users\\alexb\\AppData\\Local\\Packages\\PythonSoftwareFoundation.Python.3.8_qbz5n2kfra8p0\\LocalCache\\local-packages\\Python38\\site-packages\\telegram\\utils\\request.py\", line 283, in _request_wrapper\n",
      "    raise Conflict(message)\n",
      "telegram.error.Conflict: Conflict: terminated by other getUpdates request; make sure that only one bot instance is running\n",
      "Error while getting Updates: Conflict: terminated by other getUpdates request; make sure that only one bot instance is running\n",
      "No error handlers are registered, logging exception.\n",
      "Traceback (most recent call last):\n",
      "  File \"C:\\Users\\alexb\\AppData\\Local\\Packages\\PythonSoftwareFoundation.Python.3.8_qbz5n2kfra8p0\\LocalCache\\local-packages\\Python38\\site-packages\\telegram\\ext\\updater.py\", line 646, in _network_loop_retry\n",
      "    if not action_cb():\n",
      "  File \"C:\\Users\\alexb\\AppData\\Local\\Packages\\PythonSoftwareFoundation.Python.3.8_qbz5n2kfra8p0\\LocalCache\\local-packages\\Python38\\site-packages\\telegram\\ext\\updater.py\", line 597, in polling_action_cb\n",
      "    updates = self.bot.get_updates(\n",
      "  File \"C:\\Users\\alexb\\AppData\\Local\\Packages\\PythonSoftwareFoundation.Python.3.8_qbz5n2kfra8p0\\LocalCache\\local-packages\\Python38\\site-packages\\telegram\\ext\\extbot.py\", line 222, in get_updates\n",
      "    updates = super().get_updates(\n",
      "  File \"C:\\Users\\alexb\\AppData\\Local\\Packages\\PythonSoftwareFoundation.Python.3.8_qbz5n2kfra8p0\\LocalCache\\local-packages\\Python38\\site-packages\\telegram\\bot.py\", line 130, in decorator\n",
      "    result = func(*args, **kwargs)\n",
      "  File \"C:\\Users\\alexb\\AppData\\Local\\Packages\\PythonSoftwareFoundation.Python.3.8_qbz5n2kfra8p0\\LocalCache\\local-packages\\Python38\\site-packages\\telegram\\bot.py\", line 2861, in get_updates\n",
      "    self._post(\n",
      "  File \"C:\\Users\\alexb\\AppData\\Local\\Packages\\PythonSoftwareFoundation.Python.3.8_qbz5n2kfra8p0\\LocalCache\\local-packages\\Python38\\site-packages\\telegram\\bot.py\", line 295, in _post\n",
      "    return self.request.post(\n",
      "  File \"C:\\Users\\alexb\\AppData\\Local\\Packages\\PythonSoftwareFoundation.Python.3.8_qbz5n2kfra8p0\\LocalCache\\local-packages\\Python38\\site-packages\\telegram\\utils\\request.py\", line 356, in post\n",
      "    result = self._request_wrapper(\n",
      "  File \"C:\\Users\\alexb\\AppData\\Local\\Packages\\PythonSoftwareFoundation.Python.3.8_qbz5n2kfra8p0\\LocalCache\\local-packages\\Python38\\site-packages\\telegram\\utils\\request.py\", line 283, in _request_wrapper\n",
      "    raise Conflict(message)\n",
      "telegram.error.Conflict: Conflict: terminated by other getUpdates request; make sure that only one bot instance is running\n",
      "Error while getting Updates: Conflict: terminated by other getUpdates request; make sure that only one bot instance is running\n",
      "No error handlers are registered, logging exception.\n",
      "Traceback (most recent call last):\n",
      "  File \"C:\\Users\\alexb\\AppData\\Local\\Packages\\PythonSoftwareFoundation.Python.3.8_qbz5n2kfra8p0\\LocalCache\\local-packages\\Python38\\site-packages\\telegram\\ext\\updater.py\", line 646, in _network_loop_retry\n",
      "    if not action_cb():\n",
      "  File \"C:\\Users\\alexb\\AppData\\Local\\Packages\\PythonSoftwareFoundation.Python.3.8_qbz5n2kfra8p0\\LocalCache\\local-packages\\Python38\\site-packages\\telegram\\ext\\updater.py\", line 597, in polling_action_cb\n",
      "    updates = self.bot.get_updates(\n",
      "  File \"C:\\Users\\alexb\\AppData\\Local\\Packages\\PythonSoftwareFoundation.Python.3.8_qbz5n2kfra8p0\\LocalCache\\local-packages\\Python38\\site-packages\\telegram\\ext\\extbot.py\", line 222, in get_updates\n",
      "    updates = super().get_updates(\n",
      "  File \"C:\\Users\\alexb\\AppData\\Local\\Packages\\PythonSoftwareFoundation.Python.3.8_qbz5n2kfra8p0\\LocalCache\\local-packages\\Python38\\site-packages\\telegram\\bot.py\", line 130, in decorator\n",
      "    result = func(*args, **kwargs)\n",
      "  File \"C:\\Users\\alexb\\AppData\\Local\\Packages\\PythonSoftwareFoundation.Python.3.8_qbz5n2kfra8p0\\LocalCache\\local-packages\\Python38\\site-packages\\telegram\\bot.py\", line 2861, in get_updates\n",
      "    self._post(\n",
      "  File \"C:\\Users\\alexb\\AppData\\Local\\Packages\\PythonSoftwareFoundation.Python.3.8_qbz5n2kfra8p0\\LocalCache\\local-packages\\Python38\\site-packages\\telegram\\bot.py\", line 295, in _post\n",
      "    return self.request.post(\n",
      "  File \"C:\\Users\\alexb\\AppData\\Local\\Packages\\PythonSoftwareFoundation.Python.3.8_qbz5n2kfra8p0\\LocalCache\\local-packages\\Python38\\site-packages\\telegram\\utils\\request.py\", line 356, in post\n",
      "    result = self._request_wrapper(\n",
      "  File \"C:\\Users\\alexb\\AppData\\Local\\Packages\\PythonSoftwareFoundation.Python.3.8_qbz5n2kfra8p0\\LocalCache\\local-packages\\Python38\\site-packages\\telegram\\utils\\request.py\", line 283, in _request_wrapper\n",
      "    raise Conflict(message)\n",
      "telegram.error.Conflict: Conflict: terminated by other getUpdates request; make sure that only one bot instance is running\n",
      "Error while getting Updates: Conflict: terminated by other getUpdates request; make sure that only one bot instance is running\n",
      "No error handlers are registered, logging exception.\n",
      "Traceback (most recent call last):\n",
      "  File \"C:\\Users\\alexb\\AppData\\Local\\Packages\\PythonSoftwareFoundation.Python.3.8_qbz5n2kfra8p0\\LocalCache\\local-packages\\Python38\\site-packages\\telegram\\ext\\updater.py\", line 646, in _network_loop_retry\n",
      "    if not action_cb():\n",
      "  File \"C:\\Users\\alexb\\AppData\\Local\\Packages\\PythonSoftwareFoundation.Python.3.8_qbz5n2kfra8p0\\LocalCache\\local-packages\\Python38\\site-packages\\telegram\\ext\\updater.py\", line 597, in polling_action_cb\n",
      "    updates = self.bot.get_updates(\n",
      "  File \"C:\\Users\\alexb\\AppData\\Local\\Packages\\PythonSoftwareFoundation.Python.3.8_qbz5n2kfra8p0\\LocalCache\\local-packages\\Python38\\site-packages\\telegram\\ext\\extbot.py\", line 222, in get_updates\n",
      "    updates = super().get_updates(\n",
      "  File \"C:\\Users\\alexb\\AppData\\Local\\Packages\\PythonSoftwareFoundation.Python.3.8_qbz5n2kfra8p0\\LocalCache\\local-packages\\Python38\\site-packages\\telegram\\bot.py\", line 130, in decorator\n",
      "    result = func(*args, **kwargs)\n",
      "  File \"C:\\Users\\alexb\\AppData\\Local\\Packages\\PythonSoftwareFoundation.Python.3.8_qbz5n2kfra8p0\\LocalCache\\local-packages\\Python38\\site-packages\\telegram\\bot.py\", line 2861, in get_updates\n",
      "    self._post(\n",
      "  File \"C:\\Users\\alexb\\AppData\\Local\\Packages\\PythonSoftwareFoundation.Python.3.8_qbz5n2kfra8p0\\LocalCache\\local-packages\\Python38\\site-packages\\telegram\\bot.py\", line 295, in _post\n",
      "    return self.request.post(\n",
      "  File \"C:\\Users\\alexb\\AppData\\Local\\Packages\\PythonSoftwareFoundation.Python.3.8_qbz5n2kfra8p0\\LocalCache\\local-packages\\Python38\\site-packages\\telegram\\utils\\request.py\", line 356, in post\n",
      "    result = self._request_wrapper(\n",
      "  File \"C:\\Users\\alexb\\AppData\\Local\\Packages\\PythonSoftwareFoundation.Python.3.8_qbz5n2kfra8p0\\LocalCache\\local-packages\\Python38\\site-packages\\telegram\\utils\\request.py\", line 283, in _request_wrapper\n",
      "    raise Conflict(message)\n",
      "telegram.error.Conflict: Conflict: terminated by other getUpdates request; make sure that only one bot instance is running\n"
     ]
    }
   ],
   "source": [
    "import telegram\n",
    "from telegram.ext import Updater, CommandHandler, MessageHandler, Filters\n",
    "\n",
    "def start(update, context):\n",
    "    context.bot.send_message(chat_id=update.effective_chat.id, text=\"Hello! What's your name?\")\n",
    "\n",
    "def echo(update, context):\n",
    "    user_input = update.message.text\n",
    "    context.bot.send_message(chat_id=update.effective_chat.id, text=\"Hi, \"+user_input+\"!\")\n",
    "\n",
    "def main():\n",
    "    updater = Updater(token='6027981425:AAHdSWkDWAgxMvZZTdXXKmoTK6eo_JJmTto', use_context=True)\n",
    "    dispatcher = updater.dispatcher\n",
    "    dispatcher.add_handler(CommandHandler('start', start))\n",
    "    dispatcher.add_handler(MessageHandler(Filters.text & ~Filters.command, echo))\n",
    "    updater.start_polling(poll_interval=0.5)\n"
   ]
  }
 ],
 "metadata": {
  "kernelspec": {
   "display_name": "Python 3",
   "language": "python",
   "name": "python3"
  },
  "language_info": {
   "codemirror_mode": {
    "name": "ipython",
    "version": 3
   },
   "file_extension": ".py",
   "mimetype": "text/x-python",
   "name": "python",
   "nbconvert_exporter": "python",
   "pygments_lexer": "ipython3",
   "version": "3.8.10"
  },
  "orig_nbformat": 4
 },
 "nbformat": 4,
 "nbformat_minor": 2
}
